Workbook

Sheet 가정값
A1: ☀ ShiningShadow — Hotmart 완전판 매출 시뮬레이터 v4 (8유형 × 3티어 · 제휴 중심 전략)
A2: 🔵 파란색=직접입력 ⚫ 검정=자동계산 | 퍼널: 무료진단 → 무료개요리포트 → Hotmart 유형별 링크 | 제휴사 T1 70%로 바이럴 극대화
A4: ① 상품 가격 구조 — 누적 포함 (박리다매 · 남미 최적화)
A5: Tier 1 · Basic + 부록A 포함 | B5: 15 | C5: $15 · 마이크로트랜잭션 상한 · Hotmart 수수료 20% 적용
A6: Tier 2 · Tier1 전체 + Deep + 부록B 포함 | B6: 24 | C6: $24 · 주력 상품 · Hotmart 수수료 9.9%+$0.50 적용
A7: Tier 3 · Tier2 전체 + Master + 부록C 포함 | B7: 29 | C7: $29 · 완전판 · Hotmart 수수료 9.9%+$0.50 적용
A8: 무료 기본개요 리포트 (퍼널 입구) | B8: 0 | C8: FREE · 진단 후 자동발송 · 내부 링크로 유료 연결
A10: ② Shadowgram 퍼널 전환율 가정
A11: 월 Shadowgram 진단 완료 수 | B11: 5000 | C11: 무료진단 완료 → 이메일 입력 단계
A12: 이메일 입력률 (진단 완료 중) | B12: 0.6 | C12: 무료 리포트 받으려고 자연 입력
A13: 무료개요 → Tier1 전환율 | B13: 0.08 | C13: 리포트 내 링크 클릭 후 구매
A14: Tier1 → Tier2 업셀 전환율 | B14: 0.4 | C14: Tier1 포함이므로 자연 업그레이드
A15: Tier2 → Tier3 업셀 전환율 | B15: 0.25 | C15: 완전판 원하는 헤비유저
A16: 월 성장률 (바이럴 복리) | B16: 0.2 | C16: 진단 공유 + 리추얼 인증 루프
A18: ③ Hotmart 수수료 구조 (티어별 차등)
A19: Hotmart 수수료율 — Tier 1 ($15, 마이크로) | B19: 0.2 | C19: 20% 고정 (≤$15 마이크로트랜잭션 정책)
A20: Hotmart 수수료율 — Tier 2 ($24) | B20: 0.099 | C20: 9.9% (+ 고정액 별도)
A21: Hotmart 수수료율 — Tier 3 ($29) | B21: 0.099 | C21: 9.9% (+ 고정액 별도)
A22: Hotmart 고정액/건 (T2·T3 적용) | B22: 0.5 | C22: $0.50/건 추가 차감
A24: ④ 제휴 커미션 전략 — T1 70%로 바이럴, T2/T3는 이메일로 직접 업셀
A25: 제휴 커미션율 — Tier 1 | B25: 0.7 | C25: 70% · 제휴사 $8.40/건 · '이게 말이 돼?' → 미친 듯 홍보
A26: 제휴 커미션율 — Tier 2 | B26: 0.5 | C26: 50% · 제휴사 $10.56/건
A27: 제휴 커미션율 — Tier 3 | B27: 0.5 | C27: 50% · 제휴사 $12.81/건
A28: 제휴 경유 비중 — Tier 1 | B28: 0.8 | C28: T1 판매의 80%는 제휴사 경유 → 바이럴 엔진
A29: 제휴 경유 비중 — Tier 2 | B29: 0.3 | C29: T2는 30% 제휴 / 70% 이메일 직접 업셀
A30: 제휴 경유 비중 — Tier 3 | B30: 0.1 | C30: T3는 10% 제휴 / 90% 직접 (충성 고객)
A32: ⑤ 유형별 월 수량 (M1 기준 · 8유형 균등 가정 · 자동계산)
A33: 유형별 이메일 수집 수 | B33: =B11*B12/8 -> 375 | C33: 진단완료×이메일율÷8유형
A34: 유형별 T1 구매 수 | B34: =B33*B13 -> 30 | C34: 이메일→T1 전환
A35: 유형별 T2 구매 수 | B35: =B34*B14 -> 12 | C35: T1→T2 업셀
A36: 유형별 T3 구매 수 | B36: =B35*B15 -> 3 | C36: T2→T3 업셀
A38: ⑥ 건당 수익 구조 (자동계산 · 참조용)
A39: T1 건당 순액 (Hotmart 차감 후) | B39: =B5*(1-B19) -> 12 | C39: $15×(1-20%) = $12.00
A40: T2 건당 순액 (Hotmart 차감 후) | B40: =B6*(1-B20)-B22 -> 21.124 | C40: $24×(1-9.9%)-$0.50 = $21.12
A41: T3 건당 순액 (Hotmart 차감 후) | B41: =B7*(1-B21)-B22 -> 25.629 | C41: $29×(1-9.9%)-$0.50 = $25.63
A42: 제휴사 T1 실수령/건 | B42: =B39*B25 -> 8.4 | C42: $12.00×70% = $8.40
A43: 제휴사 T2 실수령/건 | B43: =B40*B26 -> 10.562 | C43: $21.12×50% = $10.56
A44: 제휴사 T3 실수령/건 | B44: =B41*B27 -> 12.8145 | C44: $25.63×50% = $12.81
A45: 민철님 T1 직접판매 실수령/건 | B45: =B39*(1-B25) -> 3.6 | C45: $12.00×30% = $3.60
A46: 민철님 T2 직접판매 실수령/건 | B46: =B40*(1-B26) -> 10.562 | C46: $21.12×50% = $10.56
...

Sheet 월별 성장
A1: 📈 월별 성장 시뮬레이션 — 8유형 완전판 (M1~M12) · 제휴 중심 전략
A2: 기준: 가정값 시트 전환율 · 월별 바이럴 성장률 복리 · T1 제휴 80% / T2 30% / T3 10%
A4: 항목 | B4: 설명 | C4: M1 | D4: M2 | E4: M3 | F4: M4 | G4: M5 | H4: M6 | I4: M7 | J4: M8 | K4: M9 | L4: M10 | M4: M11 | N4: M12
A5: 📊 퍼널 수량 흐름
A6: 진단 완료 수 | B6: ↑ 성장 | C6: =가정값!B11 -> 5000 | D6: =가정값!B11*(1+가정값!B16)^1 -> 6000 | E6: =가정값!B11*(1+가정값!B16)^2 -> 7200 | F6: =가정값!B11*(1+가정값!B16)^3 -> 8640 | G6: =가정값!B11*(1+가정값!B16)^4 -> 10368 | H6: =가정값!B11*(1+가정값!B16)^5 -> 12441.6 | I6: =가정값!B11*(1+가정값!B16)^6 -> 14929.92 | J6: =가정값!B11*(1+가정값!B16)^7 -> 17915.904 | K6: =가정값!B11*(1+가정값!B16)^8 -> 21499.085 | L6: =가정값!B11*(1+가정값!B16)^9 -> 25798.902 | M6: =가정값!B11*(1+가정값!B16)^10 -> 30958.682 | N6: =가정값!B11*(1+가정값!B16)^11 -> 37150.419
A7: 이메일 수집 수 | B7: ×이메일율 | C7: =C6*가정값!B12 -> 3000 | D7: =D6*가정값!B12 -> 3600 | E7: =E6*가정값!B12 -> 4320 | F7: =F6*가정값!B12 -> 5184 | G7: =G6*가정값!B12 -> 6220.8 | H7: =H6*가정값!B12 -> 7464.96 | I7: =I6*가정값!B12 -> 8957.952 | J7: =J6*가정값!B12 -> 10749.542 | K7: =K6*가정값!B12 -> 12899.451 | L7: =L6*가정값!B12 -> 15479.341 | M7: =M6*가정값!B12 -> 18575.209 | N7: =N6*가정값!B12 -> 22290.251
A8: Tier1 구매 수 (8유형 합산) | B8: ×T1전환×8 | C8: =C7*가정값!B13*8 -> 1920 | D8: =D7*가정값!B13*8 -> 2304 | E8: =E7*가정값!B13*8 -> 2764.8 | F8: =F7*가정값!B13*8 -> 3317.76 | G8: =G7*가정값!B13*8 -> 3981.312 | H8: =H7*가정값!B13*8 -> 4777.5744 | I8: =I7*가정값!B13*8 -> 5733.0893 | J8: =J7*가정값!B13*8 -> 6879.7071 | K8: =K7*가정값!B13*8 -> 8255.6486 | L8: =L7*가정값!B13*8 -> 9906.7783 | M8: =M7*가정값!B13*8 -> 11888.134 | N8: =N7*가정값!B13*8 -> 14265.761
A9: Tier2 구매 수 (8유형 합산) | B9: ×T2업셀 | C9: =C8*가정값!B14 -> 768 | D9: =D8*가정값!B14 -> 921.6 | E9: =E8*가정값!B14 -> 1105.92 | F9: =F8*가정값!B14 -> 1327.104 | G9: =G8*가정값!B14 -> 1592.5248 | H9: =H8*가정값!B14 -> 1911.0298 | I9: =I8*가정값!B14 -> 2293.2357 | J9: =J8*가정값!B14 -> 2751.8829 | K9: =K8*가정값!B14 -> 3302.2594 | L9: =L8*가정값!B14 -> 3962.7113 | M9: =M8*가정값!B14 -> 4755.2536 | N9: =N8*가정값!B14 -> 5706.3043
A10: Tier3 구매 수 (8유형 합산) | B10: ×T3업셀 | C10: =C9*가정값!B15 -> 192 | D10: =D9*가정값!B15 -> 230.4 | E10: =E9*가정값!B15 -> 276.48 | F10: =F9*가정값!B15 -> 331.776 | G10: =G9*가정값!B15 -> 398.1312 | H10: =H9*가정값!B15 -> 477.75744 | I10: =I9*가정값!B15 -> 573.30893 | J10: =J9*가정값!B15 -> 687.97071 | K10: =K9*가정값!B15 -> 825.56486 | L10: =L9*가정값!B15 -> 990.67783 | M10: =M9*가정값!B15 -> 1188.8134 | N10: =N9*가정값!B15 -> 1426.5761
A12: 💰 매출 흐름 (Gross → 차감 → 순수익)
A13: Tier1 매출 (Gross) | C13: =C8*가정값!B5 -> 28800 | D13: =D8*가정값!B5 -> 34560 | E13: =E8*가정값!B5 -> 41472 | F13: =F8*가정값!B5 -> 49766.4 | G13: =G8*가정값!B5 -> 59719.68 | H13: =H8*가정값!B5 -> 71663.616 | I13: =I8*가정값!B5 -> 85996.339 | J13: =J8*가정값!B5 -> 103195.61 | K13: =K8*가정값!B5 -> 123834.73 | L13: =L8*가정값!B5 -> 148601.67 | M13: =M8*가정값!B5 -> 178322.01 | N13: =N8*가정값!B5 -> 213986.41
A14: Tier2 매출 (Gross) | C14: =C9*가정값!B6 -> 18432 | D14: =D9*가정값!B6 -> 22118.4 | E14: =E9*가정값!B6 -> 26542.08 | F14: =F9*가정값!B6 -> 31850.496 | G14: =G9*가정값!B6 -> 38220.595 | H14: =H9*가정값!B6 -> 45864.714 | I14: =I9*가정값!B6 -> 55037.657 | J14: =J9*가정값!B6 -> 66045.189 | K14: =K9*가정값!B6 -> 79254.226 | L14: =L9*가정값!B6 -> 95105.071 | M14: =M9*가정값!B6 -> 114126.09 | N14: =N9*가정값!B6 -> 136951.3
A15: Tier3 매출 (Gross) | C15: =C10*가정값!B7 -> 5568 | D15: =D10*가정값!B7 -> 6681.6 | E15: =E10*가정값!B7 -> 8017.92 | F15: =F10*가정값!B7 -> 9621.504 | G15: =G10*가정값!B7 -> 11545.805 | H15: =H10*가정값!B7 -> 13854.966 | I15: =I10*가정값!B7 -> 16625.959 | J15: =J10*가정값!B7 -> 19951.151 | K15: =K10*가정값!B7 -> 23941.381 | L15: =L10*가정값!B7 -> 28729.657 | M15: =M10*가정값!B7 -> 34475.588 | N15: =N10*가정값!B7 -> 41370.706
A16: 총 매출 (Gross) | C16: =C13+C14+C15 -> 52800 | D16: =D13+D14+D15 -> 63360 | E16: =E13+E14+E15 -> 76032 | F16: =F13+F14+F15 -> 91238.4 | G16: =G13+G14+G15 -> 109486.08 | H16: =H13+H14+H15 -> 131383.3 | I16: =I13+I14+I15 -> 157659.96 | J16: =J13+J14+J15 -> 189191.95 | ... N16: =N13+N14+N15 -> 392308.42
A17: 차감: Hotmart 수수료 (T1:20% · T2/T3:9.9%+$0.50/건) | C17: =-(C13*가정값!$B$19+C14*가정값!$B$20+C9*가정값!$B$22+C15*가정값!$B$21+C10*가정값!$B$22) -> -8616 | D17: =-(D13*가정값!$B$19+D14*가정값!$B$20+D9*가정값!$B$22+D15*가정값!$B$21+D10*가정값!$B$22) -> -10339.2 | E17: =-(E13*가정값!$B$19+E14*가정값!$B$20+E9*가정값!$B$22+E15*가정값!$B$21+E10*가정값!$B$22) -> -12407.04 | F17: =-(F13*가정값!$B$19+F14*가정값!$B$20+F9*가정값!$B$22+F15*가정값!$B$21+F10*가정값!$B$22) -> -14888.448 | G17: =-(G13*가정값!$B$19+G14*가정값!$B$20+G9*가정값!$B$22+G15*가정값!$B$21+G10*가정값!$B$22) -> -17866.138 | H17: =-(H13*가정값!$B$19+H14*가정값!$B$20+H9*가정값!$B$22+H15*가정값!$B$21+H10*가정값!$B$22) -> -21439.365 | I17: =-(I13*가정값!$B$19+I14*가정값!$B$20+I9*가정값!$B$22+I15*가정값!$B$21+I10*가정값!$B$22) -> -25727.238 | J17: =-(J13*가정값!$B$19+J14*가정값!$B$20+J9*가정값!$B$22+J15*가정값!$B$21+J10*가정값!$B$22) -> -30872.686 | ... N17: =-(N13*가정값!$B$19+N14*가정값!$B$20+N9*가정값!$B$22+N15*가정값!$B$21+N10*가정값!$B$22) -> -64017.601
A18: 차감: 제휴 커미션 (T1:70%×80% · T2:50%×30% · T3:50%×10%) | C18: =-(C13*(1-가정값!$B$19)*가정값!$B$25*가정값!$B$28+(C14*(1-가정값!$B$20)-C9*가정값!$B$22)*가정값!$B$26*가정값!$B$29+(C15*(1-가정값!$B$21)-C10*가정값!$B$22)*가정값!$B$27*가정값!$B$30) -> -15581.923 | D18: =-(D13*(1-가정값!$B$19)*가정값!$B$25*가정값!$B$28+(D14*(1-가정값!$B$20)-D9*가정값!$B$22)*가정값!$B$26*가정값!$B$29+(D15*(1-가정값!$B$21)-D10*가정값!$B$22)*가정값!$B$27*가정값!$B$30) -> -18698.308 | E18: =-(E13*(1-가정값!$B$19)*가정값!$B$25*가정값!$B$28+(E14*(1-가정값!$B$20)-E9*가정값!$B$22)*가정값!$B$26*가정값!$B$29+(E15*(1-가정값!$B$21)-E10*가정값!$B$22)*가정값!$B$27*가정값!$B$30) -> -22437.969 | F18: =-(F13*(1-가정값!$B$19)*가정값!$B$25*가정값!$B$28+(F14*(1-가정값!$B$20)-F9*가정값!$B$22)*가정값!$B$26*가정값!$B$29+(F15*(1-가정값!$B$21)-F10*가정값!$B$22)*가정값!$B$27*가정값!$B$30) -> -26925.563 | G18: =-(G13*(1-가정값!$B$19)*가정값!$B$25*가정값!$B$28+(G14*(1-가정값!$B$20)-G9*가정값!$B$22)*가정값!$B$26*가정값!$B$29+(G15*(1-가정값!$B$21)-G10*가정값!$B$22)*가정값!$B$27*가정값!$B$30) -> -32310.676 | H18: =-(H13*(1-가정값!$B$19)*가정값!$B$25*가정값!$B$28+(H14*(1-가정값!$B$20)-H9*가정값!$B$22)*가정값!$B$26*가정값!$B$29+(H15*(1-가정값!$B$21)-H10*가정값!$B$22)*가정값!$B$27*가정값!$B$30) -> -38772.811 | I18: =-(I13*(1-가정값!$B$19)*가정값!$B$25*가정값!$B$28+(I14*(1-가정값!$B$20)-I9*가정값!$B$22)*가정값!$B$26*가정값!$B$29+(I15*(1-가정값!$B$21)-I10*가정값!$B$22)*가정값!$B$27*가정값!$B$30) -> -46527.373 | J18: =-(J13*(1-가정값!$B$19)*가정값!$B$25*가정값!$B$28+(J14*(1-가정값!$B$20)-J9*가정값!$B$22)*가정값!$B$26*가정값!$B$29+(J15*(1-가정값!$B$21)-J10*가정값!$B$22)*가정값!$B$27*가정값!$B$30) -> -55832.848 | ... N18: =-(N13*(1-가정값!$B$19)*가정값!$B$25*가정값!$B$28+(N14*(1-가정값!$B$20)-N9*가정값!$B$22)*가정값!$B$26*가정값!$B$29+(N15*(1-가정값!$B$21)-N10*가정값!$B$22)*가정값!$B$27*가정값!$B$30) -> -115774.99
A19: ▶ 월 순 수익 | C19: =C16+C17+C18 -> 28602.077 | D19: =D16+D17+D18 -> 34322.492 | E19: =E16+E17+E18 -> 41186.991 | F19: =F16+F17+F18 -> 49424.389 | G19: =G16+G17+G18 -> 59309.266 | H19: =H16+H17+H18 -> 71171.12 | I19: =I16+I17+I18 -> 85405.344 | J19: =J16+J17+J18 -> 102486.41 | ... N19: =N16+N17+N18 -> 212515.82
A20: 누적 순 수익 | C20: =C19 -> 28602.077 | D20: =C20+D19 -> 62924.569 | E20: =D20+E19 -> 104111.56 | F20: =E20+F19 -> 153535.95 | G20: =F20+G19 -> 212845.21 | H20: =G20+H19 -> 284016.33 | I20: =H20+I19 -> 369421.68 | J20: =I20+J19 -> 471908.09 | K20: =J20+K19 -> 594891.79 | ... N20: =M20+N19 -> 1132084.6
A22: 📋 연간 합계
A23: 연간 총 매출 | B23: =SUM(C16:N16) -> 2089850.5
A24: 연간 순 수익 | B24: =SUM(C19:N19) -> 1132084.6
A25: 연간 순 수익 (₩) | B25: =B24*1400 -> 1.5849184e+09

Sheet 시나리오 비교
A1: 🎯 시나리오 비교 — 보수적 / 기본 / 낙관 / 드림 (8유형 완전판 · 제휴 중심)
A2: M12(12개월 후) 월 순 수익 기준 · T1 제휴 비중 높을수록 바이럴 극대화 · 파란색 셀 직접 수정 가능
A4: 가정 항목 | B4: 보수적 😐 | C4: 기본 🙂 | D4: 낙관 😊 | E4: 드림 🚀
A5: 📥 입력 가정 (파란색 직접 수정)
A6: 월 진단 완료 수 | B6: 500 | C6: 5000 | D6: 20000 | E6: 100000
A7: 이메일 입력률 | B7: 0.4 | C7: 0.6 | D7: 0.7 | E7: 0.8
A8: 무료개요→Tier1 전환율 | B8: 0.03 | C8: 0.08 | D8: 0.12 | E8: 0.18
A9: Tier1→Tier2 업셀율 | B9: 0.2 | C9: 0.4 | D9: 0.55 | E9: 0.7
A10: Tier2→Tier3 업셀율 | B10: 0.1 | C10: 0.25 | D10: 0.4 | E10: 0.55
A11: 월 성장률 | B11: 0.05 | C11: 0.2 | D11: 0.3 | E11: 0.5
A12: T1 제휴 경유 비중 | B12: 0.5 | C12: 0.8 | D12: 0.9 | E12: 0.95
A13: T2 제휴 경유 비중 | B13: 0.2 | C13: 0.3 | D13: 0.4 | E13: 0.5
A14: T3 제휴 경유 비중 | B14: 0.05 | C14: 0.1 | D14: 0.2 | E14: 0.3
A16: 📊 M12 월 순 수익 계산 (12개월 후 · 성장률 복리 적용)
A17: 진단 수 (M12) | B17: =B6*(1+B11)^11 -> 855.16968 | C17: =C6*(1+C11)^11 -> 37150.419 | D17: =D6*(1+D11)^11 -> 358432.08 | E17: =E6*(1+E11)^11 -> 8649755.9
A18: 이메일 수집 (M12) | B18: =B17*B7 -> 342.06787 | C18: =C17*C7 -> 22290.251 | D18: =D17*D7 -> 250902.46 | E18: =E17*E7 -> 6919804.7
A19: Tier1 구매 (8유형) | B19: =B18*B8*8 -> 82.096289 | C19: =C18*C8*8 -> 14265.761 | D19: =D18*D8*8 -> 240866.36 | E19: =E18*E8*8 -> 9964518.8
A20: Tier2 구매 (8유형) | B20: =B19*B9 -> 16.419258 | C20: =C19*C9 -> 5706.3043 | D20: =D19*D9 -> 132476.5 | E20: =E19*E9 -> 6975163.1
A21: Tier3 구매 (8유형) | B21: =B20*B10 -> 1.6419258 | C21: =C20*C10 -> 1426.5761 | D21: =D20*D10 -> 52990.599 | E21: =E20*E10 -> 3836339.7
A22: Tier1 매출 | B22: =B19*15 -> 1231.4443 | C22: =C19*15 -> 213986.41 | D22: =D19*15 -> 3612995.4 | E22: =E19*15 -> 1.4946778e+08
A23: Tier2 매출 | B23: =B20*24 -> 394.06219 | C23: =C20*24 -> 136951.3 | D23: =D20*24 -> 3179435.9 | E23: =E20*24 -> 167403915
A24: Tier3 매출 | B24: =B21*29 -> 47.615848 | C24: =C21*29 -> 41370.706 | D24: =D21*29 -> 1536727.4 | E24: =E21*29 -> 1.1125385e+08
A25: 총 매출 Gross | B25: =B22+B23+B24 -> 1673.1224 | C25: =C22+C23+C24 -> 392308.42 | D25: =D22+D23+D24 -> 8329158.6 | E25: =E22+E23+E24 -> 4.2812555e+08
A26: 차감: Hotmart 수수료 (T1:20% · T2/T3:9.9%+$0.50/건) | B26: =-(B22*0.2+B23*0.099+B20*0.5+B24*0.099+B21*0.5) -> -299.04558 | C26: =-(C22*0.2+C23*0.099+C20*0.5+C24*0.099+C21*0.5) -> -64017.601 | D26: =-(D22*0.2+D23*0.099+D20*0.5+D24*0.099+D21*0.5) -> -1282232.8 | E26: =-(E22*0.2+E23*0.099+E20*0.5+E24*0.099+E21*0.5) -> -62886427
A27: 차감: 제휴 커미션 (순액 기준 · 티어별 비중) | B27: =-(B22*(1-0.2)*0.7*B12+(B23*(1-0.099)-B20*0.5)*0.5*B13+(B24*(1-0.099)-B21*0.5)*0.5*B14) -> -380.54048 | C27: =-(C22*(1-0.2)*0.7*C12+(C23*(1-0.099)-C20*0.5)*0.5*C13+(C24*(1-0.099)-C21*0.5)*0.5*C14) -> -115774.99 | D27: =-(D22*(1-0.2)*0.7*D12+(D23*(1-0.099)-D20*0.5)*0.5*D13+(D24*(1-0.099)-D21*0.5)*0.5*D14) -> -2516446 | E27: =-(E22*(1-0.2)*0.7*E12+(E23*(1-0.099)-E20*0.5)*0.5*E13+(E24*(1-0.099)-E21*0.5)*0.5*E14) -> -1.3110093e+08
A28: ▶ 월 순 수익 (M12) | B28: =B25+B26+B27 -> 993.53631 | C28: =C25+C26+C27 -> 212515.82 | D28: =D25+D26+D27 -> 4530479.9 | E28: =E25+E26+E27 -> 2.3413819e+08
A29: ★ 연간 순 수익 | B29: =B28*12 -> 11922.436 | C29: =C28*12 -> 2550189.9 | D29: =D28*12 -> 54365759 | E29: =E28*12 -> 2.8096583e+09
A31: 💰 원화 환산 (₩1,400/$1)
A32: 월 순 수익 (₩) | B32: =B28*1400 -> 1390950.8 | C32: =C28*1400 -> 2.9752215e+08 | D32: =D28*1400 -> 6.3426718e+09 | E32: =E28*1400 -> 3.2779347e+11
A33: 연간 순 수익 (₩) | B33: =B29*1400 -> 16691410 | C33: =C29*1400 -> 3.5702659e+09 | D33: =D29*1400 -> 7.6112062e+10 | E33: =E29*1400 -> 3.9335216e+12
A35: ⚡ 전략 인사이트
A36: ✅ T1 제휴 70%는 '미끼'가 아니라 '엔진' — 제휴사 $8.40/건에 눈 돌아가서 미친 듯 홍보. 무료진단 바이럴 자동화.
A37: ✅ T1 구매자 → 이메일 수집 완료 → T2/T3는 직접 업셀. 제휴 비중 T1:80% → T3:10%로 역전 → 민철님 수익 구조 탄탄.
A38: ✅ 보수적도 연 ₩1억+. 기본 시나리오 달성 시 월 순수익 $30만+. 이건 8유형 완전판 기준, SPARK+VISION 2유형만으로도 1/4 규모 바로 런칭 가능.
A39: ⚠ 드림 시나리오(월 10만 명 진단) — loveTWO 바이럴 + 스페인어판 + 미국 시장 진출 필요.

Sheet 유형별 대시보드
A1: 🌟 8유형 × 3티어 손익 대시보드 — 유형별 월 매출 & 순 수익 (M1 기준 · 제휴 중심)
A2: 가정값 시트 전환율 기준 · 각 유형 독립 계산 · T1 제휴 80% / T2 30% / T3 10% 반영
A4: 유형 | B4: T1 수량 | C4: T2 수량 | D4: T3 수량 | E4: T1 매출 | F4: T2 매출 | G4: T3 매출 | H4: Gross 합계 | I4: Hotmart 차감 | J4: 제휴 차감 | K4: 민철님 수익 | L4: 수익률(%)
A5: SPARK | B5: =가정값!$B$34 -> 30 | C5: =가정값!$B$35 -> 12 | D5: =가정값!$B$36 -> 3 | E5: =B5*15 -> 450 | F5: =C5*24 -> 288 | G5: =D5*29 -> 87 | H5: =E5+F5+G5 -> 825 | I5: =-(E5*0.2+F5*0.099+C5*0.5+G5*0.099+D5*0.5) -> -134.625 | J5: =-(E5*(1-0.2)*0.7*가정값!$B$28+(F5*(1-0.099)-C5*0.5)*0.5*가정값!$B$29+(G5*(1-0.099)-D5*0.5)*0.5*가정값!$B$30) -> -243.46755 | K5: =H5+I5+J5 -> 446.90745 | L5: =IF(H5>0,K5/H5,0) -> 0.541706
A6: STEADY | B6: =가정값!$B$34 -> 30 | C6: =가정값!$B$35 -> 12 | D6: =가정값!$B$36 -> 3 | E6: =B6*15 -> 450 | F6: =C6*24 -> 288 | G6: =D6*29 -> 87 | H6: =E6+F6+G6 -> 825 | I6: =-(E6*0.2+F6*0.099+C6*0.5+G6*0.099+D6*0.5) -> -134.625 | J6: =-(E6*(1-0.2)*0.7*가정값!$B$28+(F6*(1-0.099)-C6*0.5)*0.5*가정값!$B$29+(G6*(1-0.099)-D6*0.5)*0.5*가정값!$B$30) -> -243.46755 | K6: =H6+I6+J6 -> 446.90745 | L6: =IF(H6>0,K6/H6,0) -> 0.541706
A7: PLAYER | B7: =가정값!$B$34 -> 30 | C7: =가정값!$B$35 -> 12 | D7: =가정값!$B$36 -> 3 | E7: =B7*15 -> 450 | F7: =C7*24 -> 288 | G7: =D7*29 -> 87 | H7: =E7+F7+G7 -> 825 | I7: =-(E7*0.2+F7*0.099+C7*0.5+G7*0.099+D7*0.5) -> -134.625 | J7: =-(E7*(1-0.2)*0.7*가정값!$B$28+(F7*(1-0.099)-C7*0.5)*0.5*가정값!$B$29+(G7*(1-0.099)-D7*0.5)*0.5*가정값!$B$30) -> -243.46755 | K7: =H7+I7+J7 -> 446.90745 | L7: =IF(H7>0,K7/H7,0) -> 0.541706
A8: VISION | B8: =가정값!$B$34 -> 30 | C8: =가정값!$B$35 -> 12 | D8: =가정값!$B$36 -> 3 | E8: =B8*15 -> 450 | F8: =C8*24 -> 288 | G8: =D8*29 -> 87 | H8: =E8+F8+G8 -> 825 | I8: =-(E8*0.2+F8*0.099+C8*0.5+G8*0.099+D8*0.5) -> -134.625 | J8: =-(E8*(1-0.2)*0.7*가정값!$B$28+(F8*(1-0.099)-C8*0.5)*0.5*가정값!$B$29+(G8*(1-0.099)-D8*0.5)*0.5*가정값!$B$30) -> -243.46755 | K8: =H8+I8+J8 -> 446.90745 | L8: =IF(H8>0,K8/H8,0) -> 0.541706
A9: LOGIC | B9: =가정값!$B$34 -> 30 | C9: =가정값!$B$35 -> 12 | D9: =가정값!$B$36 -> 3 | E9: =B9*15 -> 450 | F9: =C9*24 -> 288 | G9: =D9*29 -> 87 | H9: =E9+F9+G9 -> 825 | I9: =-(E9*0.2+F9*0.099+C9*0.5+G9*0.099+D9*0.5) -> -134.625 | J9: =-(E9*(1-0.2)*0.7*가정값!$B$28+(F9*(1-0.099)-C9*0.5)*0.5*가정값!$B$29+(G9*(1-0.099)-D9*0.5)*0.5*가정값!$B$30) -> -243.46755 | K9: =H9+I9+J9 -> 446.90745 | L9: =IF(H9>0,K9/H9,0) -> 0.541706
A10: HARMONY | B10: =가정값!$B$34 -> 30 | C10: =가정값!$B$35 -> 12 | D10: =가정값!$B$36 -> 3 | E10: =B10*15 -> 450 | F10: =C10*24 -> 288 | G10: =D10*29 -> 87 | H10: =E10+F10+G10 -> 825 | I10: =-(E10*0.2+F10*0.099+C10*0.5+G10*0.099+D10*0.5) -> -134.625 | J10: =-(E10*(1-0.2)*0.7*가정값!$B$28+(F10*(1-0.099)-C10*0.5)*0.5*가정값!$B$29+(G10*(1-0.099)-D10*0.5)*0.5*가정값!$B$30) -> -243.46755 | K10: =H10+I10+J10 -> 446.90745 | L10: =IF(H10>0,K10/H10,0) -> 0.541706
A11: LEADER | B11: =가정값!$B$34 -> 30 | C11: =가정값!$B$35 -> 12 | D11: =가정값!$B$36 -> 3 | E11: =B11*15 -> 450 | F11: =C11*24 -> 288 | G11: =D11*29 -> 87 | H11: =E11+F11+G11 -> 825 | I11: =-(E11*0.2+F11*0.099+C11*0.5+G11*0.099+D11*0.5) -> -134.625 | J11: =-(E11*(1-0.2)*0.7*가정값!$B$28+(F11*(1-0.099)-C11*0.5)*0.5*가정값!$B$29+(G11*(1-0.099)-D11*0.5)*0.5*가정값!$B$30) -> -243.46755 | K11: =H11+I11+J11 -> 446.90745 | L11: =IF(H11>0,K11/H11,0) -> 0.541706
A12: SOUL | B12: =가정값!$B$34 -> 30 | C12: =가정값!$B$35 -> 12 | D12: =가정값!$B$36 -> 3 | E12: =B12*15 -> 450 | F12: =C12*24 -> 288 | G12: =D12*29 -> 87 | H12: =E12+F12+G12 -> 825 | I12: =-(E12*0.2+F12*0.099+C12*0.5+G12*0.099+D12*0.5) -> -134.625 | J12: =-(E12*(1-0.2)*0.7*가정값!$B$28+(F12*(1-0.099)-C12*0.5)*0.5*가정값!$B$29+(G12*(1-0.099)-D12*0.5)*0.5*가정값!$B$30) -> -243.46755 | K12: =H12+I12+J12 -> 446.90745 | L12: =IF(H12>0,K12/H12,0) -> 0.541706
A14: 8유형 합계 | B14: =SUM(B5:B13) -> 240 | C14: =SUM(C5:C13) -> 96 | D14: =SUM(D5:D13) -> 24 | E14: =SUM(E5:E13) -> 3600 | F14: =SUM(F5:F13) -> 2304 | G14: =SUM(G5:G13) -> 696 | H14: =SUM(H5:H13) -> 6600 | I14: =SUM(I5:I13) -> -1077 | ... K14: =SUM(K5:K13) -> 3575.2596 | L14: =IF(H14>0,K14/H14,0) -> 0.541706
A16: 💰 민철님 실수령 요약 (건당 · M1 기준)
A17: T1 직접판매 실수령/건 | B17: =가정값!B45 -> 3.6
A18: T2 직접판매 실수령/건 | B18: =가정값!B46 -> 10.562
A19: T3 직접판매 실수령/건 | B19: =가정값!B47 -> 12.8145
A20: 월 총 민철님 수익 (8유형 합산) | B20: =K14 -> 3575.2596
A21: 월 총 민철님 수익 (₩) | B21: =K14*1400 -> 5005363.4
