Workbook

Sheet 가정값
A1: ☀ ShiningShadow SOLO — Hotmart 스페인어판 수익 시뮬레이터 v5 (멕시코·콜롬비아·칠레 3국 집중)
A2: 🔵 파란색=직접입력(가정값) ⚫ 검정=자동계산 | 가격 근거: 시장 조사 스윗스팟 (16P $29 이하, 충동구매 범위)
A4: ① 상품 가격 구조 — 스윗스팟 적용 (스페인어판)
A5: 상품 | B5: 가격 (USD) | C5: 근거 / 포지셔닝
A6: Tier 1 · Guía Básica + Apéndice A | B6: 15 | C6: $15 · 마이크로트랜잭션 한계선 · 충동구매 최적 · 月소득 0.8~1.3%
A7: Tier 2 · Guía Profunda (T1 포함 + B) | B7: 27 | C7: $27 · 16Personalities $29 바로 아래 · '더 나은 선택' 포지셔닝
A8: Tier 3 · Guía Maestra (T2 포함 + C) | B8: 34 | C8: $34 · Human Design 리포트 $35 수준 · 완전판 정당화
A9: Reporte de Visión General (무료) | B9: 0 | C9: FREE · 이메일 수집 미끼 · 유형별 PDF 8종
A11: ② Hotmart 수수료 구조 (확정)
A12: 항목 | B12: 값 | C12: 설명
A13: T1 수수료율 ($15 마이크로트랜잭션) | B13: 0.2 | C13: 20% 고정 (≤$15)
A14: T2 수수료율 ($27) | B14: 0.099 | C14: 9.9% + $0.50 고정액
A15: T3 수수료율 ($34) | B15: 0.099 | C15: 9.9% + $0.50 고정액
A16: 고정액/건 (T2·T3) | B16: 0.5 | C16: $0.50 추가 차감
A18: ③ 제휴 커미션 전략 — 시장 조사 스윗스팟
A19: 티어 | B19: 커미션율 | C19: 제휴사 실수령/건 | D19: 민철님 직접/건 | E19: 전략
A20: T1 커미션율 | B20: 0.7 | C20: =B6*(1-B13)*B20 -> 8.4 | D20: =B6*(1-B13)*(1-B20) -> 3.6 | E20: 시장 최고 수준 → '눈 돌아가서' 제휴사 폭발 홍보
A21: T2 커미션율 | B21: 0.45 | C21: =(B7*(1-B14)-B16)*B21 -> 10.72215 | D21: =(B7*(1-B14)-B16)*(1-B21) -> 13.10485 | E21: 45% · 가격 올려도 실수령 ↑
A22: T3 커미션율 | B22: 0.4 | C22: =(B8*(1-B15)-B16)*B22 -> 12.0536 | D22: =(B8*(1-B15)-B16)*(1-B22) -> 18.0804 | E22: 40% · $34 기준 제휴사 $13.3/건
A24: ④ 제휴 경유 비중 (티어별)
A25: 티어 | B25: 제휴 비중 | C25: 직접 비중 | D25: 전략 이유
A26: T1 제휴 경유 비중 | B26: 0.8 | C26: =1-B26 -> 0.2 | D26: T1 70%로 제휴사 폭발 → 이메일 리스트 대규모 확보
A27: T2 제휴 경유 비중 | B27: 0.3 | C27: =1-B27 -> 0.7 | D27: 이메일 직접 업셀 70% → 민철님 몫 극대화
A28: T3 제휴 경유 비중 | B28: 0.1 | C28: =1-B28 -> 0.9 | D28: 충성 고객 직접 90% → 민철님 수익률 최고
A30: ⑤ 3국 퍼널 전환율 가정 — 국가별 차등 적용
A31: 항목 | B31: 멕시코🇲🇽 | C31: 콜롬비아🇨🇴 | D31: 칠레🇨🇱 | E31: 가중평균 | F31: 근거
A32: 월 Shadowgram 진단 완료 수 | B32: 3000 | C32: 1200 | D32: 800 | E32: =B32*0.5+C32*0.3+D32*0.2 -> 2020 | F32: 멕시코 최대 시장, 칠레 구매력 최고
A33: 이메일 입력률 | B33: 0.62 | C33: 0.58 | D33: 0.65 | E33: =B33*0.5+C33*0.3+D33*0.2 -> 0.614 | F33: WhatsApp 강국 → 이메일 수집 적극
A34: 무료개요 → T1 전환율 | B34: 0.08 | C34: 0.07 | D34: 0.1 | E34: =B34*0.5+C34*0.3+D34*0.2 -> 0.081 | F34: 칠레 구매력↑ → T1 전환 높음
A35: T1 → T2 업셀율 | B35: 0.38 | C35: 0.35 | D35: 0.42 | E35: =B35*0.5+C35*0.3+D35*0.2 -> 0.379 | F35: 깜짝선물 D+3 이메일 기준
A36: T2 → T3 업셀율 | B36: 0.23 | C36: 0.2 | D36: 0.28 | E36: =B36*0.5+C36*0.3+D36*0.2 -> 0.231 | F36: $5 더 완전판 → 칠레 전환↑
A37: 월 성장률 (바이럴 복리) | B37: 0.18 | C37: 0.15 | D37: 0.22 | E37: =B37*0.5+C37*0.3+D37*0.2 -> 0.179 | F37: personalismo 문화 → SNS 공유
A39: ⑥ 건당 수익 구조 (자동계산 · 참조용)
A40: 티어 | B40: 판매가 | C40: Hotmart 차감 | D40: 순액 (Net) | E40: 제휴사/건 | F40: 민철님 직접/건
A41: T1 · Guía Básica $15 | B41: =B6 -> 15 | C41: =B6*B13 -> 3 | D41: =B6*(1-B13) -> 12 | E41: =B6*(1-B13)*B20 -> 8.4 | F41: =B6*(1-B13)*(1-B20) -> 3.6
A42: T2 · Guía Profunda $27 | B42: =B7 -> 27 | C42: =B7*B14+B16 -> 3.173 | D42: =B7*(1-B14)-B16 -> 23.827 | E42: =(B7*(1-B14)-B16)*B21 -> 10.72215 | F42: =(B7*(1-B14)-B16)*(1-B21) -> 13.10485
A43: T3 · Guía Maestra $34 | B43: =B8 -> 34 | C43: =B8*B15+B16 -> 3.866 | D43: =B8*(1-B15)-B16 -> 30.134 | E43: =(B8*(1-B15)-B16)*B22 -> 12.0536 | F43: =(B8*(1-B15)-B16)*(1-B22) -> 18.0804
A45: ⑦ 경쟁사 가격 비교 (시장 조사 기준)
A46: 서비스 | B46: T1 상당 | C46: T2 상당 | D46: T3 상당 | E46: 비고
A47: 16Personalities | B47: - | C47: $29 | D47: $39 | E47: Premium Career Suite
...

Sheet 국가별 시뮬레이션
A1: 📊 국가별 월별 성장 시뮬레이션 — 멕시코·콜롬비아·칠레 × M1~M12
A2: 가정값 시트 전환율 적용 · 국가별 차등 성장 · T1 제휴 80% 바이럴 엔진 · 수식 자동계산
A4: 🇲🇽 멕시코 — 월별 퍼널 & 수익 시뮬레이션
A5: 항목 | B5: M1 기준 | C5: M1 | D5: M2 | E5: M3 | F5: M4 | G5: M5 | H5: M6 | I5: M7 | J5: M8 | K5: M9 | L5: M10 | M5: M11 | N5: M12 | O5: 12개월 합계
A6: 진단 완료 | B6: ↑ 가정값 | C6: =가정값!B32 -> 3000 | D6: =가정값!B32*(1+가정값!B37)^1 -> 3540 | E6: =가정값!B32*(1+가정값!B37)^2 -> 4177.2 | F6: =가정값!B32*(1+가정값!B37)^3 -> 4929.096 | G6: =가정값!B32*(1+가정값!B37)^4 -> 5816.3333 | H6: =가정값!B32*(1+가정값!B37)^5 -> 6863.2733 | I6: =가정값!B32*(1+가정값!B37)^6 -> 8098.6625 | J6: =가정값!B32*(1+가정값!B37)^7 -> 9556.4217 | K6: =가정값!B32*(1+가정값!B37)^8 -> 11276.578 | L6: =가정값!B32*(1+가정값!B37)^9 -> 13306.362 | M6: =가정값!B32*(1+가정값!B37)^10 -> 15701.507 | N6: =가정값!B32*(1+가정값!B37)^11 -> 18527.778 | O6: =SUM(C6:N6) -> 104793.21
A7: 이메일 수집 | B7: ↑ 가정값 | C7: =C6*가정값!B33 -> 1860 | D7: =D6*가정값!B33 -> 2194.8 | E7: =E6*가정값!B33 -> 2589.864 | F7: =F6*가정값!B33 -> 3056.0395 | G7: =G6*가정값!B33 -> 3606.1266 | H7: =H6*가정값!B33 -> 4255.2294 | I7: =I6*가정값!B33 -> 5021.1707 | J7: =J6*가정값!B33 -> 5924.9815 | K7: =K6*가정값!B33 -> 6991.4781 | L7: =L6*가정값!B33 -> 8249.9442 | M7: =M6*가정값!B33 -> 9734.9341 | N7: =N6*가정값!B33 -> 11487.222 | O7: =SUM(C7:N7) -> 64971.79
A8: T1 구매 (8유형) | B8: ↑ 가정값 | C8: =C7*가정값!B34*8 -> 1190.4 | D8: =D7*가정값!B34*8 -> 1404.672 | E8: =E7*가정값!B34*8 -> 1657.513 | F8: =F7*가정값!B34*8 -> 1955.8653 | G8: =G7*가정값!B34*8 -> 2307.921 | H8: =H7*가정값!B34*8 -> 2723.3468 | I8: =I7*가정값!B34*8 -> 3213.5493 | J8: =J7*가정값!B34*8 -> 3791.9881 | K8: =K7*가정값!B34*8 -> 4474.546 | L8: =L7*가정값!B34*8 -> 5279.9643 | M8: =M7*가정값!B34*8 -> 6230.3578 | N8: =N7*가정값!B34*8 -> 7351.8223 | O8: =SUM(C8:N8) -> 41581.946
A9: T2 구매 | B9: ↑ 가정값 | C9: =C8*가정값!B35 -> 452.352 | D9: =D8*가정값!B35 -> 533.77536 | E9: =E8*가정값!B35 -> 629.85492 | F9: =F8*가정값!B35 -> 743.22881 | G9: =G8*가정값!B35 -> 877.01 | H9: =H8*가정값!B35 -> 1034.8718 | I9: =I8*가정값!B35 -> 1221.1487 | J9: =J8*가정값!B35 -> 1440.9555 | K9: =K8*가정값!B35 -> 1700.3275 | L9: =L8*가정값!B35 -> 2006.3864 | M9: =M8*가정값!B35 -> 2367.536 | N9: =N8*가정값!B35 -> 2793.6925 | O9: =SUM(C9:N9) -> 15801.139
A10: T3 구매 | B10: ↑ 가정값 | C10: =C9*가정값!B36 -> 104.04096 | D10: =D9*가정값!B36 -> 122.76833 | E10: =E9*가정값!B36 -> 144.86663 | F10: =F9*가정값!B36 -> 170.94263 | G10: =G9*가정값!B36 -> 201.7123 | H10: =H9*가정값!B36 -> 238.02051 | I10: =I9*가정값!B36 -> 280.86421 | J10: =J9*가정값!B36 -> 331.41976 | K10: =K9*가정값!B36 -> 391.07532 | L10: =L9*가정값!B36 -> 461.46888 | M10: =M9*가정값!B36 -> 544.53328 | N10: =N9*가정값!B36 -> 642.54927 | O10: =SUM(C10:N10) -> 3634.2621
A11: T1 매출 (Gross) | C11: =C8*가정값!$B$6 -> 17856 | D11: =D8*가정값!$B$6 -> 21070.08 | E11: =E8*가정값!$B$6 -> 24862.694 | F11: =F8*가정값!$B$6 -> 29337.979 | G11: =G8*가정값!$B$6 -> 34618.816 | H11: =H8*가정값!$B$6 -> 40850.203 | I11: =I8*가정값!$B$6 -> 48203.239 | J11: =J8*가정값!$B$6 -> 56879.822 | ... N11: =N8*가정값!$B$6 -> 110277.33 | O11: =SUM(C11:N11) -> 623729.19
A12: T2 매출 (Gross) | C12: =C9*가정값!$B$7 -> 12213.504 | D12: =D9*가정값!$B$7 -> 14411.935 | E12: =E9*가정값!$B$7 -> 17006.083 | F12: =F9*가정값!$B$7 -> 20067.178 | G12: =G9*가정값!$B$7 -> 23679.27 | H12: =H9*가정값!$B$7 -> 27941.539 | I12: =I9*가정값!$B$7 -> 32971.015 | J12: =J9*가정값!$B$7 -> 38905.798 | ... N12: =N9*가정값!$B$7 -> 75429.696 | O12: =SUM(C12:N12) -> 426630.76
A13: T3 매출 (Gross) | C13: =C10*가정값!$B$8 -> 3537.3926 | D13: =D10*가정값!$B$8 -> 4174.1233 | E13: =E10*가정값!$B$8 -> 4925.4655 | F13: =F10*가정값!$B$8 -> 5812.0493 | G13: =G10*가정값!$B$8 -> 6858.2182 | H13: =H10*가정값!$B$8 -> 8092.6975 | I13: =I10*가정값!$B$8 -> 9549.383 | J13: =J10*가정값!$B$8 -> 11268.272 | ... N13: =N10*가정값!$B$8 -> 21846.675 | O13: =SUM(C13:N13) -> 123564.91
A14: 총 매출 (Gross) | C14: =C11+C12+C13 -> 33606.897 | D14: =D11+D12+D13 -> 39656.138 | E14: =E11+E12+E13 -> 46794.243 | F14: =F11+F12+F13 -> 55217.207 | G14: =G11+G12+G13 -> 65156.304 | H14: =H11+H12+H13 -> 76884.438 | I14: =I11+I12+I13 -> 90723.637 | J14: =J11+J12+J13 -> 107053.89 | ... N14: =N11+N12+N13 -> 207553.71 | O14: =SUM(C14:N14) -> 1173924.9
A15: 차감: Hotmart 수수료 | C15: =-(C11*가정값!$B$13+C12*가정값!$B$14+C9*가정값!$B$16+C13*가정값!$B$15+C10*가정값!$B$16) -> -5408.7352 | D15: =-(D11*가정값!$B$13+D12*가정값!$B$14+D9*가정값!$B$16+D13*가정값!$B$15+D10*가정값!$B$16) -> -6382.3076 | E15: =-(E11*가정값!$B$13+E12*가정값!$B$14+E9*가정값!$B$16+E13*가정값!$B$15+E10*가정값!$B$16) -> -7531.123 | F15: =-(F11*가정값!$B$13+F12*가정값!$B$14+F9*가정값!$B$16+F13*가정값!$B$15+F10*가정값!$B$16) -> -8886.7251 | G15: =-(G11*가정값!$B$13+G12*가정값!$B$14+G9*가정값!$B$16+G13*가정값!$B$15+G10*가정값!$B$16) -> -10486.336 | H15: =-(H11*가정값!$B$13+H12*가정값!$B$14+H9*가정값!$B$16+H13*가정값!$B$15+H10*가정값!$B$16) -> -12373.876 | I15: =-(I11*가정값!$B$13+I12*가정값!$B$14+I9*가정값!$B$16+I13*가정값!$B$15+I10*가정값!$B$16) -> -14601.174 | J15: =-(J11*가정값!$B$13+J12*가정값!$B$14+J9*가정값!$B$16+J13*가정값!$B$15+J10*가정값!$B$16) -> -17229.385 | ... N15: =-(N11*가정값!$B$13+N12*가정값!$B$14+N9*가정값!$B$16+N13*가정값!$B$15+N10*가정값!$B$16) -> -33403.948 | O15: =SUM(C15:N15) -> -188932.91
A16: 차감: 제휴 커미션 (티어별 비중) | C16: =-(C11*(1-가정값!$B$13)*가정값!$B$20*가정값!$B$26+(C12*(1-가정값!$B$14)-C9*가정값!$B$16)*가정값!$B$21*가정값!$B$27+(C13*(1-가정값!$B$15)-C10*가정값!$B$16)*가정값!$B$22*가정값!$B$28) -> -9579.9506 | D16: =-(D11*(1-가정값!$B$13)*가정값!$B$20*가정값!$B$26+(D12*(1-가정값!$B$14)-D9*가정값!$B$16)*가정값!$B$21*가정값!$B$27+(D13*(1-가정값!$B$15)-D10*가정값!$B$16)*가정값!$B$22*가정값!$B$28) -> -11304.342 | E16: =-(E11*(1-가정값!$B$13)*가정값!$B$20*가정값!$B$26+(E12*(1-가정값!$B$14)-E9*가정값!$B$16)*가정값!$B$21*가정값!$B$27+(E13*(1-가정값!$B$15)-E10*가정값!$B$16)*가정값!$B$22*가정값!$B$28) -> -13339.123 | F16: =-(F11*(1-가정값!$B$13)*가정값!$B$20*가정값!$B$26+(F12*(1-가정값!$B$14)-F9*가정값!$B$16)*가정값!$B$21*가정값!$B$27+(F13*(1-가정값!$B$15)-F10*가정값!$B$16)*가정값!$B$22*가정값!$B$28) -> -15740.165 | G16: =-(G11*(1-가정값!$B$13)*가정값!$B$20*가정값!$B$26+(G12*(1-가정값!$B$14)-G9*가정값!$B$16)*가정값!$B$21*가정값!$B$27+(G13*(1-가정값!$B$15)-G10*가정값!$B$16)*가정값!$B$22*가정값!$B$28) -> -18573.395 | H16: =-(H11*(1-가정값!$B$13)*가정값!$B$20*가정값!$B$26+(H12*(1-가정값!$B$14)-H9*가정값!$B$16)*가정값!$B$21*가정값!$B$27+(H13*(1-가정값!$B$15)-H10*가정값!$B$16)*가정값!$B$22*가정값!$B$28) -> -21916.606 | I16: =-(I11*(1-가정값!$B$13)*가정값!$B$20*가정값!$B$26+(I12*(1-가정값!$B$14)-I9*가정값!$B$16)*가정값!$B$21*가정값!$B$27+(I13*(1-가정값!$B$15)-I10*가정값!$B$16)*가정값!$B$22*가정값!$B$28) -> -25861.595 | J16: =-(J11*(1-가정값!$B$13)*가정값!$B$20*가정값!$B$26+(J12*(1-가정값!$B$14)-J9*가정값!$B$16)*가정값!$B$21*가정값!$B$27+(J13*(1-가정값!$B$15)-J10*가정값!$B$16)*가정값!$B$22*가정값!$B$28) -> -30516.683 | ... N16: =-(N11*(1-가정값!$B$13)*가정값!$B$20*가정값!$B$26+(N12*(1-가정값!$B$14)-N9*가정값!$B$16)*가정값!$B$21*가정값!$B$27+(N13*(1-가정값!$B$15)-N10*가정값!$B$16)*가정값!$B$22*가정값!$B$28) -> -59165.066 | O16: =SUM(C16:N16) -> -334637.93
A17: ▶ 월 순 수익 | C17: =C14+C15+C16 -> 18618.211 | D17: =D14+D15+D16 -> 21969.489 | E17: =E14+E15+E16 -> 25923.997 | F17: =F14+F15+F16 -> 30590.316 | G17: =G14+G15+G16 -> 36096.573 | H17: =H14+H15+H16 -> 42593.956 | I17: =I14+I15+I16 -> 50260.868 | J17: =J14+J15+J16 -> 59307.825 | ... N17: =N14+N15+N16 -> 114984.69 | O17: =SUM(C17:N17) -> 650354.03
A18: 누적 순 수익 | C18: =C17 -> 18618.211 | D18: =C18+D17 -> 40587.7 | E18: =D18+E17 -> 66511.696 | F18: =E18+F17 -> 97102.012 | G18: =F18+G17 -> 133198.59 | H18: =G18+H17 -> 175792.54 | I18: =H18+I17 -> 226053.41 | J18: =I18+J17 -> 285361.23 | K18: =J18+K17 -> 355344.47 | ... N18: =M18+N17 -> 650354.03 | O18: =N18 -> 650354.03
A19: 민철님 실수익 (제휴차감 후) | C19: =C17 -> 18618.211 | D19: =D17 -> 21969.489 | E19: =E17 -> 25923.997 | F19: =F17 -> 30590.316 | G19: =G17 -> 36096.573 | H19: =H17 -> 42593.956 | I19: =I17 -> 50260.868 | J19: =J17 -> 59307.825 | ... N19: =N17 -> 114984.69 | O19: =SUM(C19:N19) -> 650354.03
A20: 원화 환산 (₩1,400/$) | C20: =C19*1400 -> 26065495 | D20: =D19*1400 -> 30757284 | E20: =E19*1400 -> 36293595 | F20: =F19*1400 -> 42826443 | G20: =G19*1400 -> 50535202 | H20: =H19*1400 -> 59631539 | I20: =I19*1400 -> 70365216 | J20: =J19*1400 -> 83030954 | ... N20: =N19*1400 -> 1.6097857e+08 | O20: =N20*1400 -> 2.2536999e+11
A22: 🇨🇴 콜롬비아 — 월별 퍼널 & 수익 시뮬레이션
A23: 항목 | B23: M1 기준 | C23: M1 | D23: M2 | E23: M3 | F23: M4 | G23: M5 | H23: M6 | I23: M7 | J23: M8 | K23: M9 | L23: M10 | M23: M11 | N23: M12 | O23: 12개월 합계
A24: 진단 완료 | B24: ↑ 가정값 | C24: =가정값!C32 -> 1200 | D24: =가정값!C32*(1+가정값!C37)^1 -> 1380 | E24: =가정값!C32*(1+가정값!C37)^2 -> 1587 | F24: =가정값!C32*(1+가정값!C37)^3 -> 1825.05 | G24: =가정값!C32*(1+가정값!C37)^4 -> 2098.8075 | H24: =가정값!C32*(1+가정값!C37)^5 -> 2413.6286 | I24: =가정값!C32*(1+가정값!C37)^6 -> 2775.6729 | J24: =가정값!C32*(1+가정값!C37)^7 -> 3192.0239 | K24: =가정값!C32*(1+가정값!C37)^8 -> 3670.8274 | L24: =가정값!C32*(1+가정값!C37)^9 -> 4221.4516 | M24: =가정값!C32*(1+가정값!C37)^10 -> 4854.6693 | N24: =가정값!C32*(1+가정값!C37)^11 -> 5582.8697 | O24: =SUM(C24:N24) -> 34802.001
A25: 이메일 수집 | B25: ↑ 가정값 | C25: =C24*가정값!C33 -> 696 | D25: =D24*가정값!C33 -> 800.4 | E25: =E24*가정값!C33 -> 920.46 | F25: =F24*가정값!C33 -> 1058.529 | G25: =G24*가정값!C33 -> 1217.3084 | H25: =H24*가정값!C33 -> 1399.9046 | I25: =I24*가정값!C33 -> 1609.8903 | J25: =J24*가정값!C33 -> 1851.3738 | K25: =K24*가정값!C33 -> 2129.0799 | L25: =L24*가정값!C33 -> 2448.4419 | M25: =M24*가정값!C33 -> 2815.7082 | N25: =N24*가정값!C33 -> 3238.0644 | O25: =SUM(C25:N25) -> 20185.16
A26: T1 구매 (8유형) | B26: ↑ 가정값 | C26: =C25*가정값!C34*8 -> 389.76 | D26: =D25*가정값!C34*8 -> 448.224 | E26: =E25*가정값!C34*8 -> 515.4576 | F26: =F25*가정값!C34*8 -> 592.77624 | G26: =G25*가정값!C34*8 -> 681.69268 | H26: =H25*가정값!C34*8 -> 783.94658 | I26: =I25*가정값!C34*8 -> 901.53856 | J26: =J25*가정값!C34*8 -> 1036.7693 | K26: =K25*가정값!C34*8 -> 1192.2848 | L26: =L25*가정값!C34*8 -> 1371.1275 | M26: =M25*가정값!C34*8 -> 1576.7966 | N26: =N25*가정값!C34*8 -> 1813.3161 | O26: =SUM(C26:N26) -> 11303.69
A27: T2 구매 | B27: ↑ 가정값 | C27: =C26*가정값!C35 -> 136.416 | D27: =D26*가정값!C35 -> 156.8784 | E27: =E26*가정값!C35 -> 180.41016 | F27: =F26*가정값!C35 -> 207.47168 | G27: =G26*가정값!C35 -> 238.59244 | H27: =H26*가정값!C35 -> 274.3813 | I27: =I26*가정값!C35 -> 315.5385 | J27: =J26*가정값!C35 -> 362.86927 | K27: =K26*가정값!C35 -> 417.29966 | L27: =L26*가정값!C35 -> 479.89461 | M27: =M26*가정값!C35 -> 551.8788 | N27: =N26*가정값!C35 -> 634.66062 | O27: =SUM(C27:N27) -> 3956.2915
A28: T3 구매 | B28: ↑ 가정값 | C28: =C27*가정값!C36 -> 27.2832 | D28: =D27*가정값!C36 -> 31.37568 | E28: =E27*가정값!C36 -> 36.082032 | F28: =F27*가정값!C36 -> 41.494337 | G28: =G27*가정값!C36 -> 47.718487 | H28: =H27*가정값!C36 -> 54.87626 | I28: =I27*가정값!C36 -> 63.107699 | J28: =J27*가정값!C36 -> 72.573854 | K28: =K27*가정값!C36 -> 83.459933 | L28: =L27*가정값!C36 -> 95.978922 | M28: =M27*가정값!C36 -> 110.37576 | N28: =N27*가정값!C36 -> 126.93212 | O28: =SUM(C28:N28) -> 791.25829
A29: T1 매출 (Gross) | C29: =C26*가정값!$B$6 -> 5846.4 | D29: =D26*가정값!$B$6 -> 6723.36 | E29: =E26*가정값!$B$6 -> 7731.864 | F29: =F26*가정값!$B$6 -> 8891.6436 | G29: =G26*가정값!$B$6 -> 10225.39 | H29: =H26*가정값!$B$6 -> 11759.199 | I29: =I26*가정값!$B$6 -> 13523.078 | J29: =J26*가정값!$B$6 -> 15551.54 | ... N29: =N26*가정값!$B$6 -> 27199.741 | O29: =SUM(C29:N29) -> 169555.35
A30: T2 매출 (Gross) | C30: =C27*가정값!$B$7 -> 3683.232 | D30: =D27*가정값!$B$7 -> 4235.7168 | E30: =E27*가정값!$B$7 -> 4871.0743 | F30: =F27*가정값!$B$7 -> 5601.7355 | G30: =G27*가정값!$B$7 -> 6441.9958 | H30: =H27*가정값!$B$7 -> 7408.2952 | I30: =I27*가정값!$B$7 -> 8519.5394 | J30: =J27*가정값!$B$7 -> 9797.4703 | ... N30: =N27*가정값!$B$7 -> 17135.837 | O30: =SUM(C30:N30) -> 106819.87
A31: T3 매출 (Gross) | C31: =C28*가정값!$B$8 -> 927.6288 | D31: =D28*가정값!$B$8 -> 1066.7731 | E31: =E28*가정값!$B$8 -> 1226.7891 | F31: =F28*가정값!$B$8 -> 1410.8075 | G31: =G28*가정값!$B$8 -> 1622.4286 | H31: =H28*가정값!$B$8 -> 1865.7929 | I31: =I28*가정값!$B$8 -> 2145.6618 | J31: =J28*가정값!$B$8 -> 2467.511 | ... N31: =N28*가정값!$B$8 -> 4315.6922 | O31: =SUM(C31:N31) -> 26902.782
A32: 총 매출 (Gross) | C32: =C29+C30+C31 -> 10457.261 | D32: =D29+D30+D31 -> 12025.85 | E32: =E29+E30+E31 -> 13829.727 | F32: =F29+F30+F31 -> 15904.187 | G32: =G29+G30+G31 -> 18289.814 | H32: =H29+H30+H31 -> 21033.287 | I32: =I29+I30+I31 -> 24188.28 | J32: =J29+J30+J31 -> 27816.522 | ... N32: =N29+N30+N31 -> 48651.27 | O32: =SUM(C32:N32) -> 303278
A33: 차감: Hotmart 수수료 | C33: =-(C29*가정값!$B$13+C30*가정값!$B$14+C27*가정값!$B$16+C31*가정값!$B$15+C28*가정값!$B$16) -> -1707.6048 | D33: =-(D29*가정값!$B$13+D30*가정값!$B$14+D27*가정값!$B$16+D31*가정값!$B$15+D28*가정값!$B$16) -> -1963.7455 | E33: =-(E29*가정값!$B$13+E30*가정값!$B$14+E27*가정값!$B$16+E31*가정값!$B$15+E28*가정값!$B$16) -> -2258.3074 | F33: =-(F29*가정값!$B$13+F30*가정값!$B$14+F27*가정값!$B$16+F31*가정값!$B$15+F28*가정값!$B$16) -> -2597.0535 | G33: =-(G29*가정값!$B$13+G30*가정값!$B$14+G27*가정값!$B$16+G31*가정값!$B$15+G28*가정값!$B$16) -> -2986.6115 | H33: =-(H29*가정값!$B$13+H30*가정값!$B$14+H27*가정값!$B$16+H31*가정값!$B$15+H28*가정값!$B$16) -> -3434.6032 | I33: =-(I29*가정값!$B$13+I30*가정값!$B$14+I27*가정값!$B$16+I31*가정값!$B$15+I28*가정값!$B$16) -> -3949.7937 | J33: =-(J29*가정값!$B$13+J30*가정값!$B$14+J27*가정값!$B$16+J31*가정값!$B$15+J28*가정값!$B$16) -> -4542.2628 | ... N33: =-(N29*가정값!$B$13+N30*가정값!$B$14+N27*가정값!$B$16+N31*가정값!$B$15+N28*가정값!$B$16) -> -7944.446 | O33: =SUM(C33:N33) -> -49523.387
A34: 차감: 제휴 커미션 (티어별 비중) | C34: =-(C29*(1-가정값!$B$13)*가정값!$B$20*가정값!$B$26+(C30*(1-가정값!$B$14)-C27*가정값!$B$16)*가정값!$B$21*가정값!$B$27+(C31*(1-가정값!$B$15)-C28*가정값!$B$16)*가정값!$B$22*가정값!$B$28) -> -3090.8751 | D34: =-(D29*(1-가정값!$B$13)*가정값!$B$20*가정값!$B$26+(D30*(1-가정값!$B$14)-D27*가정값!$B$16)*가정값!$B$21*가정값!$B$27+(D31*(1-가정값!$B$15)-D28*가정값!$B$16)*가정값!$B$22*가정값!$B$28) -> -3554.5064 | E34: =-(E29*(1-가정값!$B$13)*가정값!$B$20*가정값!$B$26+(E30*(1-가정값!$B$14)-E27*가정값!$B$16)*가정값!$B$21*가정값!$B$27+(E31*(1-가정값!$B$15)-E28*가정값!$B$16)*가정값!$B$22*가정값!$B$28) -> -4087.6823 | F34: =-(F29*(1-가정값!$B$13)*가정값!$B$20*가정값!$B$26+(F30*(1-가정값!$B$14)-F27*가정값!$B$16)*가정값!$B$21*가정값!$B$27+(F31*(1-가정값!$B$15)-F28*가정값!$B$16)*가정값!$B$22*가정값!$B$28) -> -4700.8347 | G34: =-(G29*(1-가정값!$B$13)*가정값!$B$20*가정값!$B$26+(G30*(1-가정값!$B$14)-G27*가정값!$B$16)*가정값!$B$21*가정값!$B$27+(G31*(1-가정값!$B$15)-G28*가정값!$B$16)*가정값!$B$22*가정값!$B$28) -> -5405.9599 | H34: =-(H29*(1-가정값!$B$13)*가정값!$B$20*가정값!$B$26+(H30*(1-가정값!$B$14)-H27*가정값!$B$16)*가정값!$B$21*가정값!$B$27+(H31*(1-가정값!$B$15)-H28*가정값!$B$16)*가정값!$B$22*가정값!$B$28) -> -6216.8539 | I34: =-(I29*(1-가정값!$B$13)*가정값!$B$20*가정값!$B$26+(I30*(1-가정값!$B$14)-I27*가정값!$B$16)*가정값!$B$21*가정값!$B$27+(I31*(1-가정값!$B$15)-I28*가정값!$B$16)*가정값!$B$22*가정값!$B$28) -> -7149.382 | J34: =-(J29*(1-가정값!$B$13)*가정값!$B$20*가정값!$B$26+(J30*(1-가정값!$B$14)-J27*가정값!$B$16)*가정값!$B$21*가정값!$B$27+(J31*(1-가정값!$B$15)-J28*가정값!$B$16)*가정값!$B$22*가정값!$B$28) -> -8221.7893 | ... N34: =-(N29*(1-가정값!$B$13)*가정값!$B$20*가정값!$B$26+(N30*(1-가정값!$B$14)-N27*가정값!$B$16)*가정값!$B$21*가정값!$B$27+(N31*(1-가정값!$B$15)-N28*가정값!$B$16)*가정값!$B$22*가정값!$B$28) -> -14379.961 | O34: =SUM(C34:N34) -> -89640.532
A35: ▶ 월 순 수익 | C35: =C32+C33+C34 -> 5658.7809 | D35: =D32+D33+D34 -> 6507.598 | E35: =E32+E33+E34 -> 7483.7377 | F35: =F32+F33+F34 -> 8606.2983 | G35: =G32+G33+G34 -> 9897.2431 | H35: =H32+H33+H34 -> 11381.83 | I35: =I32+I33+I34 -> 13089.104 | J35: =J32+J33+J34 -> 15052.47 | ... N35: =N32+N33+N34 -> 26326.863 | O35: =SUM(C35:N35) -> 164114.08
A36: 누적 순 수익 | C36: =C35 -> 5658.7809 | D36: =C36+D35 -> 12166.379 | E36: =D36+E35 -> 19650.117 | F36: =E36+F35 -> 28256.415 | G36: =F36+G35 -> 38153.658 | H36: =G36+H35 -> 49535.488 | I36: =H36+I35 -> 62624.591 | J36: =I36+J35 -> 77677.061 | K36: =J36+K35 -> 94987.401 | ... N36: =M36+N35 -> 164114.08 | O36: =N36 -> 164114.08
A37: 민철님 실수익 (제휴차감 후) | C37: =C35 -> 5658.7809 | D37: =D35 -> 6507.598 | E37: =E35 -> 7483.7377 | F37: =F35 -> 8606.2983 | G37: =G35 -> 9897.2431 | H37: =H35 -> 11381.83 | I37: =I35 -> 13089.104 | J37: =J35 -> 15052.47 | ... N37: =N35 -> 26326.863 | O37: =SUM(C37:N37) -> 164114.08
A38: 원화 환산 (₩1,400/$) | C38: =C37*1400 -> 7922293.2 | D38: =D37*1400 -> 9110637.2 | E38: =E37*1400 -> 10477233 | F38: =F37*1400 -> 12048818 | G38: =G37*1400 -> 13856140 | H38: =H37*1400 -> 15934561 | I38: =I37*1400 -> 18324746 | J38: =J37*1400 -> 21073457 | ... N38: =N37*1400 -> 36857609 | O38: =N38*1400 -> 5.1600652e+10
A40: 🇨🇱 칠레 — 월별 퍼널 & 수익 시뮬레이션
A41: 항목 | B41: M1 기준 | C41: M1 | D41: M2 | E41: M3 | F41: M4 | G41: M5 | H41: M6 | I41: M7 | J41: M8 | K41: M9 | L41: M10 | M41: M11 | N41: M12 | O41: 12개월 합계
A42: 진단 완료 | B42: ↑ 가정값 | C42: =가정값!D32 -> 800 | D42: =가정값!D32*(1+가정값!D37)^1 -> 976 | E42: =가정값!D32*(1+가정값!D37)^2 -> 1190.72 | F42: =가정값!D32*(1+가정값!D37)^3 -> 1452.6784 | G42: =가정값!D32*(1+가정값!D37)^4 -> 1772.2676 | H42: =가정값!D32*(1+가정값!D37)^5 -> 2162.1665 | I42: =가정값!D32*(1+가정값!D37)^6 -> 2637.8432 | J42: =가정값!D32*(1+가정값!D37)^7 -> 3218.1687 | K42: =가정값!D32*(1+가정값!D37)^8 -> 3926.1658 | L42: =가정값!D32*(1+가정값!D37)^9 -> 4789.9222 | M42: =가정값!D32*(1+가정값!D37)^10 -> 5843.7051 | N42: =가정값!D32*(1+가정값!D37)^11 -> 7129.3203 | O42: =SUM(C42:N42) -> 35898.958
A43: 이메일 수집 | B43: ↑ 가정값 | C43: =C42*가정값!D33 -> 520 | D43: =D42*가정값!D33 -> 634.4 | E43: =E42*가정값!D33 -> 773.968 | F43: =F42*가정값!D33 -> 944.24096 | G43: =G42*가정값!D33 -> 1151.974 | H43: =H42*가정값!D33 -> 1405.4082 | I43: =I42*가정값!D33 -> 1714.5981 | J43: =J42*가정값!D33 -> 2091.8096 | K43: =K42*가정값!D33 -> 2552.0078 | L43: =L42*가정값!D33 -> 3113.4495 | M43: =M42*가정값!D33 -> 3798.4083 | N43: =N42*가정값!D33 -> 4634.0582 | O43: =SUM(C43:N43) -> 23334.323
...

Sheet 시나리오 비교
A1: 🎯 시나리오 비교 — 보수적 / 기본 / 낙관 / 드림 | 3국 가중평균 기준 | M12 월 순수익
A2: 파란색 셀 직접 수정 가능 · 3국 가중평균(멕시코50%+콜롬비아30%+칠레20%) 적용 · T1 제휴 70% 바이럴 중심
A4: 가정 항목 | B4: 보수적 😐 | C4: 기본 🙂 | D4: 낙관 😊 | E4: 드림 🚀
A5: 📥 입력 가정 (파란색 직접 수정)
A6: 월 진단 완료 수 (3국 합산) | B6: 500 | C6: 5000 | D6: 20000 | E6: 100000
A7: 이메일 입력률 | B7: 0.4 | C7: 0.62 | D7: 0.7 | E7: 0.8
A8: 무료개요 → T1 전환율 | B8: 0.03 | C8: 0.08 | D8: 0.13 | E8: 0.2
A9: T1 → T2 업셀율 | B9: 0.2 | C9: 0.39 | D9: 0.55 | E9: 0.7
A10: T2 → T3 업셀율 | B10: 0.1 | C10: 0.24 | D10: 0.4 | E10: 0.55
A11: 월 성장률 | B11: 0.05 | C11: 0.18 | D11: 0.3 | E11: 0.5
A12: T1 제휴 경유 비중 | B12: 0.5 | C12: 0.8 | D12: 0.9 | E12: 0.95
A13: T2 제휴 경유 비중 | B13: 0.2 | C13: 0.3 | D13: 0.4 | E13: 0.5
A14: T3 제휴 경유 비중 | B14: 0.05 | C14: 0.1 | D14: 0.2 | E14: 0.3
A16: 📊 M12 월 순수익 계산 (12개월 후)
A17: 진단 수 (M12) | B17: =B6*(1+B11)^11 -> 855.16968 | C17: =C6*(1+C11)^11 -> 30879.63 | D17: =D6*(1+D11)^11 -> 358432.08 | E17: =E6*(1+E11)^11 -> 8649755.9
A18: 이메일 수집 | B18: =B17*B7 -> 342.06787 | C18: =C17*C7 -> 19145.37 | D18: =D17*D7 -> 250902.46 | E18: =E17*E7 -> 6919804.7
A19: T1 구매 (8유형) | B19: =B18*B8*8 -> 82.096289 | C19: =C18*C8*8 -> 12253.037 | D19: =D18*D8*8 -> 260938.55 | E19: =E18*E8*8 -> 11071688
A20: T2 구매 | B20: =B19*B9 -> 16.419258 | C20: =C19*C9 -> 4778.6845 | D20: =D19*D9 -> 143516.2 | E20: =E19*E9 -> 7750181.2
A21: T3 구매 | B21: =B20*B10 -> 1.6419258 | C21: =C20*C10 -> 1146.8843 | D21: =D20*D10 -> 57406.482 | E21: =E20*E10 -> 4262599.7
A22: T1 매출 | B22: =15*B19 -> 1231.4443 | C22: =15*C19 -> 183795.56 | D22: =15*D19 -> 3914078.3 | E22: =15*E19 -> 1.6607531e+08
A23: T2 매출 | B23: =27*B20 -> 443.31996 | C23: =27*C20 -> 129024.48 | D23: =27*D20 -> 3874937.5 | E23: =27*E20 -> 2.0925489e+08
A24: T3 매출 | B24: =34*B21 -> 55.825477 | C24: =34*C21 -> 38994.065 | D24: =34*D21 -> 1951820.4 | E24: =34*E21 -> 1.4492839e+08
A25: 총 매출 Gross | B25: =B22+B23+B24 -> 1730.5898 | C25: =C22+C23+C24 -> 351814.1 | D25: =D22+D23+D24 -> 9740836.2 | E25: =E22+E23+E24 -> 5.202586e+08
A26: 차감: Hotmart 수수료 | B26: =-(B22*0.2+B23*0.099+B20*0.5+B24*0.099+B21*0.5) -> -304.73486 | C26: =-(C22*0.2+C23*0.099+C20*0.5+C24*0.099+C21*0.5) -> -56355.732 | D26: =-(D22*0.2+D23*0.099+D20*0.5+D24*0.099+D21*0.5) -> -1460126 | E26: =-(E22*0.2+E23*0.099+E20*0.5+E24*0.099+E21*0.5) -> -74285598
A27: 차감: 제휴 커미션 (순액·티어별) | B27: =-(B22*(1-0.2)*가정값!$B$20*B13+(B23*(1-0.099)-B20*0.5)*가정값!$B$21*B14+(B24*(1-0.099)-B21*0.5)*가정값!$B$22*B15) -> -146.72425 | C27: =-(C22*(1-0.2)*가정값!$B$20*C13+(C23*(1-0.099)-C20*0.5)*가정값!$B$21*C14+(C24*(1-0.099)-C21*0.5)*가정값!$B$22*C15) -> -36001.431 | D27: =-(D22*(1-0.2)*가정값!$B$20*D13+(D23*(1-0.099)-D20*0.5)*가정값!$B$21*D14+(D24*(1-0.099)-D21*0.5)*가정값!$B$22*D15) -> -1184514 | E27: =-(E22*(1-0.2)*가정값!$B$20*E13+(E23*(1-0.099)-E20*0.5)*가정값!$B$21*E14+(E24*(1-0.099)-E21*0.5)*가정값!$B$22*E15) -> -71430669
A28: ▶ 월 순수익 (M12) | B28: =B25+B26+B27 -> 1279.1307 | C28: =C25+C26+C27 -> 259456.94 | D28: =D25+D26+D27 -> 7096196.2 | E28: =E25+E26+E27 -> 3.7454233e+08
A29: ★ 연간 순수익 | B29: =B28*12 -> 15349.568 | C29: =C28*12 -> 3113483.3 | D29: =D28*12 -> 85154354 | E29: =E28*12 -> 4.4945079e+09
A31: 💰 원화 환산 (₩1,400/$1)
A32: 월 순수익 (₩) | B32: =B28*1400 -> 1790782.9 | C32: =C28*1400 -> 3.6323972e+08 | D32: =D28*1400 -> 9.9346746e+09 | E32: =E28*1400 -> 5.2435926e+11
A33: 연간 순수익 (₩) | B33: =B29*1400 -> 21489395 | C33: =C29*1400 -> 4.3588766e+09 | D33: =D29*1400 -> 1.192161e+11 | E33: =E29*1400 -> 6.2923111e+12
A35: 🔗 제휴사 LTV 분석 — T1 제휴사가 실제로 버는 금액
A36: 항목 | B36: 보수적 😐 | C36: 기본 🙂 | D36: 낙관 😊 | E36: 드림 🚀
A37: T1 직접 커미션/건 | B37: =가정값!B41 -> 15 | C37: =가정값!B41 -> 15 | D37: =가정값!B41 -> 15 | E37: =가정값!B41 -> 15
A38: T2 업셀 커미션 (확률반영) | B38: =가정값!B42*B9 -> 5.4 | C38: =가정값!B42*C9 -> 10.53 | D38: =가정값!B42*D9 -> 14.85 | E38: =가정값!B42*E9 -> 18.9
A39: T3 업셀 커미션 (확률반영) | B39: =가정값!B43*B9*B10 -> 0.68 | C39: =가정값!B43*C9*C10 -> 3.1824 | D39: =가정값!B43*D9*D10 -> 7.48 | E39: =가정값!B43*E9*E10 -> 13.09
A40: 제휴사 건당 기대 LTV | B40: =가정값!B41+가정값!B42*B9+가정값!B43*B9*B10 -> 21.08 | C40: =가정값!B41+가정값!B42*C9+가정값!B43*C9*C10 -> 28.7124 | D40: =가정값!B41+가정값!B42*D9+가정값!B43*D9*D10 -> 37.33 | E40: =가정값!B41+가정값!B42*E9+가정값!B43*E9*E10 -> 46.99
A42: 💡 T1 70% 커미션이지만 쿠키 30일 → T2/T3 업셀 커미션도 수령 → 제휴사 기대 LTV = $8.40~$15+ · '눈 돌아가는' 수준 맞음
A44: ⚡ 전략 인사이트
A45: ✅ 멕시코 月소득 $1,923 대비 T1 $15 = 0.78% · T3 $34 = 1.77% — 충동구매 ~ 고려구매 경계선. 스윗스팟.
A46: ✅ 콜롬비아 月소득 $1,123 대비 T1 $15 = 1.34% — 부담 있지만 자기계발 소비 의향 강한 25~40대 타겟.
...

Sheet 유형별 대시보드
A1: 🌟 8유형 × 3티어 월 손익 대시보드 — M1 기준 · 3국 가중평균 · 제휴 중심
A2: 가정값 시트 전환율(가중평균) 기준 · T1 제휴80%/T2 30%/T3 10% · $15/$27/$34 적용
A3: 수량 기준: (3국 가중평균 진단수 × 이메일율 ÷ 8유형) × 각 전환율
A4: 유형 | B4: T1 수량 | C4: T2 수량 | D4: T3 수량 | E4: T1 매출 | F4: T2 매출 | G4: T3 매출 | H4: Gross | I4: Hotmart 차감 | J4: 제휴 차감 | K4: 민철님 수익 | L4: 수익률
A5: SPARK | B5: =ROUND(가정값!$E$32*가정값!$E$33/8*가정값!$E$34,1) -> 12.6 | C5: =ROUND(B5*가정값!$E$35,1) -> 4.8 | D5: =ROUND(C5*가정값!$E$36,1) -> 1.1 | E5: =B5*15 -> 189 | F5: =C5*27 -> 129.6 | G5: =D5*34 -> 37.4 | H5: =E5+F5+G5 -> 356 | I5: =-(E5*0.2+F5*0.099+C5*0.5+G5*0.099+D5*0.5) -> -57.283 | J5: =-(E5*(1-0.2)*가정값!$B$20*가정값!$B$26+(F5*(1-0.099)-C5*0.5)*가정값!$B$21*가정값!$B$27+(G5*(1-0.099)-D5*0.5)*가정값!$B$22*가정값!$B$28) -> -101.43779 | K5: =H5+I5+J5 -> 197.27921 | L5: =IF(H5<>0,K5/H5,0) -> 0.55415508
A6: VISION | B6: =ROUND(가정값!$E$32*가정값!$E$33/8*가정값!$E$34,1) -> 12.6 | C6: =ROUND(B6*가정값!$E$35,1) -> 4.8 | D6: =ROUND(C6*가정값!$E$36,1) -> 1.1 | E6: =B6*15 -> 189 | F6: =C6*27 -> 129.6 | G6: =D6*34 -> 37.4 | H6: =E6+F6+G6 -> 356 | I6: =-(E6*0.2+F6*0.099+C6*0.5+G6*0.099+D6*0.5) -> -57.283 | J6: =-(E6*(1-0.2)*가정값!$B$20*가정값!$B$26+(F6*(1-0.099)-C6*0.5)*가정값!$B$21*가정값!$B$27+(G6*(1-0.099)-D6*0.5)*가정값!$B$22*가정값!$B$28) -> -101.43779 | K6: =H6+I6+J6 -> 197.27921 | L6: =IF(H6<>0,K6/H6,0) -> 0.55415508
A7: PLAYER | B7: =ROUND(가정값!$E$32*가정값!$E$33/8*가정값!$E$34,1) -> 12.6 | C7: =ROUND(B7*가정값!$E$35,1) -> 4.8 | D7: =ROUND(C7*가정값!$E$36,1) -> 1.1 | E7: =B7*15 -> 189 | F7: =C7*27 -> 129.6 | G7: =D7*34 -> 37.4 | H7: =E7+F7+G7 -> 356 | I7: =-(E7*0.2+F7*0.099+C7*0.5+G7*0.099+D7*0.5) -> -57.283 | J7: =-(E7*(1-0.2)*가정값!$B$20*가정값!$B$26+(F7*(1-0.099)-C7*0.5)*가정값!$B$21*가정값!$B$27+(G7*(1-0.099)-D7*0.5)*가정값!$B$22*가정값!$B$28) -> -101.43779 | K7: =H7+I7+J7 -> 197.27921 | L7: =IF(H7<>0,K7/H7,0) -> 0.55415508
A8: STEADY | B8: =ROUND(가정값!$E$32*가정값!$E$33/8*가정값!$E$34,1) -> 12.6 | C8: =ROUND(B8*가정값!$E$35,1) -> 4.8 | D8: =ROUND(C8*가정값!$E$36,1) -> 1.1 | E8: =B8*15 -> 189 | F8: =C8*27 -> 129.6 | G8: =D8*34 -> 37.4 | H8: =E8+F8+G8 -> 356 | I8: =-(E8*0.2+F8*0.099+C8*0.5+G8*0.099+D8*0.5) -> -57.283 | J8: =-(E8*(1-0.2)*가정값!$B$20*가정값!$B$26+(F8*(1-0.099)-C8*0.5)*가정값!$B$21*가정값!$B$27+(G8*(1-0.099)-D8*0.5)*가정값!$B$22*가정값!$B$28) -> -101.43779 | K8: =H8+I8+J8 -> 197.27921 | L8: =IF(H8<>0,K8/H8,0) -> 0.55415508
A9: LEADER | B9: =ROUND(가정값!$E$32*가정값!$E$33/8*가정값!$E$34,1) -> 12.6 | C9: =ROUND(B9*가정값!$E$35,1) -> 4.8 | D9: =ROUND(C9*가정값!$E$36,1) -> 1.1 | E9: =B9*15 -> 189 | F9: =C9*27 -> 129.6 | G9: =D9*34 -> 37.4 | H9: =E9+F9+G9 -> 356 | I9: =-(E9*0.2+F9*0.099+C9*0.5+G9*0.099+D9*0.5) -> -57.283 | J9: =-(E9*(1-0.2)*가정값!$B$20*가정값!$B$26+(F9*(1-0.099)-C9*0.5)*가정값!$B$21*가정값!$B$27+(G9*(1-0.099)-D9*0.5)*가정값!$B$22*가정값!$B$28) -> -101.43779 | K9: =H9+I9+J9 -> 197.27921 | L9: =IF(H9<>0,K9/H9,0) -> 0.55415508
A10: LOGIC | B10: =ROUND(가정값!$E$32*가정값!$E$33/8*가정값!$E$34,1) -> 12.6 | C10: =ROUND(B10*가정값!$E$35,1) -> 4.8 | D10: =ROUND(C10*가정값!$E$36,1) -> 1.1 | E10: =B10*15 -> 189 | F10: =C10*27 -> 129.6 | G10: =D10*34 -> 37.4 | H10: =E10+F10+G10 -> 356 | I10: =-(E10*0.2+F10*0.099+C10*0.5+G10*0.099+D10*0.5) -> -57.283 | J10: =-(E10*(1-0.2)*가정값!$B$20*가정값!$B$26+(F10*(1-0.099)-C10*0.5)*가정값!$B$21*가정값!$B$27+(G10*(1-0.099)-D10*0.5)*가정값!$B$22*가정값!$B$28) -> -101.43779 | K10: =H10+I10+J10 -> 197.27921 | L10: =IF(H10<>0,K10/H10,0) -> 0.55415508
A11: HARMONY | B11: =ROUND(가정값!$E$32*가정값!$E$33/8*가정값!$E$34,1) -> 12.6 | C11: =ROUND(B11*가정값!$E$35,1) -> 4.8 | D11: =ROUND(C11*가정값!$E$36,1) -> 1.1 | E11: =B11*15 -> 189 | F11: =C11*27 -> 129.6 | G11: =D11*34 -> 37.4 | H11: =E11+F11+G11 -> 356 | I11: =-(E11*0.2+F11*0.099+C11*0.5+G11*0.099+D11*0.5) -> -57.283 | J11: =-(E11*(1-0.2)*가정값!$B$20*가정값!$B$26+(F11*(1-0.099)-C11*0.5)*가정값!$B$21*가정값!$B$27+(G11*(1-0.099)-D11*0.5)*가정값!$B$22*가정값!$B$28) -> -101.43779 | K11: =H11+I11+J11 -> 197.27921 | L11: =IF(H11<>0,K11/H11,0) -> 0.55415508
A12: SOUL | B12: =ROUND(가정값!$E$32*가정값!$E$33/8*가정값!$E$34,1) -> 12.6 | C12: =ROUND(B12*가정값!$E$35,1) -> 4.8 | D12: =ROUND(C12*가정값!$E$36,1) -> 1.1 | E12: =B12*15 -> 189 | F12: =C12*27 -> 129.6 | G12: =D12*34 -> 37.4 | H12: =E12+F12+G12 -> 356 | I12: =-(E12*0.2+F12*0.099+C12*0.5+G12*0.099+D12*0.5) -> -57.283 | J12: =-(E12*(1-0.2)*가정값!$B$20*가정값!$B$26+(F12*(1-0.099)-C12*0.5)*가정값!$B$21*가정값!$B$27+(G12*(1-0.099)-D12*0.5)*가정값!$B$22*가정값!$B$28) -> -101.43779 | K12: =H12+I12+J12 -> 197.27921 | L12: =IF(H12<>0,K12/H12,0) -> 0.55415508
A14: 8유형 합계 | B14: =SUM(B5:B13) -> 100.8 | C14: =SUM(C5:C13) -> 38.4 | D14: =SUM(D5:D13) -> 8.8 | E14: =SUM(E5:E13) -> 1512 | F14: =SUM(F5:F13) -> 1036.8 | G14: =SUM(G5:G13) -> 299.2 | H14: =SUM(H5:H13) -> 2848 | I14: =SUM(I5:I13) -> -458.264 | ... K14: =SUM(K5:K13) -> 1578.2337 | L14: =IF(H14<>0,K14/H14,0) -> 0.55415508
A16: 💰 민철님 실수령 요약 (건당 · M1 가중평균)
A17: 구분 | B17: 건당 순액 | C17: 제휴사/건 | D17: 민철님 직접/건 | E17: 비고
A18: T1 · $15 | B18: =가정값!B41 -> 15 | C18: =가정값!B42 -> 27 | D18: =가정값!B45 -> 0 | E18: 제휴사 70% · 民 30% · 충동구매 미끼
A19: T2 · $27 | B19: =가정값!B42 -> 27 | C19: =가정값!B43 -> 34 | D19: =가정값!B46 -> T1 상당 | E19: 제휴사 45% · 民 55% · 깜짝선물 D+3
A20: T3 · $34 | B20: =가정값!B43 -> 34 | C20: =가정값!B44 -> 0 | D20: =가정값!B47 -> - | E20: 제휴사 40% · 民 60% · 완전판 $5 더
A22: 🔑 핵심: T1은 제휴사를 위한 바이럴 엔진($8.40/건). T2/T3 이메일 직접 업셀로 민철님 수익 극대화. 유형 추가할수록 선형 성장.
