Workbook

Sheet ① 자동화 가정
B1: ⚙️ Shadowgram 자동화 수익 모델 — 핵심 가정 (파란 셀만 수정)
B2: 민철 씨 개입 = 0 | Hotmart 자동정산 | 이메일 자동화 | 파트너 자율판매 | 5년 복리 성장
B4: 📦 A. 번들 가격 & 오너 수취 단가
B5: 번들 | C5: 판매가($) | D5: Hotmart수수료 | E5: 커미션율 | F5: 오너단가($) | G5: 오너단가(₩)
B6: T1+AppA (트립와이어) | C6: 12.8 | D6: 0.099 | E6: 0.7 | F6: =C6*(1-D6-E6) -> 2.5728 | G6: =F6*C21 -> 0
B7: T2+AppB (OTO) | C7: 19.9 | D7: 0.099 | E7: 0.5 | F7: =C7*(1-D7-E7) -> 7.9799 | G7: =F7*C21 -> 0
B8: T3+AppC (이메일) | C8: 28.9 | D8: 0.099 | E8: 0.4 | F8: =C8*(1-D8-E8) -> 14.4789 | G8: =F8*C21 -> 0
B10: 🤖 B. 자동화 전환율 & 퍼널 파라미터
B11: 항목 | C11: 값 | D11: 설명
B12: T2 OTO 전환율 (자동 팝업) | C12: 0.24 | D12: T1 구매 직후 자동 노출 → 평균 24% 전환
B13: T3 이메일 자동화 전환율 | C13: 0.1 | D13: 구매 후 7일 이메일 시퀀스 자동발송
B14: 파트너 자연 유입 바이럴계수 K | C14: 0.15 | D14: 기존 파트너 1명이 월 0.15명 신규 유입 (추천/입소문)
B15: 연간 파트너 이탈율 | C15: 0.2 | D15: 비활성화 20%/년 → 자동 제거 기준
B16: 파트너 활성화율 (실제 판매 발생) | C16: 0.65 | D16: 등록 파트너 중 65%만 실제 판매
B17: 상위 파트너 비율 (파레토) | C17: 0.2 | D17: 상위 20%가 80% 수익 창출
B18: 환율 (원/달러) | C18: 1400 | D18: 시나리오 변경 가능
B19: 연간 가격 인상율 | C19: 0.05 | D19: 연 5% 가격 인상 (인플레이션 반영)
B20: 연간 전환율 개선율 | C20: 0.03 | D20: 퍼널 최적화로 연 3% OTO 전환율 향상
B22: 🌍 C. 국가별 파트너 초기 설정 (D+1개월 시작값)
B23: 국가 | C23: 언어 | D23: Hotmart인지도 | E23: 초기파트너(명) | F23: 월추가파트너(명) | G23: 1년목표(명) | H23: 주석
B24: 🇧🇷 브라질 | C24: 포르투갈어 | D24: ★★★★★ | E24: 5 | F24: 17 | G24: =E24+F24*12 -> 209 | H24: 홈마켓. 53K+ 파트너생태계
B25: 🇲🇽 멕시코 | C25: 스페인어 | D25: ★★★★☆ | E25: 3 | F25: 13 | G25: =E25+F25*12 -> 159 | H25: 오피스보유. LATAM GMV 50%성장
B26: 🇨🇴 콜롬비아 | C26: 스페인어 | D26: ★★★★☆ | E26: 2 | F26: 7 | G26: =E26+F26*12 -> 86 | H26: 오피스보유. YoY 24.2%
B27: 🇺🇸 미국히스패닉 | C27: 스페인어 | D27: ★★★☆☆ | E27: 2 | F27: 8 | G27: =E27+F27*12 -> 98 | H27: 소득$2100. 달러구매력 최고
B28: 🇦🇷 아르헨티나 | C28: 스페인어 | D28: ★★★☆☆ | E28: 1 | F28: 4 | G28: =E28+F28*12 -> 49 | H28: 인플레이션→달러수익 선호
B29: 🇨🇱 칠레 | C29: 스페인어 | D29: ★★★☆☆ | E29: 1 | F29: 3 | G29: =E29+F29*12 -> 37 | H29: 인터넷94%. 소득 LATAM1위
B30: 🇵🇹 포르투갈 | C30: 포르투갈어 | D30: ★★☆☆☆ | E30: 1 | F30: 3 | G30: =E30+F30*12 -> 37 | H30: 유럽 포르투갈어. 브라질 콘텐츠 소비
B31: 합계 | E31: =SUM(E24:E30) -> 15 | F31: =SUM(F24:F30) -> 55 | G31: =SUM(G24:G30) -> 675
B33: 📈 D. 연도별 자동 성장 배수 (파트너 바이럴 + 이탈 순효과)
B34: 연도 | C34: 파트너성장배수 | D34: 설명
B35: 1년차 | C35: =1+(C12-C13) -> 1.14 | D35: 바이럴K=15% 유입, 이탈20% → 순증가
B36: 2년차 | C36: =1+(C12*1.2-C13*0.9) -> 1.198 | D36: 입소문 확산. 이탈율 개선
B37: 3년차 | C37: =1+(C12*1.5-C13*0.8) -> 1.28 | D37: 브랜드 인지. 파트너 생태계 안정화
B38: 4년차 | C38: =1+(C12*1.8-C13*0.75) -> 1.357 | D38: 복리 효과. 상위 파트너 고착화
B39: 5년차 | C39: =1+(C12*2-C13*0.7) -> 1.41 | D39: 완전 자동화. 민철 씨 개입 ≈ 0

Sheet ② 1년차 월별 시뮬
B1: 📅 1년차 월별 수익 시뮬레이션 — D+1개월 ~ D+12개월
B2: 민철 씨 개입 0 | 자동화 퍼널 | 파레토 파트너 | 국가별 합산
B4: 🌍 국가별 월별 파트너 수 & 수익
B5: 국가 | C5: 1월 | D5: 2월 | E5: 3월 | F5: 4월 | G5: 5월 | H5: 6월 | I5: 7월 | J5: 8월 | K5: 9월 | L5: 10월 | M5: 11월 | N5: 12월 | O5: 연간합계
B6: 🇧🇷 브라질 파트너(명) | C6: =ROUND('① 자동화 가정'!E24+'① 자동화 가정'!F24,0) -> 22 | D6: =ROUND(C6*(1+'① 자동화 가정'!C14/12-'① 자동화 가정'!C15/12)+'① 자동화 가정'!F24,0) -> 39 | E6: =ROUND(D6*(1+'① 자동화 가정'!C14/12-'① 자동화 가정'!C15/12)+'① 자동화 가정'!F24,0) -> 56 | F6: =ROUND(E6*(1+'① 자동화 가정'!C14/12-'① 자동화 가정'!C15/12)+'① 자동화 가정'!F24,0) -> 73 | G6: =ROUND(F6*(1+'① 자동화 가정'!C14/12-'① 자동화 가정'!C15/12)+'① 자동화 가정'!F24,0) -> 90 | H6: =ROUND(G6*(1+'① 자동화 가정'!C14/12-'① 자동화 가정'!C15/12)+'① 자동화 가정'!F24,0) -> 107 | I6: =ROUND(H6*(1+'① 자동화 가정'!C14/12-'① 자동화 가정'!C15/12)+'① 자동화 가정'!F24,0) -> 124 | J6: =ROUND(I6*(1+'① 자동화 가정'!C14/12-'① 자동화 가정'!C15/12)+'① 자동화 가정'!F24,0) -> 140 | K6: =ROUND(J6*(1+'① 자동화 가정'!C14/12-'① 자동화 가정'!C15/12)+'① 자동화 가정'!F24,0) -> 156 | L6: =ROUND(K6*(1+'① 자동화 가정'!C14/12-'① 자동화 가정'!C15/12)+'① 자동화 가정'!F24,0) -> 172 | M6: =ROUND(L6*(1+'① 자동화 가정'!C14/12-'① 자동화 가정'!C15/12)+'① 자동화 가정'!F24,0) -> 188 | N6: =ROUND(M6*(1+'① 자동화 가정'!C14/12-'① 자동화 가정'!C15/12)+'① 자동화 가정'!F24,0) -> 204 | O6: =N6 -> 204
B7: 🇧🇷 브라질 수익($) | C7: =((C6*'① 자동화 가정'!C17*'① 자동화 가정'!C16*80+C6*(1-'① 자동화 가정'!C17)*'① 자동화 가정'!C16*0.375*20+C6*(1-'① 자동화 가정'!C17)*'① 자동화 가정'!C16*0.625*3)*'① 자동화 가정'!F6+(C6*'① 자동화 가정'!C17*'① 자동화 가정'!C16*80+C6*(1-'① 자동화 가정'!C17)*'① 자동화 가정'!C16*0.375*20+C6*(1-'① 자동화 가정'!C17)*'① 자동화 가정'!C16*0.625*3)*'① 자동화 가정'!C12*'① 자동화 가정'!F7+(C6*'① 자동화 가정'!C17*'① 자동화 가정'!C16*80+C6*(1-'① 자동화 가정'!C17)*'① 자동화 가정'!C16*0.375*20+C6*(1-'① 자동화 가정'!C17)*'① 자동화 가정'!C16*0.625*3)*'① 자동화 가정'!C13*'① 자동화 가정'!F8) -> 1994.7478 | D7: =((D6*'① 자동화 가정'!C17*'① 자동화 가정'!C16*80+D6*(1-'① 자동화 가정'!C17)*'① 자동화 가정'!C16*0.375*20+D6*(1-'① 자동화 가정'!C17)*'① 자동화 가정'!C16*0.625*3)*'① 자동화 가정'!F6+(D6*'① 자동화 가정'!C17*'① 자동화 가정'!C16*80+D6*(1-'① 자동화 가정'!C17)*'① 자동화 가정'!C16*0.375*20+D6*(1-'① 자동화 가정'!C17)*'① 자동화 가정'!C16*0.625*3)*'① 자동화 가정'!C12*'① 자동화 가정'!F7+(D6*'① 자동화 가정'!C17*'① 자동화 가정'!C16*80+D6*(1-'① 자동화 가정'!C17)*'① 자동화 가정'!C16*0.375*20+D6*(1-'① 자동화 가정'!C17)*'① 자동화 가정'!C16*0.625*3)*'① 자동화 가정'!C13*'① 자동화 가정'!F8) -> 3536.1438 | E7: =((E6*'① 자동화 가정'!C17*'① 자동화 가정'!C16*80+E6*(1-'① 자동화 가정'!C17)*'① 자동화 가정'!C16*0.375*20+E6*(1-'① 자동화 가정'!C17)*'① 자동화 가정'!C16*0.625*3)*'① 자동화 가정'!F6+(E6*'① 자동화 가정'!C17*'① 자동화 가정'!C16*80+E6*(1-'① 자동화 가정'!C17)*'① 자동화 가정'!C16*0.375*20+E6*(1-'① 자동화 가정'!C17)*'① 자동화 가정'!C16*0.625*3)*'① 자동화 가정'!C12*'① 자동화 가정'!F7+(E6*'① 자동화 가정'!C17*'① 자동화 가정'!C16*80+E6*(1-'① 자동화 가정'!C17)*'① 자동화 가정'!C16*0.375*20+E6*(1-'① 자동화 가정'!C17)*'① 자동화 가정'!C16*0.625*3)*'① 자동화 가정'!C13*'① 자동화 가정'!F8) -> 5077.5398 | F7: =((F6*'① 자동화 가정'!C17*'① 자동화 가정'!C16*80+F6*(1-'① 자동화 가정'!C17)*'① 자동화 가정'!C16*0.375*20+F6*(1-'① 자동화 가정'!C17)*'① 자동화 가정'!C16*0.625*3)*'① 자동화 가정'!F6+(F6*'① 자동화 가정'!C17*'① 자동화 가정'!C16*80+F6*(1-'① 자동화 가정'!C17)*'① 자동화 가정'!C16*0.375*20+F6*(1-'① 자동화 가정'!C17)*'① 자동화 가정'!C16*0.625*3)*'① 자동화 가정'!C12*'① 자동화 가정'!F7+(F6*'① 자동화 가정'!C17*'① 자동화 가정'!C16*80+F6*(1-'① 자동화 가정'!C17)*'① 자동화 가정'!C16*0.375*20+F6*(1-'① 자동화 가정'!C17)*'① 자동화 가정'!C16*0.625*3)*'① 자동화 가정'!C13*'① 자동화 가정'!F8) -> 6618.9358 | G7: =((G6*'① 자동화 가정'!C17*'① 자동화 가정'!C16*80+G6*(1-'① 자동화 가정'!C17)*'① 자동화 가정'!C16*0.375*20+G6*(1-'① 자동화 가정'!C17)*'① 자동화 가정'!C16*0.625*3)*'① 자동화 가정'!F6+(G6*'① 자동화 가정'!C17*'① 자동화 가정'!C16*80+G6*(1-'① 자동화 가정'!C17)*'① 자동화 가정'!C16*0.375*20+G6*(1-'① 자동화 가정'!C17)*'① 자동화 가정'!C16*0.625*3)*'① 자동화 가정'!C12*'① 자동화 가정'!F7+(G6*'① 자동화 가정'!C17*'① 자동화 가정'!C16*80+G6*(1-'① 자동화 가정'!C17)*'① 자동화 가정'!C16*0.375*20+G6*(1-'① 자동화 가정'!C17)*'① 자동화 가정'!C16*0.625*3)*'① 자동화 가정'!C13*'① 자동화 가정'!F8) -> 8160.3318 | H7: =((H6*'① 자동화 가정'!C17*'① 자동화 가정'!C16*80+H6*(1-'① 자동화 가정'!C17)*'① 자동화 가정'!C16*0.375*20+H6*(1-'① 자동화 가정'!C17)*'① 자동화 가정'!C16*0.625*3)*'① 자동화 가정'!F6+(H6*'① 자동화 가정'!C17*'① 자동화 가정'!C16*80+H6*(1-'① 자동화 가정'!C17)*'① 자동화 가정'!C16*0.375*20+H6*(1-'① 자동화 가정'!C17)*'① 자동화 가정'!C16*0.625*3)*'① 자동화 가정'!C12*'① 자동화 가정'!F7+(H6*'① 자동화 가정'!C17*'① 자동화 가정'!C16*80+H6*(1-'① 자동화 가정'!C17)*'① 자동화 가정'!C16*0.375*20+H6*(1-'① 자동화 가정'!C17)*'① 자동화 가정'!C16*0.625*3)*'① 자동화 가정'!C13*'① 자동화 가정'!F8) -> 9701.7278 | I7: =((I6*'① 자동화 가정'!C17*'① 자동화 가정'!C16*80+I6*(1-'① 자동화 가정'!C17)*'① 자동화 가정'!C16*0.375*20+I6*(1-'① 자동화 가정'!C17)*'① 자동화 가정'!C16*0.625*3)*'① 자동화 가정'!F6+(I6*'① 자동화 가정'!C17*'① 자동화 가정'!C16*80+I6*(1-'① 자동화 가정'!C17)*'① 자동화 가정'!C16*0.375*20+I6*(1-'① 자동화 가정'!C17)*'① 자동화 가정'!C16*0.625*3)*'① 자동화 가정'!C12*'① 자동화 가정'!F7+(I6*'① 자동화 가정'!C17*'① 자동화 가정'!C16*80+I6*(1-'① 자동화 가정'!C17)*'① 자동화 가정'!C16*0.375*20+I6*(1-'① 자동화 가정'!C17)*'① 자동화 가정'!C16*0.625*3)*'① 자동화 가정'!C13*'① 자동화 가정'!F8) -> 11243.124 | J7: =((J6*'① 자동화 가정'!C17*'① 자동화 가정'!C16*80+J6*(1-'① 자동화 가정'!C17)*'① 자동화 가정'!C16*0.375*20+J6*(1-'① 자동화 가정'!C17)*'① 자동화 가정'!C16*0.625*3)*'① 자동화 가정'!F6+(J6*'① 자동화 가정'!C17*'① 자동화 가정'!C16*80+J6*(1-'① 자동화 가정'!C17)*'① 자동화 가정'!C16*0.375*20+J6*(1-'① 자동화 가정'!C17)*'① 자동화 가정'!C16*0.625*3)*'① 자동화 가정'!C12*'① 자동화 가정'!F7+(J6*'① 자동화 가정'!C17*'① 자동화 가정'!C16*80+J6*(1-'① 자동화 가정'!C17)*'① 자동화 가정'!C16*0.375*20+J6*(1-'① 자동화 가정'!C17)*'① 자동화 가정'!C16*0.625*3)*'① 자동화 가정'!C13*'① 자동화 가정'!F8) -> 12693.849 | K7: =((K6*'① 자동화 가정'!C17*'① 자동화 가정'!C16*80+K6*(1-'① 자동화 가정'!C17)*'① 자동화 가정'!C16*0.375*20+K6*(1-'① 자동화 가정'!C17)*'① 자동화 가정'!C16*0.625*3)*'① 자동화 가정'!F6+(K6*'① 자동화 가정'!C17*'① 자동화 가정'!C16*80+K6*(1-'① 자동화 가정'!C17)*'① 자동화 가정'!C16*0.375*20+K6*(1-'① 자동화 가정'!C17)*'① 자동화 가정'!C16*0.625*3)*'① 자동화 가정'!C12*'① 자동화 가정'!F7+(K6*'① 자동화 가정'!C17*'① 자동화 가정'!C16*80+K6*(1-'① 자동화 가정'!C17)*'① 자동화 가정'!C16*0.375*20+K6*(1-'① 자동화 가정'!C17)*'① 자동화 가정'!C16*0.625*3)*'① 자동화 가정'!C13*'① 자동화 가정'!F8) -> 14144.575 | L7: =((L6*'① 자동화 가정'!C17*'① 자동화 가정'!C16*80+L6*(1-'① 자동화 가정'!C17)*'① 자동화 가정'!C16*0.375*20+L6*(1-'① 자동화 가정'!C17)*'① 자동화 가정'!C16*0.625*3)*'① 자동화 가정'!F6+(L6*'① 자동화 가정'!C17*'① 자동화 가정'!C16*80+L6*(1-'① 자동화 가정'!C17)*'① 자동화 가정'!C16*0.375*20+L6*(1-'① 자동화 가정'!C17)*'① 자동화 가정'!C16*0.625*3)*'① 자동화 가정'!C12*'① 자동화 가정'!F7+(L6*'① 자동화 가정'!C17*'① 자동화 가정'!C16*80+L6*(1-'① 자동화 가정'!C17)*'① 자동화 가정'!C16*0.375*20+L6*(1-'① 자동화 가정'!C17)*'① 자동화 가정'!C16*0.625*3)*'① 자동화 가정'!C13*'① 자동화 가정'!F8) -> 15595.301 | M7: =((M6*'① 자동화 가정'!C17*'① 자동화 가정'!C16*80+M6*(1-'① 자동화 가정'!C17)*'① 자동화 가정'!C16*0.375*20+M6*(1-'① 자동화 가정'!C17)*'① 자동화 가정'!C16*0.625*3)*'① 자동화 가정'!F6+(M6*'① 자동화 가정'!C17*'① 자동화 가정'!C16*80+M6*(1-'① 자동화 가정'!C17)*'① 자동화 가정'!C16*0.375*20+M6*(1-'① 자동화 가정'!C17)*'① 자동화 가정'!C16*0.625*3)*'① 자동화 가정'!C12*'① 자동화 가정'!F7+(M6*'① 자동화 가정'!C17*'① 자동화 가정'!C16*80+M6*(1-'① 자동화 가정'!C17)*'① 자동화 가정'!C16*0.375*20+M6*(1-'① 자동화 가정'!C17)*'① 자동화 가정'!C16*0.625*3)*'① 자동화 가정'!C13*'① 자동화 가정'!F8) -> 17046.026 | N7: =((N6*'① 자동화 가정'!C17*'① 자동화 가정'!C16*80+N6*(1-'① 자동화 가정'!C17)*'① 자동화 가정'!C16*0.375*20+N6*(1-'① 자동화 가정'!C17)*'① 자동화 가정'!C16*0.625*3)*'① 자동화 가정'!F6+(N6*'① 자동화 가정'!C17*'① 자동화 가정'!C16*80+N6*(1-'① 자동화 가정'!C17)*'① 자동화 가정'!C16*0.375*20+N6*(1-'① 자동화 가정'!C17)*'① 자동화 가정'!C16*0.625*3)*'① 자동화 가정'!C12*'① 자동화 가정'!F7+(N6*'① 자동화 가정'!C17*'① 자동화 가정'!C16*80+N6*(1-'① 자동화 가정'!C17)*'① 자동화 가정'!C16*0.375*20+N6*(1-'① 자동화 가정'!C17)*'① 자동화 가정'!C16*0.625*3)*'① 자동화 가정'!C13*'① 자동화 가정'!F8) -> 18496.752 | O7: =SUM(C7:N7) -> 124309.05
B8: 🇧🇷 브라질 수익(₩) | C8: =C7*'① 자동화 가정'!C18 -> 2792646.9 | D8: =D7*'① 자동화 가정'!C18 -> 4950601.3 | E8: =E7*'① 자동화 가정'!C18 -> 7108555.7 | F8: =F7*'① 자동화 가정'!C18 -> 9266510.1 | G8: =G7*'① 자동화 가정'!C18 -> 11424464 | H8: =H7*'① 자동화 가정'!C18 -> 13582419 | I8: =I7*'① 자동화 가정'!C18 -> 15740373 | J8: =J7*'① 자동화 가정'!C18 -> 17771389 | K8: =K7*'① 자동화 가정'!C18 -> 19802405 | L8: =L7*'① 자동화 가정'!C18 -> 21833421 | M8: =M7*'① 자동화 가정'!C18 -> 23864437 | N8: =N7*'① 자동화 가정'!C18 -> 25895453 | O8: =N7*'① 자동화 가정'!C18 -> 25895453
B10: 🇲🇽 멕시코 파트너(명) | C10: =ROUND('① 자동화 가정'!E25+'① 자동화 가정'!F25,0) -> 16 | D10: =ROUND(C10*(1+'① 자동화 가정'!C14/12-'① 자동화 가정'!C15/12)+'① 자동화 가정'!F25,0) -> 29 | E10: =ROUND(D10*(1+'① 자동화 가정'!C14/12-'① 자동화 가정'!C15/12)+'① 자동화 가정'!F25,0) -> 42 | F10: =ROUND(E10*(1+'① 자동화 가정'!C14/12-'① 자동화 가정'!C15/12)+'① 자동화 가정'!F25,0) -> 55 | G10: =ROUND(F10*(1+'① 자동화 가정'!C14/12-'① 자동화 가정'!C15/12)+'① 자동화 가정'!F25,0) -> 68 | H10: =ROUND(G10*(1+'① 자동화 가정'!C14/12-'① 자동화 가정'!C15/12)+'① 자동화 가정'!F25,0) -> 81 | I10: =ROUND(H10*(1+'① 자동화 가정'!C14/12-'① 자동화 가정'!C15/12)+'① 자동화 가정'!F25,0) -> 94 | J10: =ROUND(I10*(1+'① 자동화 가정'!C14/12-'① 자동화 가정'!C15/12)+'① 자동화 가정'!F25,0) -> 107 | K10: =ROUND(J10*(1+'① 자동화 가정'!C14/12-'① 자동화 가정'!C15/12)+'① 자동화 가정'!F25,0) -> 120 | L10: =ROUND(K10*(1+'① 자동화 가정'!C14/12-'① 자동화 가정'!C15/12)+'① 자동화 가정'!F25,0) -> 133 | M10: =ROUND(L10*(1+'① 자동화 가정'!C14/12-'① 자동화 가정'!C15/12)+'① 자동화 가정'!F25,0) -> 145 | N10: =ROUND(M10*(1+'① 자동화 가정'!C14/12-'① 자동화 가정'!C15/12)+'① 자동화 가정'!F25,0) -> 157 | O10: =N10 -> 157
B11: 🇲🇽 멕시코 수익($) | C11: =((C10*'① 자동화 가정'!C17*'① 자동화 가정'!C16*80+C10*(1-'① 자동화 가정'!C17)*'① 자동화 가정'!C16*0.375*20+C10*(1-'① 자동화 가정'!C17)*'① 자동화 가정'!C16*0.625*3)*'① 자동화 가정'!F6+(C10*'① 자동화 가정'!C17*'① 자동화 가정'!C16*80+C10*(1-'① 자동화 가정'!C17)*'① 자동화 가정'!C16*0.375*20+C10*(1-'① 자동화 가정'!C17)*'① 자동화 가정'!C16*0.625*3)*'① 자동화 가정'!C12*'① 자동화 가정'!F7+(C10*'① 자동화 가정'!C17*'① 자동화 가정'!C16*80+C10*(1-'① 자동화 가정'!C17)*'① 자동화 가정'!C16*0.375*20+C10*(1-'① 자동화 가정'!C17)*'① 자동화 가정'!C16*0.625*3)*'① 자동화 가정'!C13*'① 자동화 가정'!F8) -> 1450.7257 | D11: =((D10*'① 자동화 가정'!C17*'① 자동화 가정'!C16*80+D10*(1-'① 자동화 가정'!C17)*'① 자동화 가정'!C16*0.375*20+D10*(1-'① 자동화 가정'!C17)*'① 자동화 가정'!C16*0.625*3)*'① 자동화 가정'!F6+(D10*'① 자동화 가정'!C17*'① 자동화 가정'!C16*80+D10*(1-'① 자동화 가정'!C17)*'① 자동화 가정'!C16*0.375*20+D10*(1-'① 자동화 가정'!C17)*'① 자동화 가정'!C16*0.625*3)*'① 자동화 가정'!C12*'① 자동화 가정'!F7+(D10*'① 자동화 가정'!C17*'① 자동화 가정'!C16*80+D10*(1-'① 자동화 가정'!C17)*'① 자동화 가정'!C16*0.375*20+D10*(1-'① 자동화 가정'!C17)*'① 자동화 가정'!C16*0.625*3)*'① 자동화 가정'!C13*'① 자동화 가정'!F8) -> 2629.4402 | E11: =((E10*'① 자동화 가정'!C17*'① 자동화 가정'!C16*80+E10*(1-'① 자동화 가정'!C17)*'① 자동화 가정'!C16*0.375*20+E10*(1-'① 자동화 가정'!C17)*'① 자동화 가정'!C16*0.625*3)*'① 자동화 가정'!F6+(E10*'① 자동화 가정'!C17*'① 자동화 가정'!C16*80+E10*(1-'① 자동화 가정'!C17)*'① 자동화 가정'!C16*0.375*20+E10*(1-'① 자동화 가정'!C17)*'① 자동화 가정'!C16*0.625*3)*'① 자동화 가정'!C12*'① 자동화 가정'!F7+(E10*'① 자동화 가정'!C17*'① 자동화 가정'!C16*80+E10*(1-'① 자동화 가정'!C17)*'① 자동화 가정'!C16*0.375*20+E10*(1-'① 자동화 가정'!C17)*'① 자동화 가정'!C16*0.625*3)*'① 자동화 가정'!C13*'① 자동화 가정'!F8) -> 3808.1548 | F11: =((F10*'① 자동화 가정'!C17*'① 자동화 가정'!C16*80+F10*(1-'① 자동화 가정'!C17)*'① 자동화 가정'!C16*0.375*20+F10*(1-'① 자동화 가정'!C17)*'① 자동화 가정'!C16*0.625*3)*'① 자동화 가정'!F6+(F10*'① 자동화 가정'!C17*'① 자동화 가정'!C16*80+F10*(1-'① 자동화 가정'!C17)*'① 자동화 가정'!C16*0.375*20+F10*(1-'① 자동화 가정'!C17)*'① 자동화 가정'!C16*0.625*3)*'① 자동화 가정'!C12*'① 자동화 가정'!F7+(F10*'① 자동화 가정'!C17*'① 자동화 가정'!C16*80+F10*(1-'① 자동화 가정'!C17)*'① 자동화 가정'!C16*0.375*20+F10*(1-'① 자동화 가정'!C17)*'① 자동화 가정'!C16*0.625*3)*'① 자동화 가정'!C13*'① 자동화 가정'!F8) -> 4986.8694 | G11: =((G10*'① 자동화 가정'!C17*'① 자동화 가정'!C16*80+G10*(1-'① 자동화 가정'!C17)*'① 자동화 가정'!C16*0.375*20+G10*(1-'① 자동화 가정'!C17)*'① 자동화 가정'!C16*0.625*3)*'① 자동화 가정'!F6+(G10*'① 자동화 가정'!C17*'① 자동화 가정'!C16*80+G10*(1-'① 자동화 가정'!C17)*'① 자동화 가정'!C16*0.375*20+G10*(1-'① 자동화 가정'!C17)*'① 자동화 가정'!C16*0.625*3)*'① 자동화 가정'!C12*'① 자동화 가정'!F7+(G10*'① 자동화 가정'!C17*'① 자동화 가정'!C16*80+G10*(1-'① 자동화 가정'!C17)*'① 자동화 가정'!C16*0.375*20+G10*(1-'① 자동화 가정'!C17)*'① 자동화 가정'!C16*0.625*3)*'① 자동화 가정'!C13*'① 자동화 가정'!F8) -> 6165.584 | H11: =((H10*'① 자동화 가정'!C17*'① 자동화 가정'!C16*80+H10*(1-'① 자동화 가정'!C17)*'① 자동화 가정'!C16*0.375*20+H10*(1-'① 자동화 가정'!C17)*'① 자동화 가정'!C16*0.625*3)*'① 자동화 가정'!F6+(H10*'① 자동화 가정'!C17*'① 자동화 가정'!C16*80+H10*(1-'① 자동화 가정'!C17)*'① 자동화 가정'!C16*0.375*20+H10*(1-'① 자동화 가정'!C17)*'① 자동화 가정'!C16*0.625*3)*'① 자동화 가정'!C12*'① 자동화 가정'!F7+(H10*'① 자동화 가정'!C17*'① 자동화 가정'!C16*80+H10*(1-'① 자동화 가정'!C17)*'① 자동화 가정'!C16*0.375*20+H10*(1-'① 자동화 가정'!C17)*'① 자동화 가정'!C16*0.625*3)*'① 자동화 가정'!C13*'① 자동화 가정'!F8) -> 7344.2986 | I11: =((I10*'① 자동화 가정'!C17*'① 자동화 가정'!C16*80+I10*(1-'① 자동화 가정'!C17)*'① 자동화 가정'!C16*0.375*20+I10*(1-'① 자동화 가정'!C17)*'① 자동화 가정'!C16*0.625*3)*'① 자동화 가정'!F6+(I10*'① 자동화 가정'!C17*'① 자동화 가정'!C16*80+I10*(1-'① 자동화 가정'!C17)*'① 자동화 가정'!C16*0.375*20+I10*(1-'① 자동화 가정'!C17)*'① 자동화 가정'!C16*0.625*3)*'① 자동화 가정'!C12*'① 자동화 가정'!F7+(I10*'① 자동화 가정'!C17*'① 자동화 가정'!C16*80+I10*(1-'① 자동화 가정'!C17)*'① 자동화 가정'!C16*0.375*20+I10*(1-'① 자동화 가정'!C17)*'① 자동화 가정'!C16*0.625*3)*'① 자동화 가정'!C13*'① 자동화 가정'!F8) -> 8523.0132 | J11: =((J10*'① 자동화 가정'!C17*'① 자동화 가정'!C16*80+J10*(1-'① 자동화 가정'!C17)*'① 자동화 가정'!C16*0.375*20+J10*(1-'① 자동화 가정'!C17)*'① 자동화 가정'!C16*0.625*3)*'① 자동화 가정'!F6+(J10*'① 자동화 가정'!C17*'① 자동화 가정'!C16*80+J10*(1-'① 자동화 가정'!C17)*'① 자동화 가정'!C16*0.375*20+J10*(1-'① 자동화 가정'!C17)*'① 자동화 가정'!C16*0.625*3)*'① 자동화 가정'!C12*'① 자동화 가정'!F7+(J10*'① 자동화 가정'!C17*'① 자동화 가정'!C16*80+J10*(1-'① 자동화 가정'!C17)*'① 자동화 가정'!C16*0.375*20+J10*(1-'① 자동화 가정'!C17)*'① 자동화 가정'!C16*0.625*3)*'① 자동화 가정'!C13*'① 자동화 가정'!F8) -> 9701.7278 | K11: =((K10*'① 자동화 가정'!C17*'① 자동화 가정'!C16*80+K10*(1-'① 자동화 가정'!C17)*'① 자동화 가정'!C16*0.375*20+K10*(1-'① 자동화 가정'!C17)*'① 자동화 가정'!C16*0.625*3)*'① 자동화 가정'!F6+(K10*'① 자동화 가정'!C17*'① 자동화 가정'!C16*80+K10*(1-'① 자동화 가정'!C17)*'① 자동화 가정'!C16*0.375*20+K10*(1-'① 자동화 가정'!C17)*'① 자동화 가정'!C16*0.625*3)*'① 자동화 가정'!C12*'① 자동화 가정'!F7+(K10*'① 자동화 가정'!C17*'① 자동화 가정'!C16*80+K10*(1-'① 자동화 가정'!C17)*'① 자동화 가정'!C16*0.375*20+K10*(1-'① 자동화 가정'!C17)*'① 자동화 가정'!C16*0.625*3)*'① 자동화 가정'!C13*'① 자동화 가정'!F8) -> 10880.442 | L11: =((L10*'① 자동화 가정'!C17*'① 자동화 가정'!C16*80+L10*(1-'① 자동화 가정'!C17)*'① 자동화 가정'!C16*0.375*20+L10*(1-'① 자동화 가정'!C17)*'① 자동화 가정'!C16*0.625*3)*'① 자동화 가정'!F6+(L10*'① 자동화 가정'!C17*'① 자동화 가정'!C16*80+L10*(1-'① 자동화 가정'!C17)*'① 자동화 가정'!C16*0.375*20+L10*(1-'① 자동화 가정'!C17)*'① 자동화 가정'!C16*0.625*3)*'① 자동화 가정'!C12*'① 자동화 가정'!F7+(L10*'① 자동화 가정'!C17*'① 자동화 가정'!C16*80+L10*(1-'① 자동화 가정'!C17)*'① 자동화 가정'!C16*0.375*20+L10*(1-'① 자동화 가정'!C17)*'① 자동화 가정'!C16*0.625*3)*'① 자동화 가정'!C13*'① 자동화 가정'!F8) -> 12059.157 | M11: =((M10*'① 자동화 가정'!C17*'① 자동화 가정'!C16*80+M10*(1-'① 자동화 가정'!C17)*'① 자동화 가정'!C16*0.375*20+M10*(1-'① 자동화 가정'!C17)*'① 자동화 가정'!C16*0.625*3)*'① 자동화 가정'!F6+(M10*'① 자동화 가정'!C17*'① 자동화 가정'!C16*80+M10*(1-'① 자동화 가정'!C17)*'① 자동화 가정'!C16*0.375*20+M10*(1-'① 자동화 가정'!C17)*'① 자동화 가정'!C16*0.625*3)*'① 자동화 가정'!C12*'① 자동화 가정'!F7+(M10*'① 자동화 가정'!C17*'① 자동화 가정'!C16*80+M10*(1-'① 자동화 가정'!C17)*'① 자동화 가정'!C16*0.375*20+M10*(1-'① 자동화 가정'!C17)*'① 자동화 가정'!C16*0.625*3)*'① 자동화 가정'!C13*'① 자동화 가정'!F8) -> 13147.201 | N11: =((N10*'① 자동화 가정'!C17*'① 자동화 가정'!C16*80+N10*(1-'① 자동화 가정'!C17)*'① 자동화 가정'!C16*0.375*20+N10*(1-'① 자동화 가정'!C17)*'① 자동화 가정'!C16*0.625*3)*'① 자동화 가정'!F6+(N10*'① 자동화 가정'!C17*'① 자동화 가정'!C16*80+N10*(1-'① 자동화 가정'!C17)*'① 자동화 가정'!C16*0.375*20+N10*(1-'① 자동화 가정'!C17)*'① 자동화 가정'!C16*0.625*3)*'① 자동화 가정'!C12*'① 자동화 가정'!F7+(N10*'① 자동화 가정'!C17*'① 자동화 가정'!C16*80+N10*(1-'① 자동화 가정'!C17)*'① 자동화 가정'!C16*0.375*20+N10*(1-'① 자동화 가정'!C17)*'① 자동화 가정'!C16*0.625*3)*'① 자동화 가정'!C13*'① 자동화 가정'!F8) -> 14235.245 | O11: =SUM(C11:N11) -> 94931.86
B12: 🇲🇽 멕시코 수익(₩) | C12: =C11*'① 자동화 가정'!C18 -> 2031015.9 | D12: =D11*'① 자동화 가정'!C18 -> 3681216.3 | E12: =E11*'① 자동화 가정'!C18 -> 5331416.8 | F12: =F11*'① 자동화 가정'!C18 -> 6981617.2 | G12: =G11*'① 자동화 가정'!C18 -> 8631817.6 | H12: =H11*'① 자동화 가정'!C18 -> 10282018 | I12: =I11*'① 자동화 가정'!C18 -> 11932218 | J12: =J11*'① 자동화 가정'!C18 -> 13582419 | K12: =K11*'① 자동화 가정'!C18 -> 15232619 | L12: =L11*'① 자동화 가정'!C18 -> 16882820 | M12: =M11*'① 자동화 가정'!C18 -> 18406082 | N12: =N11*'① 자동화 가정'!C18 -> 19929344 | O12: =N11*'① 자동화 가정'!C18 -> 19929344
B14: 🇨🇴 콜롬비아 파트너(명) | C14: =ROUND('① 자동화 가정'!E26+'① 자동화 가정'!F26,0) -> 9 | D14: =ROUND(C14*(1+'① 자동화 가정'!C14/12-'① 자동화 가정'!C15/12)+'① 자동화 가정'!F26,0) -> 16 | E14: =ROUND(D14*(1+'① 자동화 가정'!C14/12-'① 자동화 가정'!C15/12)+'① 자동화 가정'!F26,0) -> 23 | F14: =ROUND(E14*(1+'① 자동화 가정'!C14/12-'① 자동화 가정'!C15/12)+'① 자동화 가정'!F26,0) -> 30 | G14: =ROUND(F14*(1+'① 자동화 가정'!C14/12-'① 자동화 가정'!C15/12)+'① 자동화 가정'!F26,0) -> 37 | H14: =ROUND(G14*(1+'① 자동화 가정'!C14/12-'① 자동화 가정'!C15/12)+'① 자동화 가정'!F26,0) -> 44 | I14: =ROUND(H14*(1+'① 자동화 가정'!C14/12-'① 자동화 가정'!C15/12)+'① 자동화 가정'!F26,0) -> 51 | J14: =ROUND(I14*(1+'① 자동화 가정'!C14/12-'① 자동화 가정'!C15/12)+'① 자동화 가정'!F26,0) -> 58 | K14: =ROUND(J14*(1+'① 자동화 가정'!C14/12-'① 자동화 가정'!C15/12)+'① 자동화 가정'!F26,0) -> 65 | L14: =ROUND(K14*(1+'① 자동화 가정'!C14/12-'① 자동화 가정'!C15/12)+'① 자동화 가정'!F26,0) -> 72 | M14: =ROUND(L14*(1+'① 자동화 가정'!C14/12-'① 자동화 가정'!C15/12)+'① 자동화 가정'!F26,0) -> 79 | N14: =ROUND(M14*(1+'① 자동화 가정'!C14/12-'① 자동화 가정'!C15/12)+'① 자동화 가정'!F26,0) -> 86 | O14: =N14 -> 86
B15: 🇨🇴 콜롬비아 수익($) | C15: =((C14*'① 자동화 가정'!C17*'① 자동화 가정'!C16*80+C14*(1-'① 자동화 가정'!C17)*'① 자동화 가정'!C16*0.375*20+C14*(1-'① 자동화 가정'!C17)*'① 자동화 가정'!C16*0.625*3)*'① 자동화 가정'!F6+(C14*'① 자동화 가정'!C17*'① 자동화 가정'!C16*80+C14*(1-'① 자동화 가정'!C17)*'① 자동화 가정'!C16*0.375*20+C14*(1-'① 자동화 가정'!C17)*'① 자동화 가정'!C16*0.625*3)*'① 자동화 가정'!C12*'① 자동화 가정'!F7+(C14*'① 자동화 가정'!C17*'① 자동화 가정'!C16*80+C14*(1-'① 자동화 가정'!C17)*'① 자동화 가정'!C16*0.375*20+C14*(1-'① 자동화 가정'!C17)*'① 자동화 가정'!C16*0.625*3)*'① 자동화 가정'!C13*'① 자동화 가정'!F8) -> 816.03318 | D15: =((D14*'① 자동화 가정'!C17*'① 자동화 가정'!C16*80+D14*(1-'① 자동화 가정'!C17)*'① 자동화 가정'!C16*0.375*20+D14*(1-'① 자동화 가정'!C17)*'① 자동화 가정'!C16*0.625*3)*'① 자동화 가정'!F6+(D14*'① 자동화 가정'!C17*'① 자동화 가정'!C16*80+D14*(1-'① 자동화 가정'!C17)*'① 자동화 가정'!C16*0.375*20+D14*(1-'① 자동화 가정'!C17)*'① 자동화 가정'!C16*0.625*3)*'① 자동화 가정'!C12*'① 자동화 가정'!F7+(D14*'① 자동화 가정'!C17*'① 자동화 가정'!C16*80+D14*(1-'① 자동화 가정'!C17)*'① 자동화 가정'!C16*0.375*20+D14*(1-'① 자동화 가정'!C17)*'① 자동화 가정'!C16*0.625*3)*'① 자동화 가정'!C13*'① 자동화 가정'!F8) -> 1450.7257 | E15: =((E14*'① 자동화 가정'!C17*'① 자동화 가정'!C16*80+E14*(1-'① 자동화 가정'!C17)*'① 자동화 가정'!C16*0.375*20+E14*(1-'① 자동화 가정'!C17)*'① 자동화 가정'!C16*0.625*3)*'① 자동화 가정'!F6+(E14*'① 자동화 가정'!C17*'① 자동화 가정'!C16*80+E14*(1-'① 자동화 가정'!C17)*'① 자동화 가정'!C16*0.375*20+E14*(1-'① 자동화 가정'!C17)*'① 자동화 가정'!C16*0.625*3)*'① 자동화 가정'!C12*'① 자동화 가정'!F7+(E14*'① 자동화 가정'!C17*'① 자동화 가정'!C16*80+E14*(1-'① 자동화 가정'!C17)*'① 자동화 가정'!C16*0.375*20+E14*(1-'① 자동화 가정'!C17)*'① 자동화 가정'!C16*0.625*3)*'① 자동화 가정'!C13*'① 자동화 가정'!F8) -> 2085.4181 | F15: =((F14*'① 자동화 가정'!C17*'① 자동화 가정'!C16*80+F14*(1-'① 자동화 가정'!C17)*'① 자동화 가정'!C16*0.375*20+F14*(1-'① 자동화 가정'!C17)*'① 자동화 가정'!C16*0.625*3)*'① 자동화 가정'!F6+(F14*'① 자동화 가정'!C17*'① 자동화 가정'!C16*80+F14*(1-'① 자동화 가정'!C17)*'① 자동화 가정'!C16*0.375*20+F14*(1-'① 자동화 가정'!C17)*'① 자동화 가정'!C16*0.625*3)*'① 자동화 가정'!C12*'① 자동화 가정'!F7+(F14*'① 자동화 가정'!C17*'① 자동화 가정'!C16*80+F14*(1-'① 자동화 가정'!C17)*'① 자동화 가정'!C16*0.375*20+F14*(1-'① 자동화 가정'!C17)*'① 자동화 가정'!C16*0.625*3)*'① 자동화 가정'!C13*'① 자동화 가정'!F8) -> 2720.1106 | G15: =((G14*'① 자동화 가정'!C17*'① 자동화 가정'!C16*80+G14*(1-'① 자동화 가정'!C17)*'① 자동화 가정'!C16*0.375*20+G14*(1-'① 자동화 가정'!C17)*'① 자동화 가정'!C16*0.625*3)*'① 자동화 가정'!F6+(G14*'① 자동화 가정'!C17*'① 자동화 가정'!C16*80+G14*(1-'① 자동화 가정'!C17)*'① 자동화 가정'!C16*0.375*20+G14*(1-'① 자동화 가정'!C17)*'① 자동화 가정'!C16*0.625*3)*'① 자동화 가정'!C12*'① 자동화 가정'!F7+(G14*'① 자동화 가정'!C17*'① 자동화 가정'!C16*80+G14*(1-'① 자동화 가정'!C17)*'① 자동화 가정'!C16*0.375*20+G14*(1-'① 자동화 가정'!C17)*'① 자동화 가정'!C16*0.625*3)*'① 자동화 가정'!C13*'① 자동화 가정'!F8) -> 3354.8031 | H15: =((H14*'① 자동화 가정'!C17*'① 자동화 가정'!C16*80+H14*(1-'① 자동화 가정'!C17)*'① 자동화 가정'!C16*0.375*20+H14*(1-'① 자동화 가정'!C17)*'① 자동화 가정'!C16*0.625*3)*'① 자동화 가정'!F6+(H14*'① 자동화 가정'!C17*'① 자동화 가정'!C16*80+H14*(1-'① 자동화 가정'!C17)*'① 자동화 가정'!C16*0.375*20+H14*(1-'① 자동화 가정'!C17)*'① 자동화 가정'!C16*0.625*3)*'① 자동화 가정'!C12*'① 자동화 가정'!F7+(H14*'① 자동화 가정'!C17*'① 자동화 가정'!C16*80+H14*(1-'① 자동화 가정'!C17)*'① 자동화 가정'!C16*0.375*20+H14*(1-'① 자동화 가정'!C17)*'① 자동화 가정'!C16*0.625*3)*'① 자동화 가정'!C13*'① 자동화 가정'!F8) -> 3989.4955 | I15: =((I14*'① 자동화 가정'!C17*'① 자동화 가정'!C16*80+I14*(1-'① 자동화 가정'!C17)*'① 자동화 가정'!C16*0.375*20+I14*(1-'① 자동화 가정'!C17)*'① 자동화 가정'!C16*0.625*3)*'① 자동화 가정'!F6+(I14*'① 자동화 가정'!C17*'① 자동화 가정'!C16*80+I14*(1-'① 자동화 가정'!C17)*'① 자동화 가정'!C16*0.375*20+I14*(1-'① 자동화 가정'!C17)*'① 자동화 가정'!C16*0.625*3)*'① 자동화 가정'!C12*'① 자동화 가정'!F7+(I14*'① 자동화 가정'!C17*'① 자동화 가정'!C16*80+I14*(1-'① 자동화 가정'!C17)*'① 자동화 가정'!C16*0.375*20+I14*(1-'① 자동화 가정'!C17)*'① 자동화 가정'!C16*0.625*3)*'① 자동화 가정'!C13*'① 자동화 가정'!F8) -> 4624.188 | J15: =((J14*'① 자동화 가정'!C17*'① 자동화 가정'!C16*80+J14*(1-'① 자동화 가정'!C17)*'① 자동화 가정'!C16*0.375*20+J14*(1-'① 자동화 가정'!C17)*'① 자동화 가정'!C16*0.625*3)*'① 자동화 가정'!F6+(J14*'① 자동화 가정'!C17*'① 자동화 가정'!C16*80+J14*(1-'① 자동화 가정'!C17)*'① 자동화 가정'!C16*0.375*20+J14*(1-'① 자동화 가정'!C17)*'① 자동화 가정'!C16*0.625*3)*'① 자동화 가정'!C12*'① 자동화 가정'!F7+(J14*'① 자동화 가정'!C17*'① 자동화 가정'!C16*80+J14*(1-'① 자동화 가정'!C17)*'① 자동화 가정'!C16*0.375*20+J14*(1-'① 자동화 가정'!C17)*'① 자동화 가정'!C16*0.625*3)*'① 자동화 가정'!C13*'① 자동화 가정'!F8) -> 5258.8805 | K15: =((K14*'① 자동화 가정'!C17*'① 자동화 가정'!C16*80+K14*(1-'① 자동화 가정'!C17)*'① 자동화 가정'!C16*0.375*20+K14*(1-'① 자동화 가정'!C17)*'① 자동화 가정'!C16*0.625*3)*'① 자동화 가정'!F6+(K14*'① 자동화 가정'!C17*'① 자동화 가정'!C16*80+K14*(1-'① 자동화 가정'!C17)*'① 자동화 가정'!C16*0.375*20+K14*(1-'① 자동화 가정'!C17)*'① 자동화 가정'!C16*0.625*3)*'① 자동화 가정'!C12*'① 자동화 가정'!F7+(K14*'① 자동화 가정'!C17*'① 자동화 가정'!C16*80+K14*(1-'① 자동화 가정'!C17)*'① 자동화 가정'!C16*0.375*20+K14*(1-'① 자동화 가정'!C17)*'① 자동화 가정'!C16*0.625*3)*'① 자동화 가정'!C13*'① 자동화 가정'!F8) -> 5893.573 | L15: =((L14*'① 자동화 가정'!C17*'① 자동화 가정'!C16*80+L14*(1-'① 자동화 가정'!C17)*'① 자동화 가정'!C16*0.375*20+L14*(1-'① 자동화 가정'!C17)*'① 자동화 가정'!C16*0.625*3)*'① 자동화 가정'!F6+(L14*'① 자동화 가정'!C17*'① 자동화 가정'!C16*80+L14*(1-'① 자동화 가정'!C17)*'① 자동화 가정'!C16*0.375*20+L14*(1-'① 자동화 가정'!C17)*'① 자동화 가정'!C16*0.625*3)*'① 자동화 가정'!C12*'① 자동화 가정'!F7+(L14*'① 자동화 가정'!C17*'① 자동화 가정'!C16*80+L14*(1-'① 자동화 가정'!C17)*'① 자동화 가정'!C16*0.375*20+L14*(1-'① 자동화 가정'!C17)*'① 자동화 가정'!C16*0.625*3)*'① 자동화 가정'!C13*'① 자동화 가정'!F8) -> 6528.2654 | M15: =((M14*'① 자동화 가정'!C17*'① 자동화 가정'!C16*80+M14*(1-'① 자동화 가정'!C17)*'① 자동화 가정'!C16*0.375*20+M14*(1-'① 자동화 가정'!C17)*'① 자동화 가정'!C16*0.625*3)*'① 자동화 가정'!F6+(M14*'① 자동화 가정'!C17*'① 자동화 가정'!C16*80+M14*(1-'① 자동화 가정'!C17)*'① 자동화 가정'!C16*0.375*20+M14*(1-'① 자동화 가정'!C17)*'① 자동화 가정'!C16*0.625*3)*'① 자동화 가정'!C12*'① 자동화 가정'!F7+(M14*'① 자동화 가정'!C17*'① 자동화 가정'!C16*80+M14*(1-'① 자동화 가정'!C17)*'① 자동화 가정'!C16*0.375*20+M14*(1-'① 자동화 가정'!C17)*'① 자동화 가정'!C16*0.625*3)*'① 자동화 가정'!C13*'① 자동화 가정'!F8) -> 7162.9579 | N15: =((N14*'① 자동화 가정'!C17*'① 자동화 가정'!C16*80+N14*(1-'① 자동화 가정'!C17)*'① 자동화 가정'!C16*0.375*20+N14*(1-'① 자동화 가정'!C17)*'① 자동화 가정'!C16*0.625*3)*'① 자동화 가정'!F6+(N14*'① 자동화 가정'!C17*'① 자동화 가정'!C16*80+N14*(1-'① 자동화 가정'!C17)*'① 자동화 가정'!C16*0.375*20+N14*(1-'① 자동화 가정'!C17)*'① 자동화 가정'!C16*0.625*3)*'① 자동화 가정'!C12*'① 자동화 가정'!F7+(N14*'① 자동화 가정'!C17*'① 자동화 가정'!C16*80+N14*(1-'① 자동화 가정'!C17)*'① 자동화 가정'!C16*0.375*20+N14*(1-'① 자동화 가정'!C17)*'① 자동화 가정'!C16*0.625*3)*'① 자동화 가정'!C13*'① 자동화 가정'!F8) -> 7797.6504 | O15: =SUM(C15:N15) -> 51682.101
B16: 🇨🇴 콜롬비아 수익(₩) | C16: =C15*'① 자동화 가정'!C18 -> 1142446.4 | D16: =D15*'① 자동화 가정'!C18 -> 2031015.9 | E16: =E15*'① 자동화 가정'!C18 -> 2919585.4 | F16: =F15*'① 자동화 가정'!C18 -> 3808154.8 | G16: =G15*'① 자동화 가정'!C18 -> 4696724.3 | H16: =H15*'① 자동화 가정'!C18 -> 5585293.8 | I16: =I15*'① 자동화 가정'!C18 -> 6473863.2 | J16: =J15*'① 자동화 가정'!C18 -> 7362432.7 | K16: =K15*'① 자동화 가정'!C18 -> 8251002.1 | L16: =L15*'① 자동화 가정'!C18 -> 9139571.6 | M16: =M15*'① 자동화 가정'!C18 -> 10028141 | N16: =N15*'① 자동화 가정'!C18 -> 10916711 | O16: =N15*'① 자동화 가정'!C18 -> 10916711
B18: 🇺🇸 미국히스패닉 파트너(명) | C18: =ROUND('① 자동화 가정'!E27+'① 자동화 가정'!F27,0) -> 10 | D18: =ROUND(C18*(1+'① 자동화 가정'!C14/12-'① 자동화 가정'!C15/12)+'① 자동화 가정'!F27,0) -> 18 | E18: =ROUND(D18*(1+'① 자동화 가정'!C14/12-'① 자동화 가정'!C15/12)+'① 자동화 가정'!F27,0) -> 26 | F18: =ROUND(E18*(1+'① 자동화 가정'!C14/12-'① 자동화 가정'!C15/12)+'① 자동화 가정'!F27,0) -> 34 | G18: =ROUND(F18*(1+'① 자동화 가정'!C14/12-'① 자동화 가정'!C15/12)+'① 자동화 가정'!F27,0) -> 42 | H18: =ROUND(G18*(1+'① 자동화 가정'!C14/12-'① 자동화 가정'!C15/12)+'① 자동화 가정'!F27,0) -> 50 | I18: =ROUND(H18*(1+'① 자동화 가정'!C14/12-'① 자동화 가정'!C15/12)+'① 자동화 가정'!F27,0) -> 58 | J18: =ROUND(I18*(1+'① 자동화 가정'!C14/12-'① 자동화 가정'!C15/12)+'① 자동화 가정'!F27,0) -> 66 | K18: =ROUND(J18*(1+'① 자동화 가정'!C14/12-'① 자동화 가정'!C15/12)+'① 자동화 가정'!F27,0) -> 74 | L18: =ROUND(K18*(1+'① 자동화 가정'!C14/12-'① 자동화 가정'!C15/12)+'① 자동화 가정'!F27,0) -> 82 | M18: =ROUND(L18*(1+'① 자동화 가정'!C14/12-'① 자동화 가정'!C15/12)+'① 자동화 가정'!F27,0) -> 90 | N18: =ROUND(M18*(1+'① 자동화 가정'!C14/12-'① 자동화 가정'!C15/12)+'① 자동화 가정'!F27,0) -> 98 | O18: =N18 -> 98
B19: 🇺🇸 미국히스패닉 수익($) | C19: =((C18*'① 자동화 가정'!C17*'① 자동화 가정'!C16*80+C18*(1-'① 자동화 가정'!C17)*'① 자동화 가정'!C16*0.375*20+C18*(1-'① 자동화 가정'!C17)*'① 자동화 가정'!C16*0.625*3)*'① 자동화 가정'!F6+(C18*'① 자동화 가정'!C17*'① 자동화 가정'!C16*80+C18*(1-'① 자동화 가정'!C17)*'① 자동화 가정'!C16*0.375*20+C18*(1-'① 자동화 가정'!C17)*'① 자동화 가정'!C16*0.625*3)*'① 자동화 가정'!C12*'① 자동화 가정'!F7+(C18*'① 자동화 가정'!C17*'① 자동화 가정'!C16*80+C18*(1-'① 자동화 가정'!C17)*'① 자동화 가정'!C16*0.375*20+C18*(1-'① 자동화 가정'!C17)*'① 자동화 가정'!C16*0.625*3)*'① 자동화 가정'!C13*'① 자동화 가정'!F8) -> 906.70353 | D19: =((D18*'① 자동화 가정'!C17*'① 자동화 가정'!C16*80+D18*(1-'① 자동화 가정'!C17)*'① 자동화 가정'!C16*0.375*20+D18*(1-'① 자동화 가정'!C17)*'① 자동화 가정'!C16*0.625*3)*'① 자동화 가정'!F6+(D18*'① 자동화 가정'!C17*'① 자동화 가정'!C16*80+D18*(1-'① 자동화 가정'!C17)*'① 자동화 가정'!C16*0.375*20+D18*(1-'① 자동화 가정'!C17)*'① 자동화 가정'!C16*0.625*3)*'① 자동화 가정'!C12*'① 자동화 가정'!F7+(D18*'① 자동화 가정'!C17*'① 자동화 가정'!C16*80+D18*(1-'① 자동화 가정'!C17)*'① 자동화 가정'!C16*0.375*20+D18*(1-'① 자동화 가정'!C17)*'① 자동화 가정'!C16*0.625*3)*'① 자동화 가정'!C13*'① 자동화 가정'!F8) -> 1632.0664 | E19: =((E18*'① 자동화 가정'!C17*'① 자동화 가정'!C16*80+E18*(1-'① 자동화 가정'!C17)*'① 자동화 가정'!C16*0.375*20+E18*(1-'① 자동화 가정'!C17)*'① 자동화 가정'!C16*0.625*3)*'① 자동화 가정'!F6+(E18*'① 자동화 가정'!C17*'① 자동화 가정'!C16*80+E18*(1-'① 자동화 가정'!C17)*'① 자동화 가정'!C16*0.375*20+E18*(1-'① 자동화 가정'!C17)*'① 자동화 가정'!C16*0.625*3)*'① 자동화 가정'!C12*'① 자동화 가정'!F7+(E18*'① 자동화 가정'!C17*'① 자동화 가정'!C16*80+E18*(1-'① 자동화 가정'!C17)*'① 자동화 가정'!C16*0.375*20+E18*(1-'① 자동화 가정'!C17)*'① 자동화 가정'!C16*0.625*3)*'① 자동화 가정'!C13*'① 자동화 가정'!F8) -> 2357.4292 | F19: =((F18*'① 자동화 가정'!C17*'① 자동화 가정'!C16*80+F18*(1-'① 자동화 가정'!C17)*'① 자동화 가정'!C16*0.375*20+F18*(1-'① 자동화 가정'!C17)*'① 자동화 가정'!C16*0.625*3)*'① 자동화 가정'!F6+(F18*'① 자동화 가정'!C17*'① 자동화 가정'!C16*80+F18*(1-'① 자동화 가정'!C17)*'① 자동화 가정'!C16*0.375*20+F18*(1-'① 자동화 가정'!C17)*'① 자동화 가정'!C16*0.625*3)*'① 자동화 가정'!C12*'① 자동화 가정'!F7+(F18*'① 자동화 가정'!C17*'① 자동화 가정'!C16*80+F18*(1-'① 자동화 가정'!C17)*'① 자동화 가정'!C16*0.375*20+F18*(1-'① 자동화 가정'!C17)*'① 자동화 가정'!C16*0.625*3)*'① 자동화 가정'!C13*'① 자동화 가정'!F8) -> 3082.792 | G19: =((G18*'① 자동화 가정'!C17*'① 자동화 가정'!C16*80+G18*(1-'① 자동화 가정'!C17)*'① 자동화 가정'!C16*0.375*20+G18*(1-'① 자동화 가정'!C17)*'① 자동화 가정'!C16*0.625*3)*'① 자동화 가정'!F6+(G18*'① 자동화 가정'!C17*'① 자동화 가정'!C16*80+G18*(1-'① 자동화 가정'!C17)*'① 자동화 가정'!C16*0.375*20+G18*(1-'① 자동화 가정'!C17)*'① 자동화 가정'!C16*0.625*3)*'① 자동화 가정'!C12*'① 자동화 가정'!F7+(G18*'① 자동화 가정'!C17*'① 자동화 가정'!C16*80+G18*(1-'① 자동화 가정'!C17)*'① 자동화 가정'!C16*0.375*20+G18*(1-'① 자동화 가정'!C17)*'① 자동화 가정'!C16*0.625*3)*'① 자동화 가정'!C13*'① 자동화 가정'!F8) -> 3808.1548 | H19: =((H18*'① 자동화 가정'!C17*'① 자동화 가정'!C16*80+H18*(1-'① 자동화 가정'!C17)*'① 자동화 가정'!C16*0.375*20+H18*(1-'① 자동화 가정'!C17)*'① 자동화 가정'!C16*0.625*3)*'① 자동화 가정'!F6+(H18*'① 자동화 가정'!C17*'① 자동화 가정'!C16*80+H18*(1-'① 자동화 가정'!C17)*'① 자동화 가정'!C16*0.375*20+H18*(1-'① 자동화 가정'!C17)*'① 자동화 가정'!C16*0.625*3)*'① 자동화 가정'!C12*'① 자동화 가정'!F7+(H18*'① 자동화 가정'!C17*'① 자동화 가정'!C16*80+H18*(1-'① 자동화 가정'!C17)*'① 자동화 가정'!C16*0.375*20+H18*(1-'① 자동화 가정'!C17)*'① 자동화 가정'!C16*0.625*3)*'① 자동화 가정'!C13*'① 자동화 가정'!F8) -> 4533.5177 | I19: =((I18*'① 자동화 가정'!C17*'① 자동화 가정'!C16*80+I18*(1-'① 자동화 가정'!C17)*'① 자동화 가정'!C16*0.375*20+I18*(1-'① 자동화 가정'!C17)*'① 자동화 가정'!C16*0.625*3)*'① 자동화 가정'!F6+(I18*'① 자동화 가정'!C17*'① 자동화 가정'!C16*80+I18*(1-'① 자동화 가정'!C17)*'① 자동화 가정'!C16*0.375*20+I18*(1-'① 자동화 가정'!C17)*'① 자동화 가정'!C16*0.625*3)*'① 자동화 가정'!C12*'① 자동화 가정'!F7+(I18*'① 자동화 가정'!C17*'① 자동화 가정'!C16*80+I18*(1-'① 자동화 가정'!C17)*'① 자동화 가정'!C16*0.375*20+I18*(1-'① 자동화 가정'!C17)*'① 자동화 가정'!C16*0.625*3)*'① 자동화 가정'!C13*'① 자동화 가정'!F8) -> 5258.8805 | J19: =((J18*'① 자동화 가정'!C17*'① 자동화 가정'!C16*80+J18*(1-'① 자동화 가정'!C17)*'① 자동화 가정'!C16*0.375*20+J18*(1-'① 자동화 가정'!C17)*'① 자동화 가정'!C16*0.625*3)*'① 자동화 가정'!F6+(J18*'① 자동화 가정'!C17*'① 자동화 가정'!C16*80+J18*(1-'① 자동화 가정'!C17)*'① 자동화 가정'!C16*0.375*20+J18*(1-'① 자동화 가정'!C17)*'① 자동화 가정'!C16*0.625*3)*'① 자동화 가정'!C12*'① 자동화 가정'!F7+(J18*'① 자동화 가정'!C17*'① 자동화 가정'!C16*80+J18*(1-'① 자동화 가정'!C17)*'① 자동화 가정'!C16*0.375*20+J18*(1-'① 자동화 가정'!C17)*'① 자동화 가정'!C16*0.625*3)*'① 자동화 가정'!C13*'① 자동화 가정'!F8) -> 5984.2433 | K19: =((K18*'① 자동화 가정'!C17*'① 자동화 가정'!C16*80+K18*(1-'① 자동화 가정'!C17)*'① 자동화 가정'!C16*0.375*20+K18*(1-'① 자동화 가정'!C17)*'① 자동화 가정'!C16*0.625*3)*'① 자동화 가정'!F6+(K18*'① 자동화 가정'!C17*'① 자동화 가정'!C16*80+K18*(1-'① 자동화 가정'!C17)*'① 자동화 가정'!C16*0.375*20+K18*(1-'① 자동화 가정'!C17)*'① 자동화 가정'!C16*0.625*3)*'① 자동화 가정'!C12*'① 자동화 가정'!F7+(K18*'① 자동화 가정'!C17*'① 자동화 가정'!C16*80+K18*(1-'① 자동화 가정'!C17)*'① 자동화 가정'!C16*0.375*20+K18*(1-'① 자동화 가정'!C17)*'① 자동화 가정'!C16*0.625*3)*'① 자동화 가정'!C13*'① 자동화 가정'!F8) -> 6709.6061 | L19: =((L18*'① 자동화 가정'!C17*'① 자동화 가정'!C16*80+L18*(1-'① 자동화 가정'!C17)*'① 자동화 가정'!C16*0.375*20+L18*(1-'① 자동화 가정'!C17)*'① 자동화 가정'!C16*0.625*3)*'① 자동화 가정'!F6+(L18*'① 자동화 가정'!C17*'① 자동화 가정'!C16*80+L18*(1-'① 자동화 가정'!C17)*'① 자동화 가정'!C16*0.375*20+L18*(1-'① 자동화 가정'!C17)*'① 자동화 가정'!C16*0.625*3)*'① 자동화 가정'!C12*'① 자동화 가정'!F7+(L18*'① 자동화 가정'!C17*'① 자동화 가정'!C16*80+L18*(1-'① 자동화 가정'!C17)*'① 자동화 가정'!C16*0.375*20+L18*(1-'① 자동화 가정'!C17)*'① 자동화 가정'!C16*0.625*3)*'① 자동화 가정'!C13*'① 자동화 가정'!F8) -> 7434.969 | M19: =((M18*'① 자동화 가정'!C17*'① 자동화 가정'!C16*80+M18*(1-'① 자동화 가정'!C17)*'① 자동화 가정'!C16*0.375*20+M18*(1-'① 자동화 가정'!C17)*'① 자동화 가정'!C16*0.625*3)*'① 자동화 가정'!F6+(M18*'① 자동화 가정'!C17*'① 자동화 가정'!C16*80+M18*(1-'① 자동화 가정'!C17)*'① 자동화 가정'!C16*0.375*20+M18*(1-'① 자동화 가정'!C17)*'① 자동화 가정'!C16*0.625*3)*'① 자동화 가정'!C12*'① 자동화 가정'!F7+(M18*'① 자동화 가정'!C17*'① 자동화 가정'!C16*80+M18*(1-'① 자동화 가정'!C17)*'① 자동화 가정'!C16*0.375*20+M18*(1-'① 자동화 가정'!C17)*'① 자동화 가정'!C16*0.625*3)*'① 자동화 가정'!C13*'① 자동화 가정'!F8) -> 8160.3318 | N19: =((N18*'① 자동화 가정'!C17*'① 자동화 가정'!C16*80+N18*(1-'① 자동화 가정'!C17)*'① 자동화 가정'!C16*0.375*20+N18*(1-'① 자동화 가정'!C17)*'① 자동화 가정'!C16*0.625*3)*'① 자동화 가정'!F6+(N18*'① 자동화 가정'!C17*'① 자동화 가정'!C16*80+N18*(1-'① 자동화 가정'!C17)*'① 자동화 가정'!C16*0.375*20+N18*(1-'① 자동화 가정'!C17)*'① 자동화 가정'!C16*0.625*3)*'① 자동화 가정'!C12*'① 자동화 가정'!F7+(N18*'① 자동화 가정'!C17*'① 자동화 가정'!C16*80+N18*(1-'① 자동화 가정'!C17)*'① 자동화 가정'!C16*0.375*20+N18*(1-'① 자동화 가정'!C17)*'① 자동화 가정'!C16*0.625*3)*'① 자동화 가정'!C13*'① 자동화 가정'!F8) -> 8885.6946 | O19: =SUM(C19:N19) -> 58754.389
B20: 🇺🇸 미국히스패닉 수익(₩) | C20: =C19*'① 자동화 가정'!C18 -> 1269384.9 | D20: =D19*'① 자동화 가정'!C18 -> 2284892.9 | E20: =E19*'① 자동화 가정'!C18 -> 3300400.9 | F20: =F19*'① 자동화 가정'!C18 -> 4315908.8 | G20: =G19*'① 자동화 가정'!C18 -> 5331416.8 | H20: =H19*'① 자동화 가정'!C18 -> 6346924.7 | I20: =I19*'① 자동화 가정'!C18 -> 7362432.7 | J20: =J19*'① 자동화 가정'!C18 -> 8377940.6 | K20: =K19*'① 자동화 가정'!C18 -> 9393448.6 | L20: =L19*'① 자동화 가정'!C18 -> 10408957 | M20: =M19*'① 자동화 가정'!C18 -> 11424464 | N20: =N19*'① 자동화 가정'!C18 -> 12439972 | O20: =N19*'① 자동화 가정'!C18 -> 12439972
B22: 🇦🇷 아르헨티나 파트너(명) | C22: =ROUND('① 자동화 가정'!E28+'① 자동화 가정'!F28,0) -> 5 | D22: =ROUND(C22*(1+'① 자동화 가정'!C14/12-'① 자동화 가정'!C15/12)+'① 자동화 가정'!F28,0) -> 9 | E22: =ROUND(D22*(1+'① 자동화 가정'!C14/12-'① 자동화 가정'!C15/12)+'① 자동화 가정'!F28,0) -> 13 | F22: =ROUND(E22*(1+'① 자동화 가정'!C14/12-'① 자동화 가정'!C15/12)+'① 자동화 가정'!F28,0) -> 17 | G22: =ROUND(F22*(1+'① 자동화 가정'!C14/12-'① 자동화 가정'!C15/12)+'① 자동화 가정'!F28,0) -> 21 | H22: =ROUND(G22*(1+'① 자동화 가정'!C14/12-'① 자동화 가정'!C15/12)+'① 자동화 가정'!F28,0) -> 25 | I22: =ROUND(H22*(1+'① 자동화 가정'!C14/12-'① 자동화 가정'!C15/12)+'① 자동화 가정'!F28,0) -> 29 | J22: =ROUND(I22*(1+'① 자동화 가정'!C14/12-'① 자동화 가정'!C15/12)+'① 자동화 가정'!F28,0) -> 33 | K22: =ROUND(J22*(1+'① 자동화 가정'!C14/12-'① 자동화 가정'!C15/12)+'① 자동화 가정'!F28,0) -> 37 | L22: =ROUND(K22*(1+'① 자동화 가정'!C14/12-'① 자동화 가정'!C15/12)+'① 자동화 가정'!F28,0) -> 41 | M22: =ROUND(L22*(1+'① 자동화 가정'!C14/12-'① 자동화 가정'!C15/12)+'① 자동화 가정'!F28,0) -> 45 | N22: =ROUND(M22*(1+'① 자동화 가정'!C14/12-'① 자동화 가정'!C15/12)+'① 자동화 가정'!F28,0) -> 49 | O22: =N22 -> 49
B23: 🇦🇷 아르헨티나 수익($) | C23: =((C22*'① 자동화 가정'!C17*'① 자동화 가정'!C16*80+C22*(1-'① 자동화 가정'!C17)*'① 자동화 가정'!C16*0.375*20+C22*(1-'① 자동화 가정'!C17)*'① 자동화 가정'!C16*0.625*3)*'① 자동화 가정'!F6+(C22*'① 자동화 가정'!C17*'① 자동화 가정'!C16*80+C22*(1-'① 자동화 가정'!C17)*'① 자동화 가정'!C16*0.375*20+C22*(1-'① 자동화 가정'!C17)*'① 자동화 가정'!C16*0.625*3)*'① 자동화 가정'!C12*'① 자동화 가정'!F7+(C22*'① 자동화 가정'!C17*'① 자동화 가정'!C16*80+C22*(1-'① 자동화 가정'!C17)*'① 자동화 가정'!C16*0.375*20+C22*(1-'① 자동화 가정'!C17)*'① 자동화 가정'!C16*0.625*3)*'① 자동화 가정'!C13*'① 자동화 가정'!F8) -> 453.35177 | D23: =((D22*'① 자동화 가정'!C17*'① 자동화 가정'!C16*80+D22*(1-'① 자동화 가정'!C17)*'① 자동화 가정'!C16*0.375*20+D22*(1-'① 자동화 가정'!C17)*'① 자동화 가정'!C16*0.625*3)*'① 자동화 가정'!F6+(D22*'① 자동화 가정'!C17*'① 자동화 가정'!C16*80+D22*(1-'① 자동화 가정'!C17)*'① 자동화 가정'!C16*0.375*20+D22*(1-'① 자동화 가정'!C17)*'① 자동화 가정'!C16*0.625*3)*'① 자동화 가정'!C12*'① 자동화 가정'!F7+(D22*'① 자동화 가정'!C17*'① 자동화 가정'!C16*80+D22*(1-'① 자동화 가정'!C17)*'① 자동화 가정'!C16*0.375*20+D22*(1-'① 자동화 가정'!C17)*'① 자동화 가정'!C16*0.625*3)*'① 자동화 가정'!C13*'① 자동화 가정'!F8) -> 816.03318 | E23: =((E22*'① 자동화 가정'!C17*'① 자동화 가정'!C16*80+E22*(1-'① 자동화 가정'!C17)*'① 자동화 가정'!C16*0.375*20+E22*(1-'① 자동화 가정'!C17)*'① 자동화 가정'!C16*0.625*3)*'① 자동화 가정'!F6+(E22*'① 자동화 가정'!C17*'① 자동화 가정'!C16*80+E22*(1-'① 자동화 가정'!C17)*'① 자동화 가정'!C16*0.375*20+E22*(1-'① 자동화 가정'!C17)*'① 자동화 가정'!C16*0.625*3)*'① 자동화 가정'!C12*'① 자동화 가정'!F7+(E22*'① 자동화 가정'!C17*'① 자동화 가정'!C16*80+E22*(1-'① 자동화 가정'!C17)*'① 자동화 가정'!C16*0.375*20+E22*(1-'① 자동화 가정'!C17)*'① 자동화 가정'!C16*0.625*3)*'① 자동화 가정'!C13*'① 자동화 가정'!F8) -> 1178.7146 | F23: =((F22*'① 자동화 가정'!C17*'① 자동화 가정'!C16*80+F22*(1-'① 자동화 가정'!C17)*'① 자동화 가정'!C16*0.375*20+F22*(1-'① 자동화 가정'!C17)*'① 자동화 가정'!C16*0.625*3)*'① 자동화 가정'!F6+(F22*'① 자동화 가정'!C17*'① 자동화 가정'!C16*80+F22*(1-'① 자동화 가정'!C17)*'① 자동화 가정'!C16*0.375*20+F22*(1-'① 자동화 가정'!C17)*'① 자동화 가정'!C16*0.625*3)*'① 자동화 가정'!C12*'① 자동화 가정'!F7+(F22*'① 자동화 가정'!C17*'① 자동화 가정'!C16*80+F22*(1-'① 자동화 가정'!C17)*'① 자동화 가정'!C16*0.375*20+F22*(1-'① 자동화 가정'!C17)*'① 자동화 가정'!C16*0.625*3)*'① 자동화 가정'!C13*'① 자동화 가정'!F8) -> 1541.396 | G23: =((G22*'① 자동화 가정'!C17*'① 자동화 가정'!C16*80+G22*(1-'① 자동화 가정'!C17)*'① 자동화 가정'!C16*0.375*20+G22*(1-'① 자동화 가정'!C17)*'① 자동화 가정'!C16*0.625*3)*'① 자동화 가정'!F6+(G22*'① 자동화 가정'!C17*'① 자동화 가정'!C16*80+G22*(1-'① 자동화 가정'!C17)*'① 자동화 가정'!C16*0.375*20+G22*(1-'① 자동화 가정'!C17)*'① 자동화 가정'!C16*0.625*3)*'① 자동화 가정'!C12*'① 자동화 가정'!F7+(G22*'① 자동화 가정'!C17*'① 자동화 가정'!C16*80+G22*(1-'① 자동화 가정'!C17)*'① 자동화 가정'!C16*0.375*20+G22*(1-'① 자동화 가정'!C17)*'① 자동화 가정'!C16*0.625*3)*'① 자동화 가정'!C13*'① 자동화 가정'!F8) -> 1904.0774 | H23: =((H22*'① 자동화 가정'!C17*'① 자동화 가정'!C16*80+H22*(1-'① 자동화 가정'!C17)*'① 자동화 가정'!C16*0.375*20+H22*(1-'① 자동화 가정'!C17)*'① 자동화 가정'!C16*0.625*3)*'① 자동화 가정'!F6+(H22*'① 자동화 가정'!C17*'① 자동화 가정'!C16*80+H22*(1-'① 자동화 가정'!C17)*'① 자동화 가정'!C16*0.375*20+H22*(1-'① 자동화 가정'!C17)*'① 자동화 가정'!C16*0.625*3)*'① 자동화 가정'!C12*'① 자동화 가정'!F7+(H22*'① 자동화 가정'!C17*'① 자동화 가정'!C16*80+H22*(1-'① 자동화 가정'!C17)*'① 자동화 가정'!C16*0.375*20+H22*(1-'① 자동화 가정'!C17)*'① 자동화 가정'!C16*0.625*3)*'① 자동화 가정'!C13*'① 자동화 가정'!F8) -> 2266.7588 | I23: =((I22*'① 자동화 가정'!C17*'① 자동화 가정'!C16*80+I22*(1-'① 자동화 가정'!C17)*'① 자동화 가정'!C16*0.375*20+I22*(1-'① 자동화 가정'!C17)*'① 자동화 가정'!C16*0.625*3)*'① 자동화 가정'!F6+(I22*'① 자동화 가정'!C17*'① 자동화 가정'!C16*80+I22*(1-'① 자동화 가정'!C17)*'① 자동화 가정'!C16*0.375*20+I22*(1-'① 자동화 가정'!C17)*'① 자동화 가정'!C16*0.625*3)*'① 자동화 가정'!C12*'① 자동화 가정'!F7+(I22*'① 자동화 가정'!C17*'① 자동화 가정'!C16*80+I22*(1-'① 자동화 가정'!C17)*'① 자동화 가정'!C16*0.375*20+I22*(1-'① 자동화 가정'!C17)*'① 자동화 가정'!C16*0.625*3)*'① 자동화 가정'!C13*'① 자동화 가정'!F8) -> 2629.4402 | J23: =((J22*'① 자동화 가정'!C17*'① 자동화 가정'!C16*80+J22*(1-'① 자동화 가정'!C17)*'① 자동화 가정'!C16*0.375*20+J22*(1-'① 자동화 가정'!C17)*'① 자동화 가정'!C16*0.625*3)*'① 자동화 가정'!F6+(J22*'① 자동화 가정'!C17*'① 자동화 가정'!C16*80+J22*(1-'① 자동화 가정'!C17)*'① 자동화 가정'!C16*0.375*20+J22*(1-'① 자동화 가정'!C17)*'① 자동화 가정'!C16*0.625*3)*'① 자동화 가정'!C12*'① 자동화 가정'!F7+(J22*'① 자동화 가정'!C17*'① 자동화 가정'!C16*80+J22*(1-'① 자동화 가정'!C17)*'① 자동화 가정'!C16*0.375*20+J22*(1-'① 자동화 가정'!C17)*'① 자동화 가정'!C16*0.625*3)*'① 자동화 가정'!C13*'① 자동화 가정'!F8) -> 2992.1217 | K23: =((K22*'① 자동화 가정'!C17*'① 자동화 가정'!C16*80+K22*(1-'① 자동화 가정'!C17)*'① 자동화 가정'!C16*0.375*20+K22*(1-'① 자동화 가정'!C17)*'① 자동화 가정'!C16*0.625*3)*'① 자동화 가정'!F6+(K22*'① 자동화 가정'!C17*'① 자동화 가정'!C16*80+K22*(1-'① 자동화 가정'!C17)*'① 자동화 가정'!C16*0.375*20+K22*(1-'① 자동화 가정'!C17)*'① 자동화 가정'!C16*0.625*3)*'① 자동화 가정'!C12*'① 자동화 가정'!F7+(K22*'① 자동화 가정'!C17*'① 자동화 가정'!C16*80+K22*(1-'① 자동화 가정'!C17)*'① 자동화 가정'!C16*0.375*20+K22*(1-'① 자동화 가정'!C17)*'① 자동화 가정'!C16*0.625*3)*'① 자동화 가정'!C13*'① 자동화 가정'!F8) -> 3354.8031 | L23: =((L22*'① 자동화 가정'!C17*'① 자동화 가정'!C16*80+L22*(1-'① 자동화 가정'!C17)*'① 자동화 가정'!C16*0.375*20+L22*(1-'① 자동화 가정'!C17)*'① 자동화 가정'!C16*0.625*3)*'① 자동화 가정'!F6+(L22*'① 자동화 가정'!C17*'① 자동화 가정'!C16*80+L22*(1-'① 자동화 가정'!C17)*'① 자동화 가정'!C16*0.375*20+L22*(1-'① 자동화 가정'!C17)*'① 자동화 가정'!C16*0.625*3)*'① 자동화 가정'!C12*'① 자동화 가정'!F7+(L22*'① 자동화 가정'!C17*'① 자동화 가정'!C16*80+L22*(1-'① 자동화 가정'!C17)*'① 자동화 가정'!C16*0.375*20+L22*(1-'① 자동화 가정'!C17)*'① 자동화 가정'!C16*0.625*3)*'① 자동화 가정'!C13*'① 자동화 가정'!F8) -> 3717.4845 | M23: =((M22*'① 자동화 가정'!C17*'① 자동화 가정'!C16*80+M22*(1-'① 자동화 가정'!C17)*'① 자동화 가정'!C16*0.375*20+M22*(1-'① 자동화 가정'!C17)*'① 자동화 가정'!C16*0.625*3)*'① 자동화 가정'!F6+(M22*'① 자동화 가정'!C17*'① 자동화 가정'!C16*80+M22*(1-'① 자동화 가정'!C17)*'① 자동화 가정'!C16*0.375*20+M22*(1-'① 자동화 가정'!C17)*'① 자동화 가정'!C16*0.625*3)*'① 자동화 가정'!C12*'① 자동화 가정'!F7+(M22*'① 자동화 가정'!C17*'① 자동화 가정'!C16*80+M22*(1-'① 자동화 가정'!C17)*'① 자동화 가정'!C16*0.375*20+M22*(1-'① 자동화 가정'!C17)*'① 자동화 가정'!C16*0.625*3)*'① 자동화 가정'!C13*'① 자동화 가정'!F8) -> 4080.1659 | N23: =((N22*'① 자동화 가정'!C17*'① 자동화 가정'!C16*80+N22*(1-'① 자동화 가정'!C17)*'① 자동화 가정'!C16*0.375*20+N22*(1-'① 자동화 가정'!C17)*'① 자동화 가정'!C16*0.625*3)*'① 자동화 가정'!F6+(N22*'① 자동화 가정'!C17*'① 자동화 가정'!C16*80+N22*(1-'① 자동화 가정'!C17)*'① 자동화 가정'!C16*0.375*20+N22*(1-'① 자동화 가정'!C17)*'① 자동화 가정'!C16*0.625*3)*'① 자동화 가정'!C12*'① 자동화 가정'!F7+(N22*'① 자동화 가정'!C17*'① 자동화 가정'!C16*80+N22*(1-'① 자동화 가정'!C17)*'① 자동화 가정'!C16*0.375*20+N22*(1-'① 자동화 가정'!C17)*'① 자동화 가정'!C16*0.625*3)*'① 자동화 가정'!C13*'① 자동화 가정'!F8) -> 4442.8473 | O23: =SUM(C23:N23) -> 29377.194
B24: 🇦🇷 아르헨티나 수익(₩) | C24: =C23*'① 자동화 가정'!C18 -> 634692.47 | D24: =D23*'① 자동화 가정'!C18 -> 1142446.4 | E24: =E23*'① 자동화 가정'!C18 -> 1650200.4 | F24: =F23*'① 자동화 가정'!C18 -> 2157954.4 | G24: =G23*'① 자동화 가정'!C18 -> 2665708.4 | H24: =H23*'① 자동화 가정'!C18 -> 3173462.4 | I24: =I23*'① 자동화 가정'!C18 -> 3681216.3 | J24: =J23*'① 자동화 가정'!C18 -> 4188970.3 | K24: =K23*'① 자동화 가정'!C18 -> 4696724.3 | L24: =L23*'① 자동화 가정'!C18 -> 5204478.3 | M24: =M23*'① 자동화 가정'!C18 -> 5712232.2 | N24: =N23*'① 자동화 가정'!C18 -> 6219986.2 | O24: =N23*'① 자동화 가정'!C18 -> 6219986.2
B26: 🇨🇱 칠레 파트너(명) | C26: =ROUND('① 자동화 가정'!E29+'① 자동화 가정'!F29,0) -> 4 | D26: =ROUND(C26*(1+'① 자동화 가정'!C14/12-'① 자동화 가정'!C15/12)+'① 자동화 가정'!F29,0) -> 7 | E26: =ROUND(D26*(1+'① 자동화 가정'!C14/12-'① 자동화 가정'!C15/12)+'① 자동화 가정'!F29,0) -> 10 | F26: =ROUND(E26*(1+'① 자동화 가정'!C14/12-'① 자동화 가정'!C15/12)+'① 자동화 가정'!F29,0) -> 13 | G26: =ROUND(F26*(1+'① 자동화 가정'!C14/12-'① 자동화 가정'!C15/12)+'① 자동화 가정'!F29,0) -> 16 | H26: =ROUND(G26*(1+'① 자동화 가정'!C14/12-'① 자동화 가정'!C15/12)+'① 자동화 가정'!F29,0) -> 19 | I26: =ROUND(H26*(1+'① 자동화 가정'!C14/12-'① 자동화 가정'!C15/12)+'① 자동화 가정'!F29,0) -> 22 | J26: =ROUND(I26*(1+'① 자동화 가정'!C14/12-'① 자동화 가정'!C15/12)+'① 자동화 가정'!F29,0) -> 25 | K26: =ROUND(J26*(1+'① 자동화 가정'!C14/12-'① 자동화 가정'!C15/12)+'① 자동화 가정'!F29,0) -> 28 | L26: =ROUND(K26*(1+'① 자동화 가정'!C14/12-'① 자동화 가정'!C15/12)+'① 자동화 가정'!F29,0) -> 31 | M26: =ROUND(L26*(1+'① 자동화 가정'!C14/12-'① 자동화 가정'!C15/12)+'① 자동화 가정'!F29,0) -> 34 | N26: =ROUND(M26*(1+'① 자동화 가정'!C14/12-'① 자동화 가정'!C15/12)+'① 자동화 가정'!F29,0) -> 37 | O26: =N26 -> 37
B27: 🇨🇱 칠레 수익($) | C27: =((C26*'① 자동화 가정'!C17*'① 자동화 가정'!C16*80+C26*(1-'① 자동화 가정'!C17)*'① 자동화 가정'!C16*0.375*20+C26*(1-'① 자동화 가정'!C17)*'① 자동화 가정'!C16*0.625*3)*'① 자동화 가정'!F6+(C26*'① 자동화 가정'!C17*'① 자동화 가정'!C16*80+C26*(1-'① 자동화 가정'!C17)*'① 자동화 가정'!C16*0.375*20+C26*(1-'① 자동화 가정'!C17)*'① 자동화 가정'!C16*0.625*3)*'① 자동화 가정'!C12*'① 자동화 가정'!F7+(C26*'① 자동화 가정'!C17*'① 자동화 가정'!C16*80+C26*(1-'① 자동화 가정'!C17)*'① 자동화 가정'!C16*0.375*20+C26*(1-'① 자동화 가정'!C17)*'① 자동화 가정'!C16*0.625*3)*'① 자동화 가정'!C13*'① 자동화 가정'!F8) -> 362.68141 | D27: =((D26*'① 자동화 가정'!C17*'① 자동화 가정'!C16*80+D26*(1-'① 자동화 가정'!C17)*'① 자동화 가정'!C16*0.375*20+D26*(1-'① 자동화 가정'!C17)*'① 자동화 가정'!C16*0.625*3)*'① 자동화 가정'!F6+(D26*'① 자동화 가정'!C17*'① 자동화 가정'!C16*80+D26*(1-'① 자동화 가정'!C17)*'① 자동화 가정'!C16*0.375*20+D26*(1-'① 자동화 가정'!C17)*'① 자동화 가정'!C16*0.625*3)*'① 자동화 가정'!C12*'① 자동화 가정'!F7+(D26*'① 자동화 가정'!C17*'① 자동화 가정'!C16*80+D26*(1-'① 자동화 가정'!C17)*'① 자동화 가정'!C16*0.375*20+D26*(1-'① 자동화 가정'!C17)*'① 자동화 가정'!C16*0.625*3)*'① 자동화 가정'!C13*'① 자동화 가정'!F8) -> 634.69247 | E27: =((E26*'① 자동화 가정'!C17*'① 자동화 가정'!C16*80+E26*(1-'① 자동화 가정'!C17)*'① 자동화 가정'!C16*0.375*20+E26*(1-'① 자동화 가정'!C17)*'① 자동화 가정'!C16*0.625*3)*'① 자동화 가정'!F6+(E26*'① 자동화 가정'!C17*'① 자동화 가정'!C16*80+E26*(1-'① 자동화 가정'!C17)*'① 자동화 가정'!C16*0.375*20+E26*(1-'① 자동화 가정'!C17)*'① 자동화 가정'!C16*0.625*3)*'① 자동화 가정'!C12*'① 자동화 가정'!F7+(E26*'① 자동화 가정'!C17*'① 자동화 가정'!C16*80+E26*(1-'① 자동화 가정'!C17)*'① 자동화 가정'!C16*0.375*20+E26*(1-'① 자동화 가정'!C17)*'① 자동화 가정'!C16*0.625*3)*'① 자동화 가정'!C13*'① 자동화 가정'!F8) -> 906.70353 | F27: =((F26*'① 자동화 가정'!C17*'① 자동화 가정'!C16*80+F26*(1-'① 자동화 가정'!C17)*'① 자동화 가정'!C16*0.375*20+F26*(1-'① 자동화 가정'!C17)*'① 자동화 가정'!C16*0.625*3)*'① 자동화 가정'!F6+(F26*'① 자동화 가정'!C17*'① 자동화 가정'!C16*80+F26*(1-'① 자동화 가정'!C17)*'① 자동화 가정'!C16*0.375*20+F26*(1-'① 자동화 가정'!C17)*'① 자동화 가정'!C16*0.625*3)*'① 자동화 가정'!C12*'① 자동화 가정'!F7+(F26*'① 자동화 가정'!C17*'① 자동화 가정'!C16*80+F26*(1-'① 자동화 가정'!C17)*'① 자동화 가정'!C16*0.375*20+F26*(1-'① 자동화 가정'!C17)*'① 자동화 가정'!C16*0.625*3)*'① 자동화 가정'!C13*'① 자동화 가정'!F8) -> 1178.7146 | G27: =((G26*'① 자동화 가정'!C17*'① 자동화 가정'!C16*80+G26*(1-'① 자동화 가정'!C17)*'① 자동화 가정'!C16*0.375*20+G26*(1-'① 자동화 가정'!C17)*'① 자동화 가정'!C16*0.625*3)*'① 자동화 가정'!F6+(G26*'① 자동화 가정'!C17*'① 자동화 가정'!C16*80+G26*(1-'① 자동화 가정'!C17)*'① 자동화 가정'!C16*0.375*20+G26*(1-'① 자동화 가정'!C17)*'① 자동화 가정'!C16*0.625*3)*'① 자동화 가정'!C12*'① 자동화 가정'!F7+(G26*'① 자동화 가정'!C17*'① 자동화 가정'!C16*80+G26*(1-'① 자동화 가정'!C17)*'① 자동화 가정'!C16*0.375*20+G26*(1-'① 자동화 가정'!C17)*'① 자동화 가정'!C16*0.625*3)*'① 자동화 가정'!C13*'① 자동화 가정'!F8) -> 1450.7257 | H27: =((H26*'① 자동화 가정'!C17*'① 자동화 가정'!C16*80+H26*(1-'① 자동화 가정'!C17)*'① 자동화 가정'!C16*0.375*20+H26*(1-'① 자동화 가정'!C17)*'① 자동화 가정'!C16*0.625*3)*'① 자동화 가정'!F6+(H26*'① 자동화 가정'!C17*'① 자동화 가정'!C16*80+H26*(1-'① 자동화 가정'!C17)*'① 자동화 가정'!C16*0.375*20+H26*(1-'① 자동화 가정'!C17)*'① 자동화 가정'!C16*0.625*3)*'① 자동화 가정'!C12*'① 자동화 가정'!F7+(H26*'① 자동화 가정'!C17*'① 자동화 가정'!C16*80+H26*(1-'① 자동화 가정'!C17)*'① 자동화 가정'!C16*0.375*20+H26*(1-'① 자동화 가정'!C17)*'① 자동화 가정'!C16*0.625*3)*'① 자동화 가정'!C13*'① 자동화 가정'!F8) -> 1722.7367 | I27: =((I26*'① 자동화 가정'!C17*'① 자동화 가정'!C16*80+I26*(1-'① 자동화 가정'!C17)*'① 자동화 가정'!C16*0.375*20+I26*(1-'① 자동화 가정'!C17)*'① 자동화 가정'!C16*0.625*3)*'① 자동화 가정'!F6+(I26*'① 자동화 가정'!C17*'① 자동화 가정'!C16*80+I26*(1-'① 자동화 가정'!C17)*'① 자동화 가정'!C16*0.375*20+I26*(1-'① 자동화 가정'!C17)*'① 자동화 가정'!C16*0.625*3)*'① 자동화 가정'!C12*'① 자동화 가정'!F7+(I26*'① 자동화 가정'!C17*'① 자동화 가정'!C16*80+I26*(1-'① 자동화 가정'!C17)*'① 자동화 가정'!C16*0.375*20+I26*(1-'① 자동화 가정'!C17)*'① 자동화 가정'!C16*0.625*3)*'① 자동화 가정'!C13*'① 자동화 가정'!F8) -> 1994.7478 | J27: =((J26*'① 자동화 가정'!C17*'① 자동화 가정'!C16*80+J26*(1-'① 자동화 가정'!C17)*'① 자동화 가정'!C16*0.375*20+J26*(1-'① 자동화 가정'!C17)*'① 자동화 가정'!C16*0.625*3)*'① 자동화 가정'!F6+(J26*'① 자동화 가정'!C17*'① 자동화 가정'!C16*80+J26*(1-'① 자동화 가정'!C17)*'① 자동화 가정'!C16*0.375*20+J26*(1-'① 자동화 가정'!C17)*'① 자동화 가정'!C16*0.625*3)*'① 자동화 가정'!C12*'① 자동화 가정'!F7+(J26*'① 자동화 가정'!C17*'① 자동화 가정'!C16*80+J26*(1-'① 자동화 가정'!C17)*'① 자동화 가정'!C16*0.375*20+J26*(1-'① 자동화 가정'!C17)*'① 자동화 가정'!C16*0.625*3)*'① 자동화 가정'!C13*'① 자동화 가정'!F8) -> 2266.7588 | K27: =((K26*'① 자동화 가정'!C17*'① 자동화 가정'!C16*80+K26*(1-'① 자동화 가정'!C17)*'① 자동화 가정'!C16*0.375*20+K26*(1-'① 자동화 가정'!C17)*'① 자동화 가정'!C16*0.625*3)*'① 자동화 가정'!F6+(K26*'① 자동화 가정'!C17*'① 자동화 가정'!C16*80+K26*(1-'① 자동화 가정'!C17)*'① 자동화 가정'!C16*0.375*20+K26*(1-'① 자동화 가정'!C17)*'① 자동화 가정'!C16*0.625*3)*'① 자동화 가정'!C12*'① 자동화 가정'!F7+(K26*'① 자동화 가정'!C17*'① 자동화 가정'!C16*80+K26*(1-'① 자동화 가정'!C17)*'① 자동화 가정'!C16*0.375*20+K26*(1-'① 자동화 가정'!C17)*'① 자동화 가정'!C16*0.625*3)*'① 자동화 가정'!C13*'① 자동화 가정'!F8) -> 2538.7699 | L27: =((L26*'① 자동화 가정'!C17*'① 자동화 가정'!C16*80+L26*(1-'① 자동화 가정'!C17)*'① 자동화 가정'!C16*0.375*20+L26*(1-'① 자동화 가정'!C17)*'① 자동화 가정'!C16*0.625*3)*'① 자동화 가정'!F6+(L26*'① 자동화 가정'!C17*'① 자동화 가정'!C16*80+L26*(1-'① 자동화 가정'!C17)*'① 자동화 가정'!C16*0.375*20+L26*(1-'① 자동화 가정'!C17)*'① 자동화 가정'!C16*0.625*3)*'① 자동화 가정'!C12*'① 자동화 가정'!F7+(L26*'① 자동화 가정'!C17*'① 자동화 가정'!C16*80+L26*(1-'① 자동화 가정'!C17)*'① 자동화 가정'!C16*0.375*20+L26*(1-'① 자동화 가정'!C17)*'① 자동화 가정'!C16*0.625*3)*'① 자동화 가정'!C13*'① 자동화 가정'!F8) -> 2810.7809 | M27: =((M26*'① 자동화 가정'!C17*'① 자동화 가정'!C16*80+M26*(1-'① 자동화 가정'!C17)*'① 자동화 가정'!C16*0.375*20+M26*(1-'① 자동화 가정'!C17)*'① 자동화 가정'!C16*0.625*3)*'① 자동화 가정'!F6+(M26*'① 자동화 가정'!C17*'① 자동화 가정'!C16*80+M26*(1-'① 자동화 가정'!C17)*'① 자동화 가정'!C16*0.375*20+M26*(1-'① 자동화 가정'!C17)*'① 자동화 가정'!C16*0.625*3)*'① 자동화 가정'!C12*'① 자동화 가정'!F7+(M26*'① 자동화 가정'!C17*'① 자동화 가정'!C16*80+M26*(1-'① 자동화 가정'!C17)*'① 자동화 가정'!C16*0.375*20+M26*(1-'① 자동화 가정'!C17)*'① 자동화 가정'!C16*0.625*3)*'① 자동화 가정'!C13*'① 자동화 가정'!F8) -> 3082.792 | N27: =((N26*'① 자동화 가정'!C17*'① 자동화 가정'!C16*80+N26*(1-'① 자동화 가정'!C17)*'① 자동화 가정'!C16*0.375*20+N26*(1-'① 자동화 가정'!C17)*'① 자동화 가정'!C16*0.625*3)*'① 자동화 가정'!F6+(N26*'① 자동화 가정'!C17*'① 자동화 가정'!C16*80+N26*(1-'① 자동화 가정'!C17)*'① 자동화 가정'!C16*0.375*20+N26*(1-'① 자동화 가정'!C17)*'① 자동화 가정'!C16*0.625*3)*'① 자동화 가정'!C12*'① 자동화 가정'!F7+(N26*'① 자동화 가정'!C17*'① 자동화 가정'!C16*80+N26*(1-'① 자동화 가정'!C17)*'① 자동화 가정'!C16*0.375*20+N26*(1-'① 자동화 가정'!C17)*'① 자동화 가정'!C16*0.625*3)*'① 자동화 가정'!C13*'① 자동화 가정'!F8) -> 3354.8031 | O27: =SUM(C27:N27) -> 22304.907
B28: 🇨🇱 칠레 수익(₩) | C28: =C27*'① 자동화 가정'!C18 -> 507753.98 | D28: =D27*'① 자동화 가정'!C18 -> 888569.46 | E28: =E27*'① 자동화 가정'!C18 -> 1269384.9 | F28: =F27*'① 자동화 가정'!C18 -> 1650200.4 | G28: =G27*'① 자동화 가정'!C18 -> 2031015.9 | H28: =H27*'① 자동화 가정'!C18 -> 2411831.4 | I28: =I27*'① 자동화 가정'!C18 -> 2792646.9 | J28: =J27*'① 자동화 가정'!C18 -> 3173462.4 | K28: =K27*'① 자동화 가정'!C18 -> 3554277.8 | L28: =L27*'① 자동화 가정'!C18 -> 3935093.3 | M28: =M27*'① 자동화 가정'!C18 -> 4315908.8 | N28: =N27*'① 자동화 가정'!C18 -> 4696724.3 | O28: =N27*'① 자동화 가정'!C18 -> 4696724.3
B30: 🇵🇹 포르투갈 파트너(명) | C30: =ROUND('① 자동화 가정'!E30+'① 자동화 가정'!F30,0) -> 4 | D30: =ROUND(C30*(1+'① 자동화 가정'!C14/12-'① 자동화 가정'!C15/12)+'① 자동화 가정'!F30,0) -> 7 | E30: =ROUND(D30*(1+'① 자동화 가정'!C14/12-'① 자동화 가정'!C15/12)+'① 자동화 가정'!F30,0) -> 10 | F30: =ROUND(E30*(1+'① 자동화 가정'!C14/12-'① 자동화 가정'!C15/12)+'① 자동화 가정'!F30,0) -> 13 | G30: =ROUND(F30*(1+'① 자동화 가정'!C14/12-'① 자동화 가정'!C15/12)+'① 자동화 가정'!F30,0) -> 16 | H30: =ROUND(G30*(1+'① 자동화 가정'!C14/12-'① 자동화 가정'!C15/12)+'① 자동화 가정'!F30,0) -> 19 | I30: =ROUND(H30*(1+'① 자동화 가정'!C14/12-'① 자동화 가정'!C15/12)+'① 자동화 가정'!F30,0) -> 22 | J30: =ROUND(I30*(1+'① 자동화 가정'!C14/12-'① 자동화 가정'!C15/12)+'① 자동화 가정'!F30,0) -> 25 | K30: =ROUND(J30*(1+'① 자동화 가정'!C14/12-'① 자동화 가정'!C15/12)+'① 자동화 가정'!F30,0) -> 28 | L30: =ROUND(K30*(1+'① 자동화 가정'!C14/12-'① 자동화 가정'!C15/12)+'① 자동화 가정'!F30,0) -> 31 | M30: =ROUND(L30*(1+'① 자동화 가정'!C14/12-'① 자동화 가정'!C15/12)+'① 자동화 가정'!F30,0) -> 34 | N30: =ROUND(M30*(1+'① 자동화 가정'!C14/12-'① 자동화 가정'!C15/12)+'① 자동화 가정'!F30,0) -> 37 | O30: =N30 -> 37
B31: 🇵🇹 포르투갈 수익($) | C31: =((C30*'① 자동화 가정'!C17*'① 자동화 가정'!C16*80+C30*(1-'① 자동화 가정'!C17)*'① 자동화 가정'!C16*0.375*20+C30*(1-'① 자동화 가정'!C17)*'① 자동화 가정'!C16*0.625*3)*'① 자동화 가정'!F6+(C30*'① 자동화 가정'!C17*'① 자동화 가정'!C16*80+C30*(1-'① 자동화 가정'!C17)*'① 자동화 가정'!C16*0.375*20+C30*(1-'① 자동화 가정'!C17)*'① 자동화 가정'!C16*0.625*3)*'① 자동화 가정'!C12*'① 자동화 가정'!F7+(C30*'① 자동화 가정'!C17*'① 자동화 가정'!C16*80+C30*(1-'① 자동화 가정'!C17)*'① 자동화 가정'!C16*0.375*20+C30*(1-'① 자동화 가정'!C17)*'① 자동화 가정'!C16*0.625*3)*'① 자동화 가정'!C13*'① 자동화 가정'!F8) -> 362.68141 | D31: =((D30*'① 자동화 가정'!C17*'① 자동화 가정'!C16*80+D30*(1-'① 자동화 가정'!C17)*'① 자동화 가정'!C16*0.375*20+D30*(1-'① 자동화 가정'!C17)*'① 자동화 가정'!C16*0.625*3)*'① 자동화 가정'!F6+(D30*'① 자동화 가정'!C17*'① 자동화 가정'!C16*80+D30*(1-'① 자동화 가정'!C17)*'① 자동화 가정'!C16*0.375*20+D30*(1-'① 자동화 가정'!C17)*'① 자동화 가정'!C16*0.625*3)*'① 자동화 가정'!C12*'① 자동화 가정'!F7+(D30*'① 자동화 가정'!C17*'① 자동화 가정'!C16*80+D30*(1-'① 자동화 가정'!C17)*'① 자동화 가정'!C16*0.375*20+D30*(1-'① 자동화 가정'!C17)*'① 자동화 가정'!C16*0.625*3)*'① 자동화 가정'!C13*'① 자동화 가정'!F8) -> 634.69247 | E31: =((E30*'① 자동화 가정'!C17*'① 자동화 가정'!C16*80+E30*(1-'① 자동화 가정'!C17)*'① 자동화 가정'!C16*0.375*20+E30*(1-'① 자동화 가정'!C17)*'① 자동화 가정'!C16*0.625*3)*'① 자동화 가정'!F6+(E30*'① 자동화 가정'!C17*'① 자동화 가정'!C16*80+E30*(1-'① 자동화 가정'!C17)*'① 자동화 가정'!C16*0.375*20+E30*(1-'① 자동화 가정'!C17)*'① 자동화 가정'!C16*0.625*3)*'① 자동화 가정'!C12*'① 자동화 가정'!F7+(E30*'① 자동화 가정'!C17*'① 자동화 가정'!C16*80+E30*(1-'① 자동화 가정'!C17)*'① 자동화 가정'!C16*0.375*20+E30*(1-'① 자동화 가정'!C17)*'① 자동화 가정'!C16*0.625*3)*'① 자동화 가정'!C13*'① 자동화 가정'!F8) -> 906.70353 | F31: =((F30*'① 자동화 가정'!C17*'① 자동화 가정'!C16*80+F30*(1-'① 자동화 가정'!C17)*'① 자동화 가정'!C16*0.375*20+F30*(1-'① 자동화 가정'!C17)*'① 자동화 가정'!C16*0.625*3)*'① 자동화 가정'!F6+(F30*'① 자동화 가정'!C17*'① 자동화 가정'!C16*80+F30*(1-'① 자동화 가정'!C17)*'① 자동화 가정'!C16*0.375*20+F30*(1-'① 자동화 가정'!C17)*'① 자동화 가정'!C16*0.625*3)*'① 자동화 가정'!C12*'① 자동화 가정'!F7+(F30*'① 자동화 가정'!C17*'① 자동화 가정'!C16*80+F30*(1-'① 자동화 가정'!C17)*'① 자동화 가정'!C16*0.375*20+F30*(1-'① 자동화 가정'!C17)*'① 자동화 가정'!C16*0.625*3)*'① 자동화 가정'!C13*'① 자동화 가정'!F8) -> 1178.7146 | G31: =((G30*'① 자동화 가정'!C17*'① 자동화 가정'!C16*80+G30*(1-'① 자동화 가정'!C17)*'① 자동화 가정'!C16*0.375*20+G30*(1-'① 자동화 가정'!C17)*'① 자동화 가정'!C16*0.625*3)*'① 자동화 가정'!F6+(G30*'① 자동화 가정'!C17*'① 자동화 가정'!C16*80+G30*(1-'① 자동화 가정'!C17)*'① 자동화 가정'!C16*0.375*20+G30*(1-'① 자동화 가정'!C17)*'① 자동화 가정'!C16*0.625*3)*'① 자동화 가정'!C12*'① 자동화 가정'!F7+(G30*'① 자동화 가정'!C17*'① 자동화 가정'!C16*80+G30*(1-'① 자동화 가정'!C17)*'① 자동화 가정'!C16*0.375*20+G30*(1-'① 자동화 가정'!C17)*'① 자동화 가정'!C16*0.625*3)*'① 자동화 가정'!C13*'① 자동화 가정'!F8) -> 1450.7257 | H31: =((H30*'① 자동화 가정'!C17*'① 자동화 가정'!C16*80+H30*(1-'① 자동화 가정'!C17)*'① 자동화 가정'!C16*0.375*20+H30*(1-'① 자동화 가정'!C17)*'① 자동화 가정'!C16*0.625*3)*'① 자동화 가정'!F6+(H30*'① 자동화 가정'!C17*'① 자동화 가정'!C16*80+H30*(1-'① 자동화 가정'!C17)*'① 자동화 가정'!C16*0.375*20+H30*(1-'① 자동화 가정'!C17)*'① 자동화 가정'!C16*0.625*3)*'① 자동화 가정'!C12*'① 자동화 가정'!F7+(H30*'① 자동화 가정'!C17*'① 자동화 가정'!C16*80+H30*(1-'① 자동화 가정'!C17)*'① 자동화 가정'!C16*0.375*20+H30*(1-'① 자동화 가정'!C17)*'① 자동화 가정'!C16*0.625*3)*'① 자동화 가정'!C13*'① 자동화 가정'!F8) -> 1722.7367 | I31: =((I30*'① 자동화 가정'!C17*'① 자동화 가정'!C16*80+I30*(1-'① 자동화 가정'!C17)*'① 자동화 가정'!C16*0.375*20+I30*(1-'① 자동화 가정'!C17)*'① 자동화 가정'!C16*0.625*3)*'① 자동화 가정'!F6+(I30*'① 자동화 가정'!C17*'① 자동화 가정'!C16*80+I30*(1-'① 자동화 가정'!C17)*'① 자동화 가정'!C16*0.375*20+I30*(1-'① 자동화 가정'!C17)*'① 자동화 가정'!C16*0.625*3)*'① 자동화 가정'!C12*'① 자동화 가정'!F7+(I30*'① 자동화 가정'!C17*'① 자동화 가정'!C16*80+I30*(1-'① 자동화 가정'!C17)*'① 자동화 가정'!C16*0.375*20+I30*(1-'① 자동화 가정'!C17)*'① 자동화 가정'!C16*0.625*3)*'① 자동화 가정'!C13*'① 자동화 가정'!F8) -> 1994.7478 | J31: =((J30*'① 자동화 가정'!C17*'① 자동화 가정'!C16*80+J30*(1-'① 자동화 가정'!C17)*'① 자동화 가정'!C16*0.375*20+J30*(1-'① 자동화 가정'!C17)*'① 자동화 가정'!C16*0.625*3)*'① 자동화 가정'!F6+(J30*'① 자동화 가정'!C17*'① 자동화 가정'!C16*80+J30*(1-'① 자동화 가정'!C17)*'① 자동화 가정'!C16*0.375*20+J30*(1-'① 자동화 가정'!C17)*'① 자동화 가정'!C16*0.625*3)*'① 자동화 가정'!C12*'① 자동화 가정'!F7+(J30*'① 자동화 가정'!C17*'① 자동화 가정'!C16*80+J30*(1-'① 자동화 가정'!C17)*'① 자동화 가정'!C16*0.375*20+J30*(1-'① 자동화 가정'!C17)*'① 자동화 가정'!C16*0.625*3)*'① 자동화 가정'!C13*'① 자동화 가정'!F8) -> 2266.7588 | K31: =((K30*'① 자동화 가정'!C17*'① 자동화 가정'!C16*80+K30*(1-'① 자동화 가정'!C17)*'① 자동화 가정'!C16*0.375*20+K30*(1-'① 자동화 가정'!C17)*'① 자동화 가정'!C16*0.625*3)*'① 자동화 가정'!F6+(K30*'① 자동화 가정'!C17*'① 자동화 가정'!C16*80+K30*(1-'① 자동화 가정'!C17)*'① 자동화 가정'!C16*0.375*20+K30*(1-'① 자동화 가정'!C17)*'① 자동화 가정'!C16*0.625*3)*'① 자동화 가정'!C12*'① 자동화 가정'!F7+(K30*'① 자동화 가정'!C17*'① 자동화 가정'!C16*80+K30*(1-'① 자동화 가정'!C17)*'① 자동화 가정'!C16*0.375*20+K30*(1-'① 자동화 가정'!C17)*'① 자동화 가정'!C16*0.625*3)*'① 자동화 가정'!C13*'① 자동화 가정'!F8) -> 2538.7699 | L31: =((L30*'① 자동화 가정'!C17*'① 자동화 가정'!C16*80+L30*(1-'① 자동화 가정'!C17)*'① 자동화 가정'!C16*0.375*20+L30*(1-'① 자동화 가정'!C17)*'① 자동화 가정'!C16*0.625*3)*'① 자동화 가정'!F6+(L30*'① 자동화 가정'!C17*'① 자동화 가정'!C16*80+L30*(1-'① 자동화 가정'!C17)*'① 자동화 가정'!C16*0.375*20+L30*(1-'① 자동화 가정'!C17)*'① 자동화 가정'!C16*0.625*3)*'① 자동화 가정'!C12*'① 자동화 가정'!F7+(L30*'① 자동화 가정'!C17*'① 자동화 가정'!C16*80+L30*(1-'① 자동화 가정'!C17)*'① 자동화 가정'!C16*0.375*20+L30*(1-'① 자동화 가정'!C17)*'① 자동화 가정'!C16*0.625*3)*'① 자동화 가정'!C13*'① 자동화 가정'!F8) -> 2810.7809 | M31: =((M30*'① 자동화 가정'!C17*'① 자동화 가정'!C16*80+M30*(1-'① 자동화 가정'!C17)*'① 자동화 가정'!C16*0.375*20+M30*(1-'① 자동화 가정'!C17)*'① 자동화 가정'!C16*0.625*3)*'① 자동화 가정'!F6+(M30*'① 자동화 가정'!C17*'① 자동화 가정'!C16*80+M30*(1-'① 자동화 가정'!C17)*'① 자동화 가정'!C16*0.375*20+M30*(1-'① 자동화 가정'!C17)*'① 자동화 가정'!C16*0.625*3)*'① 자동화 가정'!C12*'① 자동화 가정'!F7+(M30*'① 자동화 가정'!C17*'① 자동화 가정'!C16*80+M30*(1-'① 자동화 가정'!C17)*'① 자동화 가정'!C16*0.375*20+M30*(1-'① 자동화 가정'!C17)*'① 자동화 가정'!C16*0.625*3)*'① 자동화 가정'!C13*'① 자동화 가정'!F8) -> 3082.792 | N31: =((N30*'① 자동화 가정'!C17*'① 자동화 가정'!C16*80+N30*(1-'① 자동화 가정'!C17)*'① 자동화 가정'!C16*0.375*20+N30*(1-'① 자동화 가정'!C17)*'① 자동화 가정'!C16*0.625*3)*'① 자동화 가정'!F6+(N30*'① 자동화 가정'!C17*'① 자동화 가정'!C16*80+N30*(1-'① 자동화 가정'!C17)*'① 자동화 가정'!C16*0.375*20+N30*(1-'① 자동화 가정'!C17)*'① 자동화 가정'!C16*0.625*3)*'① 자동화 가정'!C12*'① 자동화 가정'!F7+(N30*'① 자동화 가정'!C17*'① 자동화 가정'!C16*80+N30*(1-'① 자동화 가정'!C17)*'① 자동화 가정'!C16*0.375*20+N30*(1-'① 자동화 가정'!C17)*'① 자동화 가정'!C16*0.625*3)*'① 자동화 가정'!C13*'① 자동화 가정'!F8) -> 3354.8031 | O31: =SUM(C31:N31) -> 22304.907
B32: 🇵🇹 포르투갈 수익(₩) | C32: =C31*'① 자동화 가정'!C18 -> 507753.98 | D32: =D31*'① 자동화 가정'!C18 -> 888569.46 | E32: =E31*'① 자동화 가정'!C18 -> 1269384.9 | F32: =F31*'① 자동화 가정'!C18 -> 1650200.4 | G32: =G31*'① 자동화 가정'!C18 -> 2031015.9 | H32: =H31*'① 자동화 가정'!C18 -> 2411831.4 | I32: =I31*'① 자동화 가정'!C18 -> 2792646.9 | J32: =J31*'① 자동화 가정'!C18 -> 3173462.4 | K32: =K31*'① 자동화 가정'!C18 -> 3554277.8 | L32: =L31*'① 자동화 가정'!C18 -> 3935093.3 | M32: =M31*'① 자동화 가정'!C18 -> 4315908.8 | N32: =N31*'① 자동화 가정'!C18 -> 4696724.3 | O32: =N31*'① 자동화 가정'!C18 -> 4696724.3
B34: 🏆 전체 국가 합산
B35: 항목 | C35: 1월 | D35: 2월 | E35: 3월 | F35: 4월 | G35: 5월 | H35: 6월 | I35: 7월 | J35: 8월 | K35: 9월 | L35: 10월 | M35: 11월 | N35: 12월 | O35: 연간합계
B36: 💰 전체 월수익(₩) | C36: =C8+C12+C16+C20+C24+C28+C32 -> 8885694.6 | D36: =D8+D12+D16+D20+D24+D28+D32 -> 15867312 | E36: =E8+E12+E16+E20+E24+E28+E32 -> 22848929 | F36: =F8+F12+F16+F20+F24+F28+F32 -> 29830546 | G36: =G8+G12+G16+G20+G24+G28+G32 -> 36812163 | H36: =H8+H12+H16+H20+H24+H28+H32 -> 43793781 | I36: =I8+I12+I16+I20+I24+I28+I32 -> 50775398 | J36: =J8+J12+J16+J20+J24+J28+J32 -> 57630076 | ... N36: =N8+N12+N16+N20+N24+N28+N32 -> 84794914 | O36: =SUM(C36:N36) -> 5.6513018e+08
B37: 📊 누적 수익(₩) | C37: =C36 -> 8885694.6 | D37: =C37+D36 -> 24753006 | E37: =D37+E36 -> 47601935 | F37: =E37+F36 -> 77432482 | G37: =F37+G36 -> 1.1424464e+08 | H37: =G37+H36 -> 1.5803843e+08 | I37: =H37+I36 -> 2.0881382e+08 | J37: =I37+J36 -> 2.664439e+08 | K37: =J37+K36 -> 3.3092865e+08 | ... N37: =M37+N36 -> 5.6513018e+08 | O37: =N37 -> 5.6513018e+08

Sheet ③ 5년 연간 시뮬
B1: 🚀 5년 자동화 수익 시뮬레이션 — 복리 성장 + 파트너 생태계
B2: 연간 가격인상 5% + 전환율 개선 3% + 바이럴K 복리 | 민철 씨 개입 ≈ 0
B4: 📊 연도별 핵심 지표 요약
B5: 지표 | C5: 1년차 | D5: 2년차 | E5: 3년차 | F5: 4년차 | G5: 5년차
B6: 총 파트너 수 (연말, 명) | C6: ='② 1년차 월별 시뮬'!N6+'② 1년차 월별 시뮬'!N10+'② 1년차 월별 시뮬'!N14+'② 1년차 월별 시뮬'!N18+'② 1년차 월별 시뮬'!N22+'② 1년차 월별 시뮬'!N26+'② 1년차 월별 시뮬'!N30 -> 668 | D6: =ROUND(C6*'① 자동화 가정'!C36,0) -> 800 | E6: =ROUND(D6*'① 자동화 가정'!C37,0) -> 1024 | F6: =ROUND(E6*'① 자동화 가정'!C38,0) -> 1390 | G6: =ROUND(F6*'① 자동화 가정'!C39,0) -> 1960
B7: 월평균 오너수익 ($) | C7: ='② 1년차 월별 시뮬'!O36/'① 자동화 가정'!C18/12 -> 33638.701 | D7: =C7*'① 자동화 가정'!C36*(1+'① 자동화 가정'!C19)*(1+'① 자동화 가정'!C20) -> 43583.546 | E7: =D7*'① 자동화 가정'!C37*(1+'① 자동화 가정'!C19)*(1+'① 자동화 가정'!C20) -> 60333.574 | F7: =E7*'① 자동화 가정'!C38*(1+'① 자동화 가정'!C19)*(1+'① 자동화 가정'!C20) -> 88545.282 | G7: =F7*'① 자동화 가정'!C39*(1+'① 자동화 가정'!C19)*(1+'① 자동화 가정'!C20) -> 135024.03
B8: 연간 오너수익 (₩) | C8: ='② 1년차 월별 시뮬'!O36 -> 5.6513018e+08 | D8: =C8*'① 자동화 가정'!C36*(1+'① 자동화 가정'!C19)*(1+'① 자동화 가정'!C20) -> 7.3220357e+08 | E8: =D8*'① 자동화 가정'!C37*(1+'① 자동화 가정'!C19)*(1+'① 자동화 가정'!C20) -> 1.013604e+09 | F8: =E8*'① 자동화 가정'!C38*(1+'① 자동화 가정'!C19)*(1+'① 자동화 가정'!C20) -> 1.4875607e+09 | G8: =F8*'① 자동화 가정'!C39*(1+'① 자동화 가정'!C19)*(1+'① 자동화 가정'!C20) -> 2.2684037e+09
B9: 누적 오너수익 (₩, 5년) | C9: =C8 -> 5.6513018e+08 | D9: =C9+D8 -> 1.2973337e+09 | E9: =D9+E8 -> 2.3109378e+09 | F9: =E9+F8 -> 3.7984985e+09 | G9: =F9+G8 -> 6.0669022e+09
B10: 월평균 오너수익 (₩) | C10: =C8/12 -> 47094181 | D10: =D8/12 -> 61016964 | E10: =E8/12 -> 84467004 | F10: =F8/12 -> 1.2396339e+08 | G10: =G8/12 -> 1.8903364e+08
B11: 파트너 1인당 월수익 (₩) | C11: =IF(C6>0,C10/C6,0) -> 70500.272 | D11: =IF(D6>0,D10/D6,0) -> 76271.205 | E11: =IF(E6>0,E10/E6,0) -> 82487.308 | F11: =IF(F6>0,F10/F6,0) -> 89182.298 | G11: =IF(G6>0,G10/G6,0) -> 96445.734
B12: T1 번들가 ($, 가격인상 반영) | C12: ='① 자동화 가정'!C6 -> 12.8 | D12: =C12*(1+'① 자동화 가정'!C19) -> 13.44 | E12: =D12*(1+'① 자동화 가정'!C19) -> 14.112 | F12: =E12*(1+'① 자동화 가정'!C19) -> 14.8176 | G12: =F12*(1+'① 자동화 가정'!C19) -> 15.55848
B13: T2 OTO 전환율 (개선 반영) | C13: ='① 자동화 가정'!C12 -> 0.24 | D13: =MIN(C13*(1+'① 자동화 가정'!C20),0.45) -> 0.2472 | E13: =MIN(D13*(1+'① 자동화 가정'!C20),0.45) -> 0.254616 | F13: =MIN(E13*(1+'① 자동화 가정'!C20),0.45) -> 0.26225448 | G13: =MIN(F13*(1+'① 자동화 가정'!C20),0.45) -> 0.27012211
B15: 🎯 5년 수익 시나리오 비교 (파트너 모집 속도별)
B16: 시나리오 | C16: 월추가파트너 | D16: 1년차 연간 | E16: 2년차 연간 | F16: 3년차 연간 | G16: 4년차 연간 | H16: 5년차 연간 | I16: 5년 누적
B17: 🐢 보수적 | C17: 0.5 | D17: =C17*'① 자동화 가정'!C36*(1+'① 자동화 가정'!C19)*(1+'① 자동화 가정'!C20) -> 0.6478185 | E17: =D17*'① 자동화 가정'!C37*(1+'① 자동화 가정'!C19)*(1+'① 자동화 가정'!C20) -> 0.89678811 | F17: =E17*'① 자동화 가정'!C38*(1+'① 자동화 가정'!C19)*(1+'① 자동화 가정'!C20) -> 1.3161222 | G17: =F17*'① 자동화 가정'!C39*(1+'① 자동화 가정'!C19)*(1+'① 자동화 가정'!C20) -> 2.0069745 | I17: =SUM(D17:H17) -> 4.8677033
B18: 🚀 기본(현재) | C18: 1 | D18: =C18*'① 자동화 가정'!C36*(1+'① 자동화 가정'!C19)*(1+'① 자동화 가정'!C20) -> 1.295637 | E18: =D18*'① 자동화 가정'!C37*(1+'① 자동화 가정'!C19)*(1+'① 자동화 가정'!C20) -> 1.7935762 | F18: =E18*'① 자동화 가정'!C38*(1+'① 자동화 가정'!C19)*(1+'① 자동화 가정'!C20) -> 2.6322444 | G18: =F18*'① 자동화 가정'!C39*(1+'① 자동화 가정'!C19)*(1+'① 자동화 가정'!C20) -> 4.0139489 | I18: =SUM(D18:H18) -> 9.7354065
B19: 💥 공격적 | C19: 2 | D19: =C19*'① 자동화 가정'!C36*(1+'① 자동화 가정'!C19)*(1+'① 자동화 가정'!C20) -> 2.591274 | E19: =D19*'① 자동화 가정'!C37*(1+'① 자동화 가정'!C19)*(1+'① 자동화 가정'!C20) -> 3.5871524 | F19: =E19*'① 자동화 가정'!C38*(1+'① 자동화 가정'!C19)*(1+'① 자동화 가정'!C20) -> 5.2644888 | G19: =F19*'① 자동화 가정'!C39*(1+'① 자동화 가정'!C19)*(1+'① 자동화 가정'!C20) -> 8.0278979 | I19: =SUM(D19:H19) -> 19.470813
B20: 🌋 폭발적 | C20: 3 | D20: =C20*'① 자동화 가정'!C36*(1+'① 자동화 가정'!C19)*(1+'① 자동화 가정'!C20) -> 3.886911 | E20: =D20*'① 자동화 가정'!C37*(1+'① 자동화 가정'!C19)*(1+'① 자동화 가정'!C20) -> 5.3807286 | F20: =E20*'① 자동화 가정'!C38*(1+'① 자동화 가정'!C19)*(1+'① 자동화 가정'!C20) -> 7.8967331 | G20: =F20*'① 자동화 가정'!C39*(1+'① 자동화 가정'!C19)*(1+'① 자동화 가정'!C20) -> 12.041847 | I20: =SUM(D20:H20) -> 29.20622
B22: 🤖 자동화 수익원 분해 — 민철 씨 시간투자 대비 수익
B23: 수익원 | C23: 자동화 방식 | D23: 민철씨 개입 | E23: 1년차 기여율 | F23: 성장성
