Workbook

Sheet ① 시장 인텔리전스
B1: 🌎 Shadowgram 국가별 시장 인텔리전스 — Hotmart 인지도 기반 파트너 잠재력
B2: Source: Hotmart Press, World Bank, GSMA, PCMI 2024 | 스페인어 4개국 + 포르투갈어 3개국
B4: 국가 | C4: 언어 | D4: Hotmart 인지도 | E4: 디지털상품 시장규모($M) | F4: 월평균 소득($) | G4: 인터넷 보급률 | H4: 모바일 결제율 | I4: Hotmart 사무소 | J4: 파트너 잠재력지수 | K4: 권장 초기 파트너수(명) | L4: 권장 1년후 파트너수(명)
B5: 🇧🇷 브라질 | C5: 포르투갈어 | D5: ★★★★★ | E5: 7400 | F5: 449 | G5: 0.85 | H5: 0.84 | I5: ✅ 보유 | J5: =(5/5)*35+MIN(E5/7400,1)*25+(F5/2100)*20+G5*10+H5*10 -> 81.17619 | K5: =ROUND(MAX(20,MIN(200,J5*2)),0) -> 162 | L5: =ROUND(MAX(50,MIN(500,J5*5)),0) -> 406 | M5: 홈마켓 창업국. 26M 유저, 전체 거래의 60%+
B6: 🇲🇽 멕시코 | C6: 스페인어 | D6: ★★★★☆ | E6: 3200 | F6: 525 | G6: 0.85 | H6: 0.53 | I6: ✅ 보유 | J6: =(4/5)*35+MIN(E6/7400,1)*25+(F6/2100)*20+G6*10+H6*10 -> 57.610811 | K6: =ROUND(MAX(20,MIN(200,J6*2)),0) -> 115 | L6: =ROUND(MAX(50,MIN(500,J6*5)),0) -> 288 | M6: 2위 시장. LATAM GMV 50% 성장 견인
B7: 🇨🇴 콜롬비아 | C7: 스페인어 | D7: ★★★★☆ | E7: 450 | F7: 480 | G7: 0.82 | H7: 0.4 | I7: ✅ 보유 | J7: =(4/5)*35+MIN(E7/7400,1)*25+(F7/2100)*20+G7*10+H7*10 -> 46.291699 | K7: =ROUND(MAX(20,MIN(200,J7*2)),0) -> 93 | L7: =ROUND(MAX(50,MIN(500,J7*5)),0) -> 231 | M7: 24.2% YoY 성장. 오피스 보유
B8: 🇺🇸 미국 히스패닉 | C8: 스페인어 | D8: ★★★☆☆ | E8: 2400 | F8: 2100 | G8: 0.95 | H8: 0.72 | I8: ✅ 보유 | J8: =(3/5)*35+MIN(E8/7400,1)*25+(F8/2100)*20+G8*10+H8*10 -> 65.808108 | K8: =ROUND(MAX(20,MIN(200,J8*2)),0) -> 132 | L8: =ROUND(MAX(50,MIN(500,J8*5)),0) -> 329 | M8: $2.4T 구매력. 소득 최고. 오피스 보유
B9: 🇦🇷 아르헨티나 | C9: 스페인어 | D9: ★★★☆☆ | E9: 198 | F9: 570 | G9: 0.9 | H9: 0.45 | I9: — | J9: =(3/5)*35+MIN(E9/7400,1)*25+(F9/2100)*20+G9*10+H9*10 -> 40.59749 | K9: =ROUND(MAX(20,MIN(200,J9*2)),0) -> 81 | L9: =ROUND(MAX(50,MIN(500,J9*5)),0) -> 203 | M9: 인플레이션 고려, 달러 수익 선호도 높음
B10: 🇨🇱 칠레 | C10: 스페인어 | D10: ★★★☆☆ | E10: 85 | F10: 691 | G10: 0.94 | H10: 0.55 | I10: — | J10: =(3/5)*35+MIN(E10/7400,1)*25+(F10/2100)*20+G10*10+H10*10 -> 42.768115 | K10: =ROUND(MAX(20,MIN(200,J10*2)),0) -> 86 | L10: =ROUND(MAX(50,MIN(500,J10*5)),0) -> 214 | M10: 인터넷 보급 최고(94%). 소득 지역 1위
B11: 🇵🇹 포르투갈 | C11: 포르투갈어 | D11: ★★☆☆☆ | E11: 61 | F11: 1200 | G11: 0.92 | H11: 0.65 | I11: — | J11: =(2/5)*35+MIN(E11/7400,1)*25+(F11/2100)*20+G11*10+H11*10 -> 41.334653 | K11: =ROUND(MAX(20,MIN(200,J11*2)),0) -> 83 | L11: =ROUND(MAX(50,MIN(500,J11*5)),0) -> 207 | M11: 유럽 포르투갈어 시장. 브라질 콘텐츠 소비
B12: 📊 전체 합계 | K12: =SUM(K5:K11) -> 752 | L12: =SUM(L5:L11) -> 1878
B14: 📊 Hotmart 플랫폼 핵심 통계 (2024 공식 발표)
B15: 지표 | C15: 수치 | D15: 비고
B16: 총 등록 유저 | C16: 2,600만명 | D16: 2024년 공식 발표
B17: 누적 크리에이터 수익 | C17: $100억 (GMV) | D17: 2024년 3월 기록 돌파
B18: 등록 상품 수 | C18: 370,000+개 | D18: 콘텐츠, 코스, 소프트웨어
B19: 판매 국가 수 | C19: 185개국 | D19: 사실상 전세계
B20: LATAM GMV 성장 (ex-Brazil) | C20: +50% YoY | D20: 2022→2023
B21: 제휴 파트너 (추정) | C21: 53,154명+ | D21: AffiliateDB 기준
B22: 브라질 시장 점유 | C22: 25%+ (LATAM e-learning) | D22: 지역 1위 플랫폼

Sheet ② 국가별 파트너 설정
B1: 🎯 국가별 파트너 수 직접 설정 — 수익 자동 계산
B2: 파란 셀 숫자만 바꾸면 전체 수익 자동 연동 | 파레토 법칙 국가별 적용
B4: 💰 번들 오너 단가 (Hotmart 9.9% 수수료 차감 후)
B5: 번들 | C5: 판매가($) | D5: 커미션율 | E5: 오너단가($) | F5: 오너단가(₩)
B6: T1+AppA | C6: 12.8 | D6: 0.7 | E6: =C6*(1-D6-0.099) -> 2.5728 | F6: =E6*C13 -> 3601.92
B7: T2+AppB | C7: 19.9 | D7: 0.5 | E7: =C7*(1-D7-0.099) -> 7.9799 | F7: =E7*C13 -> 11171.86
B8: T3+AppC | C8: 28.9 | D8: 0.4 | E8: =C8*(1-D8-0.099) -> 14.4789 | F8: =E8*C13 -> 20270.46
B9: ⚙️ 공통 가정
B10: 항목 | C10: 값 | D10: 단위
B11: T2 OTO 전환율 | C11: 0.24
B12: T3 이메일 전환율 | C12: 0.1
B13: 환율 (원/달러) | C13: 1400 | D13: 원
B14: 파레토 상위 비율 | C14: 0.2
B15: 상위 파트너 월판매(T1) | C15: 80 | D15: 건/명
B16: 중간 파트너 월판매(T1) | C16: 20 | D16: 건/명
B17: 하위 파트너 월판매(T1) | C17: 3 | D17: 건/명
B19: 🌍 국가별 파트너 수 설정 — 파란 셀에 원하는 수 직접 입력
B20: 국가 | C20: 언어 | D20: Hotmart 인지도 | E20: 설정 파트너수(명) | F20: 상위 파트너(명) | G20: 중간 파트너(명) | H20: 하위 파트너(명) | I20: 월T1판매 총건수 | J20: 월오너 수익($) | K20: 월오너 수익(₩) | L20: 전체대비 비중(%) | M20: 파트너1인당 월평균수익(₩)
B21: 🇧🇷 브라질 | C21: 포르투갈어 | D21: ★★★★★ | E21: 200 | F21: =ROUND(E21*$C$14,0) -> 40 | G21: =ROUND(E21*0.3,0) -> 60 | H21: =E21-F21-G21 -> 100 | I21: =F21*$C$15+G21*$C$16+H21*$C$17 -> 4700 | J21: =(F21*$C$15+G21*$C$16+H21*$C$17)*$E$6+(F21*$C$15+G21*$C$16+H21*$C$17)*$C$11*$E$7+(F21*$C$15+G21*$C$16+H21*$C$17)*$C$12*$E$8 -> 27898.57 | K21: =J21*$C$13 -> 39057998 | L21: =J21/J$28 -> 0.30769231 | M21: =IF(E21>0,K21/E21,0) -> 195289.99
B22: 🇲🇽 멕시코 | C22: 스페인어 | D22: ★★★★☆ | E22: 150 | F22: =ROUND(E22*$C$14,0) -> 30 | G22: =ROUND(E22*0.3,0) -> 45 | H22: =E22-F22-G22 -> 75 | I22: =F22*$C$15+G22*$C$16+H22*$C$17 -> 3525 | J22: =(F22*$C$15+G22*$C$16+H22*$C$17)*$E$6+(F22*$C$15+G22*$C$16+H22*$C$17)*$C$11*$E$7+(F22*$C$15+G22*$C$16+H22*$C$17)*$C$12*$E$8 -> 20923.928 | K22: =J22*$C$13 -> 29293499 | L22: =J22/J$28 -> 0.23076923 | M22: =IF(E22>0,K22/E22,0) -> 195289.99
B23: 🇨🇴 콜롬비아 | C23: 스페인어 | D23: ★★★★☆ | E23: 80 | F23: =ROUND(E23*$C$14,0) -> 16 | G23: =ROUND(E23*0.3,0) -> 24 | H23: =E23-F23-G23 -> 40 | I23: =F23*$C$15+G23*$C$16+H23*$C$17 -> 1880 | J23: =(F23*$C$15+G23*$C$16+H23*$C$17)*$E$6+(F23*$C$15+G23*$C$16+H23*$C$17)*$C$11*$E$7+(F23*$C$15+G23*$C$16+H23*$C$17)*$C$12*$E$8 -> 11159.428 | K23: =J23*$C$13 -> 15623199 | L23: =J23/J$28 -> 0.12307692 | M23: =IF(E23>0,K23/E23,0) -> 195289.99
B24: 🇺🇸 미국 히스패닉 | C24: 스페인어 | D24: ★★★☆☆ | E24: 100 | F24: =ROUND(E24*$C$14,0) -> 20 | G24: =ROUND(E24*0.3,0) -> 30 | H24: =E24-F24-G24 -> 50 | I24: =F24*$C$15+G24*$C$16+H24*$C$17 -> 2350 | J24: =(F24*$C$15+G24*$C$16+H24*$C$17)*$E$6+(F24*$C$15+G24*$C$16+H24*$C$17)*$C$11*$E$7+(F24*$C$15+G24*$C$16+H24*$C$17)*$C$12*$E$8 -> 13949.285 | K24: =J24*$C$13 -> 19528999 | L24: =J24/J$28 -> 0.15384615 | M24: =IF(E24>0,K24/E24,0) -> 195289.99
B25: 🇦🇷 아르헨티나 | C25: 스페인어 | D25: ★★★☆☆ | E25: 50 | F25: =ROUND(E25*$C$14,0) -> 10 | G25: =ROUND(E25*0.3,0) -> 15 | H25: =E25-F25-G25 -> 25 | I25: =F25*$C$15+G25*$C$16+H25*$C$17 -> 1175 | J25: =(F25*$C$15+G25*$C$16+H25*$C$17)*$E$6+(F25*$C$15+G25*$C$16+H25*$C$17)*$C$11*$E$7+(F25*$C$15+G25*$C$16+H25*$C$17)*$C$12*$E$8 -> 6974.6425 | K25: =J25*$C$13 -> 9764499.6 | L25: =J25/J$28 -> 0.076923077 | M25: =IF(E25>0,K25/E25,0) -> 195289.99
B26: 🇨🇱 칠레 | C26: 스페인어 | D26: ★★★☆☆ | E26: 40 | F26: =ROUND(E26*$C$14,0) -> 8 | G26: =ROUND(E26*0.3,0) -> 12 | H26: =E26-F26-G26 -> 20 | I26: =F26*$C$15+G26*$C$16+H26*$C$17 -> 940 | J26: =(F26*$C$15+G26*$C$16+H26*$C$17)*$E$6+(F26*$C$15+G26*$C$16+H26*$C$17)*$C$11*$E$7+(F26*$C$15+G26*$C$16+H26*$C$17)*$C$12*$E$8 -> 5579.714 | K26: =J26*$C$13 -> 7811599.7 | L26: =J26/J$28 -> 0.061538462 | M26: =IF(E26>0,K26/E26,0) -> 195289.99
B27: 🇵🇹 포르투갈 | C27: 포르투갈어 | D27: ★★☆☆☆ | E27: 30 | F27: =ROUND(E27*$C$14,0) -> 6 | G27: =ROUND(E27*0.3,0) -> 9 | H27: =E27-F27-G27 -> 15 | I27: =F27*$C$15+G27*$C$16+H27*$C$17 -> 705 | J27: =(F27*$C$15+G27*$C$16+H27*$C$17)*$E$6+(F27*$C$15+G27*$C$16+H27*$C$17)*$C$11*$E$7+(F27*$C$15+G27*$C$16+H27*$C$17)*$C$12*$E$8 -> 4184.7855 | K27: =J27*$C$13 -> 5858699.7 | L27: =J27/J$28 -> 0.046153846 | M27: =IF(E27>0,K27/E27,0) -> 195289.99
B28: 📊 전체 합계 | E28: =SUM(E21:E27) -> 650 | F28: =SUM(F21:F27) -> 130 | G28: =SUM(G21:G27) -> 195 | H28: =SUM(H21:H27) -> 325 | I28: =SUM(I21:I27) -> 15275 | J28: =SUM(J21:J27) -> 90670.353 | K28: =SUM(K21:K27) -> 1.2693849e+08 | L28: =SUM(L21:L27) -> 1 | M28: =IF(E28>0,K28/E28,0) -> 195289.99
B30: 💡 파트너 설정 가이드라인 (Hotmart 인지도 기반)
B31: 국가 | C31: 목표 | D31: 전략 근거
B32: 🇧🇷 브라질 (★★★★★) | C32: 200명+ 목표 | D32: Hotmart 창업국. 이미 수십만 파트너 생태계 구축. 가장 쉽게 모집 가능. 포르투갈어 콘텐츠 완성 → 즉시 런칭.
B33: 🇲🇽 멕시코 (★★★★☆) | C33: 150명 목표 | D33: 커플/연애 콘텐츠 소비 LATAM 1위. Hotmart 공식 오피스 → 파트너 지원 인프라 탄탄.
B34: 🇺🇸 미국 히스패닉 (★★★☆☆) | C34: 100명 목표 | D34: 소득 $2100/월로 최고. T2/T3 전환율 더 높을 가능성. 커미션 매력 ↑
B35: 🇨🇴 콜롬비아 (★★★★☆) | C35: 80명 목표 | D35: YoY 24.2% 고성장. 오피스 보유. 가성비 최고의 성장 시장.
B36: 🇦🇷 아르헨티나 (★★★☆☆) | C36: 50명 목표 | D36: 인플레이션으로 달러 수익 선호도 극강 → 파트너 동기 높음.
B37: 🇨🇱 칠레 (★★★☆☆) | C37: 40명 목표 | D37: 인터넷 94% + 소득 1위 → 작지만 질적으로 우수한 파트너 가능.
B38: 🇵🇹 포르투갈 (★★☆☆☆) | C38: 30명 목표 | D38: 유럽 포르투갈어 시장. 브라질 콘텐츠 소비 문화 있음. 소득 높아 T3까지 전환 잘 됨.

Sheet ③ 12개월 성장 시뮬
B1: 📈 국가별 12개월 파트너 성장 시뮬레이션 — D+1개월 시작
B2: 각 국가 파트너를 매월 점진적으로 추가 | 파레토 적용 | 월수익(₩) + 누적수익(₩)
B4: ⚙️ 가정: 매월 파트너 추가 → 12월 달성 목표 (D+1개월부터 카운트)
B5: 항목 | C5: 1월 | D5: 2월 | E5: 3월 | F5: 4월 | G5: 5월 | H5: 6월 | I5: 7월 | J5: 8월 | K5: 9월 | L5: 10월 | M5: 11월 | N5: 12월 | O5: 연간합계
B6: 🇧🇷 브라질 — 월 +17명 추가 → 12개월 목표 204명
B7: 파트너 수 (명) | C7: 17 | D7: 34 | E7: 51 | F7: 68 | G7: 85 | H7: 102 | I7: 119 | J7: 136 | K7: 153 | L7: 170 | M7: 187 | N7: 204 | O7: =N7 -> 204
B8: 상위 파트너 (파레토 20%) | C8: =ROUND(C7*'② 국가별 파트너 설정'!$C$14,0) -> 3 | D8: =ROUND(D7*'② 국가별 파트너 설정'!$C$14,0) -> 7 | E8: =ROUND(E7*'② 국가별 파트너 설정'!$C$14,0) -> 10 | F8: =ROUND(F7*'② 국가별 파트너 설정'!$C$14,0) -> 14 | G8: =ROUND(G7*'② 국가별 파트너 설정'!$C$14,0) -> 17 | H8: =ROUND(H7*'② 국가별 파트너 설정'!$C$14,0) -> 20 | I8: =ROUND(I7*'② 국가별 파트너 설정'!$C$14,0) -> 24 | J8: =ROUND(J7*'② 국가별 파트너 설정'!$C$14,0) -> 27 | ... N8: =ROUND(N7*'② 국가별 파트너 설정'!$C$14,0) -> 41 | O8: =ROUND(N7*'② 국가별 파트너 설정'!$C$14,0) -> 41
B9: 월 오너 수익 ($) | C9: =(C8*'② 국가별 파트너 설정'!$C$15+(C7-C8)*0.375*'② 국가별 파트너 설정'!$C$16+(C7-C8)*0.625*'② 국가별 파트너 설정'!$C$17)*('② 국가별 파트너 설정'!$E$6+'② 국가별 파트너 설정'!$C$11*'② 국가별 파트너 설정'!$E$7+'② 국가별 파트너 설정'!$C$12*'② 국가별 파트너 설정'!$E$8) -> 2203.6903 | D9: =(D8*'② 국가별 파트너 설정'!$C$15+(D7-D8)*0.375*'② 국가별 파트너 설정'!$C$16+(D7-D8)*0.625*'② 국가별 파트너 설정'!$C$17)*('② 국가별 파트너 설정'!$E$6+'② 국가별 파트너 설정'!$C$11*'② 국가별 파트너 설정'!$E$7+'② 국가별 파트너 설정'!$C$12*'② 국가별 파트너 설정'!$E$8) -> 4826.601 | E9: =(E8*'② 국가별 파트너 설정'!$C$15+(E7-E8)*0.375*'② 국가별 파트너 설정'!$C$16+(E7-E8)*0.625*'② 국가별 파트너 설정'!$C$17)*('② 국가별 파트너 설정'!$E$6+'② 국가별 파트너 설정'!$C$11*'② 국가별 파트너 설정'!$E$7+'② 국가별 파트너 설정'!$C$12*'② 국가별 파트너 설정'!$E$8) -> 7030.2913 | F9: =(F8*'② 국가별 파트너 설정'!$C$15+(F7-F8)*0.375*'② 국가별 파트너 설정'!$C$16+(F7-F8)*0.625*'② 국가별 파트너 설정'!$C$17)*('② 국가별 파트너 설정'!$E$6+'② 국가별 파트너 설정'!$C$11*'② 국가별 파트너 설정'!$E$7+'② 국가별 파트너 설정'!$C$12*'② 국가별 파트너 설정'!$E$8) -> 9653.2021 | G9: =(G8*'② 국가별 파트너 설정'!$C$15+(G7-G8)*0.375*'② 국가별 파트너 설정'!$C$16+(G7-G8)*0.625*'② 국가별 파트너 설정'!$C$17)*('② 국가별 파트너 설정'!$E$6+'② 국가별 파트너 설정'!$C$11*'② 국가별 파트너 설정'!$E$7+'② 국가별 파트너 설정'!$C$12*'② 국가별 파트너 설정'!$E$8) -> 11856.892 | H9: =(H8*'② 국가별 파트너 설정'!$C$15+(H7-H8)*0.375*'② 국가별 파트너 설정'!$C$16+(H7-H8)*0.625*'② 국가별 파트너 설정'!$C$17)*('② 국가별 파트너 설정'!$E$6+'② 국가별 파트너 설정'!$C$11*'② 국가별 파트너 설정'!$E$7+'② 국가별 파트너 설정'!$C$12*'② 국가별 파트너 설정'!$E$8) -> 14060.583 | I9: =(I8*'② 국가별 파트너 설정'!$C$15+(I7-I8)*0.375*'② 국가별 파트너 설정'!$C$16+(I7-I8)*0.625*'② 국가별 파트너 설정'!$C$17)*('② 국가별 파트너 설정'!$E$6+'② 국가별 파트너 설정'!$C$11*'② 국가별 파트너 설정'!$E$7+'② 국가별 파트너 설정'!$C$12*'② 국가별 파트너 설정'!$E$8) -> 16683.493 | J9: =(J8*'② 국가별 파트너 설정'!$C$15+(J7-J8)*0.375*'② 국가별 파트너 설정'!$C$16+(J7-J8)*0.625*'② 국가별 파트너 설정'!$C$17)*('② 국가별 파트너 설정'!$E$6+'② 국가별 파트너 설정'!$C$11*'② 국가별 파트너 설정'!$E$7+'② 국가별 파트너 설정'!$C$12*'② 국가별 파트너 설정'!$E$8) -> 18887.184 | ... N9: =(N8*'② 국가별 파트너 설정'!$C$15+(N7-N8)*0.375*'② 국가별 파트너 설정'!$C$16+(N7-N8)*0.625*'② 국가별 파트너 설정'!$C$17)*('② 국가별 파트너 설정'!$E$6+'② 국가별 파트너 설정'!$C$11*'② 국가별 파트너 설정'!$E$7+'② 국가별 파트너 설정'!$C$12*'② 국가별 파트너 설정'!$E$8) -> 28540.386 | O9: =SUM(C9:N9) -> 184883.68
B10: 💰 월 오너 수익 (₩) | C10: =C9*'② 국가별 파트너 설정'!$C$13 -> 3085166.4 | D10: =D9*'② 국가별 파트너 설정'!$C$13 -> 6757241.5 | E10: =E9*'② 국가별 파트너 설정'!$C$13 -> 9842407.8 | F10: =F9*'② 국가별 파트너 설정'!$C$13 -> 13514483 | G10: =G9*'② 국가별 파트너 설정'!$C$13 -> 16599649 | H10: =H9*'② 국가별 파트너 설정'!$C$13 -> 19684816 | I10: =I9*'② 국가별 파트너 설정'!$C$13 -> 23356891 | J10: =J9*'② 국가별 파트너 설정'!$C$13 -> 26442057 | ... N10: =N9*'② 국가별 파트너 설정'!$C$13 -> 39956540 | O10: =SUM(C10:N10) -> 2.5883715e+08
B12: 🇲🇽 멕시코 — 월 +13명 추가 → 12개월 목표 156명
B13: 파트너 수 (명) | C13: 13 | D13: 26 | E13: 39 | F13: 52 | G13: 65 | H13: 78 | I13: 91 | J13: 104 | K13: 117 | L13: 130 | M13: 143 | N13: 156 | O13: =N13 -> 156
B14: 상위 파트너 (파레토 20%) | C14: =ROUND(C13*'② 국가별 파트너 설정'!$C$14,0) -> 3 | D14: =ROUND(D13*'② 국가별 파트너 설정'!$C$14,0) -> 5 | E14: =ROUND(E13*'② 국가별 파트너 설정'!$C$14,0) -> 8 | F14: =ROUND(F13*'② 국가별 파트너 설정'!$C$14,0) -> 10 | G14: =ROUND(G13*'② 국가별 파트너 설정'!$C$14,0) -> 13 | H14: =ROUND(H13*'② 국가별 파트너 설정'!$C$14,0) -> 16 | I14: =ROUND(I13*'② 국가별 파트너 설정'!$C$14,0) -> 18 | J14: =ROUND(J13*'② 국가별 파트너 설정'!$C$14,0) -> 21 | ... N14: =ROUND(N13*'② 국가별 파트너 설정'!$C$14,0) -> 31 | O14: =ROUND(N13*'② 국가별 파트너 설정'!$C$14,0) -> 31
B15: 월 오너 수익 ($) | C15: =(C14*'② 국가별 파트너 설정'!$C$15+(C13-C14)*0.375*'② 국가별 파트너 설정'!$C$16+(C13-C14)*0.625*'② 국가별 파트너 설정'!$C$17)*('② 국가별 파트너 설정'!$E$6+'② 국가별 파트너 설정'!$C$11*'② 국가별 파트너 설정'!$E$7+'② 국가별 파트너 설정'!$C$12*'② 국가별 파트너 설정'!$E$8) -> 1981.0953 | D15: =(D14*'② 국가별 파트너 설정'!$C$15+(D13-D14)*0.375*'② 국가별 파트너 설정'!$C$16+(D13-D14)*0.625*'② 국가별 파트너 설정'!$C$17)*('② 국가별 파트너 설정'!$E$6+'② 국가별 파트너 설정'!$C$11*'② 국가별 파트너 설정'!$E$7+'② 국가별 파트너 설정'!$C$12*'② 국가별 파트너 설정'!$E$8) -> 3542.97 | E15: =(E14*'② 국가별 파트너 설정'!$C$15+(E13-E14)*0.375*'② 국가별 파트너 설정'!$C$16+(E13-E14)*0.625*'② 국가별 파트너 설정'!$C$17)*('② 국가별 파트너 설정'!$E$6+'② 국가별 파트너 설정'!$C$11*'② 국가별 파트너 설정'!$E$7+'② 국가별 파트너 설정'!$C$12*'② 국가별 파트너 설정'!$E$8) -> 5524.0653 | F15: =(F14*'② 국가별 파트너 설정'!$C$15+(F13-F14)*0.375*'② 국가별 파트너 설정'!$C$16+(F13-F14)*0.625*'② 국가별 파트너 설정'!$C$17)*('② 국가별 파트너 설정'!$E$6+'② 국가별 파트너 설정'!$C$11*'② 국가별 파트너 설정'!$E$7+'② 국가별 파트너 설정'!$C$12*'② 국가별 파트너 설정'!$E$8) -> 7085.94 | G15: =(G14*'② 국가별 파트너 설정'!$C$15+(G13-G14)*0.375*'② 국가별 파트너 설정'!$C$16+(G13-G14)*0.625*'② 국가별 파트너 설정'!$C$17)*('② 국가별 파트너 설정'!$E$6+'② 국가별 파트너 설정'!$C$11*'② 국가별 파트너 설정'!$E$7+'② 국가별 파트너 설정'!$C$12*'② 국가별 파트너 설정'!$E$8) -> 9067.0353 | H15: =(H14*'② 국가별 파트너 설정'!$C$15+(H13-H14)*0.375*'② 국가별 파트너 설정'!$C$16+(H13-H14)*0.625*'② 국가별 파트너 설정'!$C$17)*('② 국가별 파트너 설정'!$E$6+'② 국가별 파트너 설정'!$C$11*'② 국가별 파트너 설정'!$E$7+'② 국가별 파트너 설정'!$C$12*'② 국가별 파트너 설정'!$E$8) -> 11048.131 | I15: =(I14*'② 국가별 파트너 설정'!$C$15+(I13-I14)*0.375*'② 국가별 파트너 설정'!$C$16+(I13-I14)*0.625*'② 국가별 파트너 설정'!$C$17)*('② 국가별 파트너 설정'!$E$6+'② 국가별 파트너 설정'!$C$11*'② 국가별 파트너 설정'!$E$7+'② 국가별 파트너 설정'!$C$12*'② 국가별 파트너 설정'!$E$8) -> 12610.005 | J15: =(J14*'② 국가별 파트너 설정'!$C$15+(J13-J14)*0.375*'② 국가별 파트너 설정'!$C$16+(J13-J14)*0.625*'② 국가별 파트너 설정'!$C$17)*('② 국가별 파트너 설정'!$E$6+'② 국가별 파트너 설정'!$C$11*'② 국가별 파트너 설정'!$E$7+'② 국가별 파트너 설정'!$C$12*'② 국가별 파트너 설정'!$E$8) -> 14591.101 | ... N15: =(N14*'② 국가별 파트너 설정'!$C$15+(N13-N14)*0.375*'② 국가별 파트너 설정'!$C$16+(N13-N14)*0.625*'② 국가별 파트너 설정'!$C$17)*('② 국가별 파트너 설정'!$E$6+'② 국가별 파트너 설정'!$C$11*'② 국가별 파트너 설정'!$E$7+'② 국가별 파트너 설정'!$C$12*'② 국가별 파트너 설정'!$E$8) -> 21677.041 | O15: =SUM(C15:N15) -> 141529.6
B16: 💰 월 오너 수익 (₩) | C16: =C15*'② 국가별 파트너 설정'!$C$13 -> 2773533.4 | D16: =D15*'② 국가별 파트너 설정'!$C$13 -> 4960158 | E16: =E15*'② 국가별 파트너 설정'!$C$13 -> 7733691.4 | F16: =F15*'② 국가별 파트너 설정'!$C$13 -> 9920316.1 | G16: =G15*'② 국가별 파트너 설정'!$C$13 -> 12693849 | H16: =H15*'② 국가별 파트너 설정'!$C$13 -> 15467383 | I16: =I15*'② 국가별 파트너 설정'!$C$13 -> 17654007 | J16: =J15*'② 국가별 파트너 설정'!$C$13 -> 20427541 | ... N16: =N15*'② 국가별 파트너 설정'!$C$13 -> 30347857 | O16: =SUM(C16:N16) -> 1.9814143e+08
B18: 🇨🇴 콜롬비아 — 월 +7명 추가 → 12개월 목표 84명
B19: 파트너 수 (명) | C19: 7 | D19: 14 | E19: 21 | F19: 28 | G19: 35 | H19: 42 | I19: 49 | J19: 56 | K19: 63 | L19: 70 | M19: 77 | N19: 84 | O19: =N19 -> 84
B20: 상위 파트너 (파레토 20%) | C20: =ROUND(C19*'② 국가별 파트너 설정'!$C$14,0) -> 1 | D20: =ROUND(D19*'② 국가별 파트너 설정'!$C$14,0) -> 3 | E20: =ROUND(E19*'② 국가별 파트너 설정'!$C$14,0) -> 4 | F20: =ROUND(F19*'② 국가별 파트너 설정'!$C$14,0) -> 6 | G20: =ROUND(G19*'② 국가별 파트너 설정'!$C$14,0) -> 7 | H20: =ROUND(H19*'② 국가별 파트너 설정'!$C$14,0) -> 8 | I20: =ROUND(I19*'② 국가별 파트너 설정'!$C$14,0) -> 10 | J20: =ROUND(J19*'② 국가별 파트너 설정'!$C$14,0) -> 11 | ... N20: =ROUND(N19*'② 국가별 파트너 설정'!$C$14,0) -> 17 | O20: =ROUND(N19*'② 국가별 파트너 설정'!$C$14,0) -> 17
B21: 월 오너 수익 ($) | C21: =(C20*'② 국가별 파트너 설정'!$C$15+(C19-C20)*0.375*'② 국가별 파트너 설정'!$C$16+(C19-C20)*0.625*'② 국가별 파트너 설정'!$C$17)*('② 국가별 파트너 설정'!$E$6+'② 국가별 파트너 설정'!$C$11*'② 국가별 파트너 설정'!$E$7+'② 국가별 파트너 설정'!$C$12*'② 국가별 파트너 설정'!$E$8) -> 808.76174 | D21: =(D20*'② 국가별 파트너 설정'!$C$15+(D19-D20)*0.375*'② 국가별 파트너 설정'!$C$16+(D19-D20)*0.625*'② 국가별 파트너 설정'!$C$17)*('② 국가별 파트너 설정'!$E$6+'② 국가별 파트너 설정'!$C$11*'② 국가별 파트너 설정'!$E$7+'② 국가별 파트너 설정'!$C$12*'② 국가별 파트너 설정'!$E$8) -> 2036.744 | E21: =(E20*'② 국가별 파트너 설정'!$C$15+(E19-E20)*0.375*'② 국가별 파트너 설정'!$C$16+(E19-E20)*0.625*'② 국가별 파트너 설정'!$C$17)*('② 국가별 파트너 설정'!$E$6+'② 국가별 파트너 설정'!$C$11*'② 국가별 파트너 설정'!$E$7+'② 국가별 파트너 설정'!$C$12*'② 국가별 파트너 설정'!$E$8) -> 2845.5058 | F21: =(F20*'② 국가별 파트너 설정'!$C$15+(F19-F20)*0.375*'② 국가별 파트너 설정'!$C$16+(F19-F20)*0.625*'② 국가별 파트너 설정'!$C$17)*('② 국가별 파트너 설정'!$E$6+'② 국가별 파트너 설정'!$C$11*'② 국가별 파트너 설정'!$E$7+'② 국가별 파트너 설정'!$C$12*'② 국가별 파트너 설정'!$E$8) -> 4073.488 | G21: =(G20*'② 국가별 파트너 설정'!$C$15+(G19-G20)*0.375*'② 국가별 파트너 설정'!$C$16+(G19-G20)*0.625*'② 국가별 파트너 설정'!$C$17)*('② 국가별 파트너 설정'!$E$6+'② 국가별 파트너 설정'!$C$11*'② 국가별 파트너 설정'!$E$7+'② 국가별 파트너 설정'!$C$12*'② 국가별 파트너 설정'!$E$8) -> 4882.2498 | H21: =(H20*'② 국가별 파트너 설정'!$C$15+(H19-H20)*0.375*'② 국가별 파트너 설정'!$C$16+(H19-H20)*0.625*'② 국가별 파트너 설정'!$C$17)*('② 국가별 파트너 설정'!$E$6+'② 국가별 파트너 설정'!$C$11*'② 국가별 파트너 설정'!$E$7+'② 국가별 파트너 설정'!$C$12*'② 국가별 파트너 설정'!$E$8) -> 5691.0115 | I21: =(I20*'② 국가별 파트너 설정'!$C$15+(I19-I20)*0.375*'② 국가별 파트너 설정'!$C$16+(I19-I20)*0.625*'② 국가별 파트너 설정'!$C$17)*('② 국가별 파트너 설정'!$E$6+'② 국가별 파트너 설정'!$C$11*'② 국가별 파트너 설정'!$E$7+'② 국가별 파트너 설정'!$C$12*'② 국가별 파트너 설정'!$E$8) -> 6918.9938 | J21: =(J20*'② 국가별 파트너 설정'!$C$15+(J19-J20)*0.375*'② 국가별 파트너 설정'!$C$16+(J19-J20)*0.625*'② 국가별 파트너 설정'!$C$17)*('② 국가별 파트너 설정'!$E$6+'② 국가별 파트너 설정'!$C$11*'② 국가별 파트너 설정'!$E$7+'② 국가별 파트너 설정'!$C$12*'② 국가별 파트너 설정'!$E$8) -> 7727.7555 | ... N21: =(N20*'② 국가별 파트너 설정'!$C$15+(N19-N20)*0.375*'② 국가별 파트너 설정'!$C$16+(N19-N20)*0.625*'② 국가별 파트너 설정'!$C$17)*('② 국가별 파트너 설정'!$E$6+'② 국가별 파트너 설정'!$C$11*'② 국가별 파트너 설정'!$E$7+'② 국가별 파트너 설정'!$C$12*'② 국가별 파트너 설정'!$E$8) -> 11801.244 | O21: =SUM(C21:N21) -> 76079.253
B22: 💰 월 오너 수익 (₩) | C22: =C21*'② 국가별 파트너 설정'!$C$13 -> 1132266.4 | D22: =D21*'② 국가별 파트너 설정'!$C$13 -> 2851441.6 | E22: =E21*'② 국가별 파트너 설정'!$C$13 -> 3983708.1 | F22: =F21*'② 국가별 파트너 설정'!$C$13 -> 5702883.3 | G22: =G21*'② 국가별 파트너 설정'!$C$13 -> 6835149.7 | H22: =H21*'② 국가별 파트너 설정'!$C$13 -> 7967416.1 | I22: =I21*'② 국가별 파트너 설정'!$C$13 -> 9686591.3 | J22: =J21*'② 국가별 파트너 설정'!$C$13 -> 10818858 | ... N22: =N21*'② 국가별 파트너 설정'!$C$13 -> 16521741 | O22: =SUM(C22:N22) -> 1.0651095e+08
B24: 🇺🇸 미국히스패닉 — 월 +8명 추가 → 12개월 목표 96명
B25: 파트너 수 (명) | C25: 8 | D25: 16 | E25: 24 | F25: 32 | G25: 40 | H25: 48 | I25: 56 | J25: 64 | K25: 72 | L25: 80 | M25: 88 | N25: 96 | O25: =N25 -> 96
B26: 상위 파트너 (파레토 20%) | C26: =ROUND(C25*'② 국가별 파트너 설정'!$C$14,0) -> 2 | D26: =ROUND(D25*'② 국가별 파트너 설정'!$C$14,0) -> 3 | E26: =ROUND(E25*'② 국가별 파트너 설정'!$C$14,0) -> 5 | F26: =ROUND(F25*'② 국가별 파트너 설정'!$C$14,0) -> 6 | G26: =ROUND(G25*'② 국가별 파트너 설정'!$C$14,0) -> 8 | H26: =ROUND(H25*'② 국가별 파트너 설정'!$C$14,0) -> 10 | I26: =ROUND(I25*'② 국가별 파트너 설정'!$C$14,0) -> 11 | J26: =ROUND(J25*'② 국가별 파트너 설정'!$C$14,0) -> 13 | ... N26: =ROUND(N25*'② 국가별 파트너 설정'!$C$14,0) -> 19 | O26: =ROUND(N25*'② 국가별 파트너 설정'!$C$14,0) -> 19
B27: 월 오너 수익 ($) | C27: =(C26*'② 국가별 파트너 설정'!$C$15+(C25-C26)*0.375*'② 국가별 파트너 설정'!$C$16+(C25-C26)*0.625*'② 국가별 파트너 설정'!$C$17)*('② 국가별 파트너 설정'!$E$6+'② 국가별 파트너 설정'!$C$11*'② 국가별 파트너 설정'!$E$7+'② 국가별 파트너 설정'!$C$12*'② 국가별 파트너 설정'!$E$8) -> 1283.631 | D27: =(D26*'② 국가별 파트너 설정'!$C$15+(D25-D26)*0.375*'② 국가별 파트너 설정'!$C$16+(D25-D26)*0.625*'② 국가별 파트너 설정'!$C$17)*('② 국가별 파트너 설정'!$E$6+'② 국가별 파트너 설정'!$C$11*'② 국가별 파트너 설정'!$E$7+'② 국가별 파트너 설정'!$C$12*'② 국가별 파트너 설정'!$E$8) -> 2148.0415 | E27: =(E26*'② 국가별 파트너 설정'!$C$15+(E25-E26)*0.375*'② 국가별 파트너 설정'!$C$16+(E25-E26)*0.625*'② 국가별 파트너 설정'!$C$17)*('② 국가별 파트너 설정'!$E$6+'② 국가별 파트너 설정'!$C$11*'② 국가별 파트너 설정'!$E$7+'② 국가별 파트너 설정'!$C$12*'② 국가별 파트너 설정'!$E$8) -> 3431.6725 | F27: =(F26*'② 국가별 파트너 설정'!$C$15+(F25-F26)*0.375*'② 국가별 파트너 설정'!$C$16+(F25-F26)*0.625*'② 국가별 파트너 설정'!$C$17)*('② 국가별 파트너 설정'!$E$6+'② 국가별 파트너 설정'!$C$11*'② 국가별 파트너 설정'!$E$7+'② 국가별 파트너 설정'!$C$12*'② 국가별 파트너 설정'!$E$8) -> 4296.083 | G27: =(G26*'② 국가별 파트너 설정'!$C$15+(G25-G26)*0.375*'② 국가별 파트너 설정'!$C$16+(G25-G26)*0.625*'② 국가별 파트너 설정'!$C$17)*('② 국가별 파트너 설정'!$E$6+'② 국가별 파트너 설정'!$C$11*'② 국가별 파트너 설정'!$E$7+'② 국가별 파트너 설정'!$C$12*'② 국가별 파트너 설정'!$E$8) -> 5579.714 | H27: =(H26*'② 국가별 파트너 설정'!$C$15+(H25-H26)*0.375*'② 국가별 파트너 설정'!$C$16+(H25-H26)*0.625*'② 국가별 파트너 설정'!$C$17)*('② 국가별 파트너 설정'!$E$6+'② 국가별 파트너 설정'!$C$11*'② 국가별 파트너 설정'!$E$7+'② 국가별 파트너 설정'!$C$12*'② 국가별 파트너 설정'!$E$8) -> 6863.3451 | I27: =(I26*'② 국가별 파트너 설정'!$C$15+(I25-I26)*0.375*'② 국가별 파트너 설정'!$C$16+(I25-I26)*0.625*'② 국가별 파트너 설정'!$C$17)*('② 국가별 파트너 설정'!$E$6+'② 국가별 파트너 설정'!$C$11*'② 국가별 파트너 설정'!$E$7+'② 국가별 파트너 설정'!$C$12*'② 국가별 파트너 설정'!$E$8) -> 7727.7555 | J27: =(J26*'② 국가별 파트너 설정'!$C$15+(J25-J26)*0.375*'② 국가별 파트너 설정'!$C$16+(J25-J26)*0.625*'② 국가별 파트너 설정'!$C$17)*('② 국가별 파트너 설정'!$E$6+'② 국가별 파트너 설정'!$C$11*'② 국가별 파트너 설정'!$E$7+'② 국가별 파트너 설정'!$C$12*'② 국가별 파트너 설정'!$E$8) -> 9011.3866 | ... N27: =(N26*'② 국가별 파트너 설정'!$C$15+(N25-N26)*0.375*'② 국가별 파트너 설정'!$C$16+(N25-N26)*0.625*'② 국가별 파트너 설정'!$C$17)*('② 국가별 파트너 설정'!$E$6+'② 국가별 파트너 설정'!$C$11*'② 국가별 파트너 설정'!$E$7+'② 국가별 파트너 설정'!$C$12*'② 국가별 파트너 설정'!$E$8) -> 13307.47 | O27: =SUM(C27:N27) -> 87127.383
B28: 💰 월 오너 수익 (₩) | C28: =C27*'② 국가별 파트너 설정'!$C$13 -> 1797083.4 | D28: =D27*'② 국가별 파트너 설정'!$C$13 -> 3007258.1 | E28: =E27*'② 국가별 파트너 설정'!$C$13 -> 4804341.5 | F28: =F27*'② 국가별 파트너 설정'!$C$13 -> 6014516.2 | G28: =G27*'② 국가별 파트너 설정'!$C$13 -> 7811599.7 | H28: =H27*'② 국가별 파트너 설정'!$C$13 -> 9608683.1 | I28: =I27*'② 국가별 파트너 설정'!$C$13 -> 10818858 | J28: =J27*'② 국가별 파트너 설정'!$C$13 -> 12615941 | ... N28: =N27*'② 국가별 파트너 설정'!$C$13 -> 18630457 | O28: =SUM(C28:N28) -> 1.2197834e+08
B30: 🇦🇷 아르헨티나 — 월 +4명 추가 → 12개월 목표 48명
B31: 파트너 수 (명) | C31: 4 | D31: 8 | E31: 12 | F31: 16 | G31: 20 | H31: 24 | I31: 28 | J31: 32 | K31: 36 | L31: 40 | M31: 44 | N31: 48 | O31: =N31 -> 48
B32: 상위 파트너 (파레토 20%) | C32: =ROUND(C31*'② 국가별 파트너 설정'!$C$14,0) -> 1 | D32: =ROUND(D31*'② 국가별 파트너 설정'!$C$14,0) -> 2 | E32: =ROUND(E31*'② 국가별 파트너 설정'!$C$14,0) -> 2 | F32: =ROUND(F31*'② 국가별 파트너 설정'!$C$14,0) -> 3 | G32: =ROUND(G31*'② 국가별 파트너 설정'!$C$14,0) -> 4 | H32: =ROUND(H31*'② 국가별 파트너 설정'!$C$14,0) -> 5 | I32: =ROUND(I31*'② 국가별 파트너 설정'!$C$14,0) -> 6 | J32: =ROUND(J31*'② 국가별 파트너 설정'!$C$14,0) -> 6 | ... N32: =ROUND(N31*'② 국가별 파트너 설정'!$C$14,0) -> 10 | O32: =ROUND(N31*'② 국가별 파트너 설정'!$C$14,0) -> 10
B33: 월 오너 수익 ($) | C33: =(C32*'② 국가별 파트너 설정'!$C$15+(C31-C32)*0.375*'② 국가별 파트너 설정'!$C$16+(C31-C32)*0.625*'② 국가별 파트너 설정'!$C$17)*('② 국가별 파트너 설정'!$E$6+'② 국가별 파트너 설정'!$C$11*'② 국가별 파트너 설정'!$E$7+'② 국가별 파트너 설정'!$C$12*'② 국가별 파트너 설정'!$E$8) -> 641.81551 | D33: =(D32*'② 국가별 파트너 설정'!$C$15+(D31-D32)*0.375*'② 국가별 파트너 설정'!$C$16+(D31-D32)*0.625*'② 국가별 파트너 설정'!$C$17)*('② 국가별 파트너 설정'!$E$6+'② 국가별 파트너 설정'!$C$11*'② 국가별 파트너 설정'!$E$7+'② 국가별 파트너 설정'!$C$12*'② 국가별 파트너 설정'!$E$8) -> 1283.631 | E33: =(E32*'② 국가별 파트너 설정'!$C$15+(E31-E32)*0.375*'② 국가별 파트너 설정'!$C$16+(E31-E32)*0.625*'② 국가별 파트너 설정'!$C$17)*('② 국가별 파트너 설정'!$E$6+'② 국가별 파트너 설정'!$C$11*'② 국가별 파트너 설정'!$E$7+'② 국가별 파트너 설정'!$C$12*'② 국가별 파트너 설정'!$E$8) -> 1506.226 | F33: =(F32*'② 국가별 파트너 설정'!$C$15+(F31-F32)*0.375*'② 국가별 파트너 설정'!$C$16+(F31-F32)*0.625*'② 국가별 파트너 설정'!$C$17)*('② 국가별 파트너 설정'!$E$6+'② 국가별 파트너 설정'!$C$11*'② 국가별 파트너 설정'!$E$7+'② 국가별 파트너 설정'!$C$12*'② 국가별 파트너 설정'!$E$8) -> 2148.0415 | G33: =(G32*'② 국가별 파트너 설정'!$C$15+(G31-G32)*0.375*'② 국가별 파트너 설정'!$C$16+(G31-G32)*0.625*'② 국가별 파트너 설정'!$C$17)*('② 국가별 파트너 설정'!$E$6+'② 국가별 파트너 설정'!$C$11*'② 국가별 파트너 설정'!$E$7+'② 국가별 파트너 설정'!$C$12*'② 국가별 파트너 설정'!$E$8) -> 2789.857 | H33: =(H32*'② 국가별 파트너 설정'!$C$15+(H31-H32)*0.375*'② 국가별 파트너 설정'!$C$16+(H31-H32)*0.625*'② 국가별 파트너 설정'!$C$17)*('② 국가별 파트너 설정'!$E$6+'② 국가별 파트너 설정'!$C$11*'② 국가별 파트너 설정'!$E$7+'② 국가별 파트너 설정'!$C$12*'② 국가별 파트너 설정'!$E$8) -> 3431.6725 | I33: =(I32*'② 국가별 파트너 설정'!$C$15+(I31-I32)*0.375*'② 국가별 파트너 설정'!$C$16+(I31-I32)*0.625*'② 국가별 파트너 설정'!$C$17)*('② 국가별 파트너 설정'!$E$6+'② 국가별 파트너 설정'!$C$11*'② 국가별 파트너 설정'!$E$7+'② 국가별 파트너 설정'!$C$12*'② 국가별 파트너 설정'!$E$8) -> 4073.488 | J33: =(J32*'② 국가별 파트너 설정'!$C$15+(J31-J32)*0.375*'② 국가별 파트너 설정'!$C$16+(J31-J32)*0.625*'② 국가별 파트너 설정'!$C$17)*('② 국가별 파트너 설정'!$E$6+'② 국가별 파트너 설정'!$C$11*'② 국가별 파트너 설정'!$E$7+'② 국가별 파트너 설정'!$C$12*'② 국가별 파트너 설정'!$E$8) -> 4296.083 | ... N33: =(N32*'② 국가별 파트너 설정'!$C$15+(N31-N32)*0.375*'② 국가별 파트너 설정'!$C$16+(N31-N32)*0.625*'② 국가별 파트너 설정'!$C$17)*('② 국가별 파트너 설정'!$E$6+'② 국가별 파트너 설정'!$C$11*'② 국가별 파트너 설정'!$E$7+'② 국가별 파트너 설정'!$C$12*'② 국가별 파트너 설정'!$E$8) -> 6863.3451 | O33: =SUM(C33:N33) -> 43773.302
B34: 💰 월 오너 수익 (₩) | C34: =C33*'② 국가별 파트너 설정'!$C$13 -> 898541.72 | D34: =D33*'② 국가별 파트너 설정'!$C$13 -> 1797083.4 | E34: =E33*'② 국가별 파트너 설정'!$C$13 -> 2108716.4 | F34: =F33*'② 국가별 파트너 설정'!$C$13 -> 3007258.1 | G34: =G33*'② 국가별 파트너 설정'!$C$13 -> 3905799.8 | H34: =H33*'② 국가별 파트너 설정'!$C$13 -> 4804341.5 | I34: =I33*'② 국가별 파트너 설정'!$C$13 -> 5702883.3 | J34: =J33*'② 국가별 파트너 설정'!$C$13 -> 6014516.2 | ... N34: =N33*'② 국가별 파트너 설정'!$C$13 -> 9608683.1 | O34: =SUM(C34:N34) -> 61282623
B36: 🇨🇱 칠레 — 월 +3명 추가 → 12개월 목표 36명
B37: 파트너 수 (명) | C37: 3 | D37: 6 | E37: 9 | F37: 12 | G37: 15 | H37: 18 | I37: 21 | J37: 24 | K37: 27 | L37: 30 | M37: 33 | N37: 36 | O37: =N37 -> 36
B38: 상위 파트너 (파레토 20%) | C38: =ROUND(C37*'② 국가별 파트너 설정'!$C$14,0) -> 1 | D38: =ROUND(D37*'② 국가별 파트너 설정'!$C$14,0) -> 1 | E38: =ROUND(E37*'② 국가별 파트너 설정'!$C$14,0) -> 2 | F38: =ROUND(F37*'② 국가별 파트너 설정'!$C$14,0) -> 2 | G38: =ROUND(G37*'② 국가별 파트너 설정'!$C$14,0) -> 3 | H38: =ROUND(H37*'② 국가별 파트너 설정'!$C$14,0) -> 4 | I38: =ROUND(I37*'② 국가별 파트너 설정'!$C$14,0) -> 4 | J38: =ROUND(J37*'② 국가별 파트너 설정'!$C$14,0) -> 5 | ... N38: =ROUND(N37*'② 국가별 파트너 설정'!$C$14,0) -> 7 | O38: =ROUND(N37*'② 국가별 파트너 설정'!$C$14,0) -> 7
B39: 월 오너 수익 ($) | C39: =(C38*'② 국가별 파트너 설정'!$C$15+(C37-C38)*0.375*'② 국가별 파트너 설정'!$C$16+(C37-C38)*0.625*'② 국가별 파트너 설정'!$C$17)*('② 국가별 파트너 설정'!$E$6+'② 국가별 파트너 설정'!$C$11*'② 국가별 파트너 설정'!$E$7+'② 국가별 파트너 설정'!$C$12*'② 국가별 파트너 설정'!$E$8) -> 586.16677 | D39: =(D38*'② 국가별 파트너 설정'!$C$15+(D37-D38)*0.375*'② 국가별 파트너 설정'!$C$16+(D37-D38)*0.625*'② 국가별 파트너 설정'!$C$17)*('② 국가별 파트너 설정'!$E$6+'② 국가별 파트너 설정'!$C$11*'② 국가별 파트너 설정'!$E$7+'② 국가별 파트너 설정'!$C$12*'② 국가별 파트너 설정'!$E$8) -> 753.113 | E39: =(E38*'② 국가별 파트너 설정'!$C$15+(E37-E38)*0.375*'② 국가별 파트너 설정'!$C$16+(E37-E38)*0.625*'② 국가별 파트너 설정'!$C$17)*('② 국가별 파트너 설정'!$E$6+'② 국가별 파트너 설정'!$C$11*'② 국가별 파트너 설정'!$E$7+'② 국가별 파트너 설정'!$C$12*'② 국가별 파트너 설정'!$E$8) -> 1339.2798 | F39: =(F38*'② 국가별 파트너 설정'!$C$15+(F37-F38)*0.375*'② 국가별 파트너 설정'!$C$16+(F37-F38)*0.625*'② 국가별 파트너 설정'!$C$17)*('② 국가별 파트너 설정'!$E$6+'② 국가별 파트너 설정'!$C$11*'② 국가별 파트너 설정'!$E$7+'② 국가별 파트너 설정'!$C$12*'② 국가별 파트너 설정'!$E$8) -> 1506.226 | G39: =(G38*'② 국가별 파트너 설정'!$C$15+(G37-G38)*0.375*'② 국가별 파트너 설정'!$C$16+(G37-G38)*0.625*'② 국가별 파트너 설정'!$C$17)*('② 국가별 파트너 설정'!$E$6+'② 국가별 파트너 설정'!$C$11*'② 국가별 파트너 설정'!$E$7+'② 국가별 파트너 설정'!$C$12*'② 국가별 파트너 설정'!$E$8) -> 2092.3928 | H39: =(H38*'② 국가별 파트너 설정'!$C$15+(H37-H38)*0.375*'② 국가별 파트너 설정'!$C$16+(H37-H38)*0.625*'② 국가별 파트너 설정'!$C$17)*('② 국가별 파트너 설정'!$E$6+'② 국가별 파트너 설정'!$C$11*'② 국가별 파트너 설정'!$E$7+'② 국가별 파트너 설정'!$C$12*'② 국가별 파트너 설정'!$E$8) -> 2678.5595 | I39: =(I38*'② 국가별 파트너 설정'!$C$15+(I37-I38)*0.375*'② 국가별 파트너 설정'!$C$16+(I37-I38)*0.625*'② 국가별 파트너 설정'!$C$17)*('② 국가별 파트너 설정'!$E$6+'② 국가별 파트너 설정'!$C$11*'② 국가별 파트너 설정'!$E$7+'② 국가별 파트너 설정'!$C$12*'② 국가별 파트너 설정'!$E$8) -> 2845.5058 | J39: =(J38*'② 국가별 파트너 설정'!$C$15+(J37-J38)*0.375*'② 국가별 파트너 설정'!$C$16+(J37-J38)*0.625*'② 국가별 파트너 설정'!$C$17)*('② 국가별 파트너 설정'!$E$6+'② 국가별 파트너 설정'!$C$11*'② 국가별 파트너 설정'!$E$7+'② 국가별 파트너 설정'!$C$12*'② 국가별 파트너 설정'!$E$8) -> 3431.6725 | ... N39: =(N38*'② 국가별 파트너 설정'!$C$15+(N37-N38)*0.375*'② 국가별 파트너 설정'!$C$16+(N37-N38)*0.625*'② 국가별 파트너 설정'!$C$17)*('② 국가별 파트너 설정'!$E$6+'② 국가별 파트너 설정'!$C$11*'② 국가별 파트너 설정'!$E$7+'② 국가별 파트너 설정'!$C$12*'② 국가별 파트너 설정'!$E$8) -> 4937.8985 | O39: =SUM(C39:N39) -> 32725.171
B40: 💰 월 오너 수익 (₩) | C40: =C39*'② 국가별 파트너 설정'!$C$13 -> 820633.47 | D40: =D39*'② 국가별 파트너 설정'!$C$13 -> 1054358.2 | E40: =E39*'② 국가별 파트너 설정'!$C$13 -> 1874991.7 | F40: =F39*'② 국가별 파트너 설정'!$C$13 -> 2108716.4 | G40: =G39*'② 국가별 파트너 설정'!$C$13 -> 2929349.9 | H40: =H39*'② 국가별 파트너 설정'!$C$13 -> 3749983.3 | I40: =I39*'② 국가별 파트너 설정'!$C$13 -> 3983708.1 | J40: =J39*'② 국가별 파트너 설정'!$C$13 -> 4804341.5 | ... N40: =N39*'② 국가별 파트너 설정'!$C$13 -> 6913057.9 | O40: =SUM(C40:N40) -> 45815240
B42: 🇵🇹 포르투갈 — 월 +3명 추가 → 12개월 목표 36명
B43: 파트너 수 (명) | C43: 3 | D43: 6 | E43: 9 | F43: 12 | G43: 15 | H43: 18 | I43: 21 | J43: 24 | K43: 27 | L43: 30 | M43: 33 | N43: 36 | O43: =N43 -> 36
B44: 상위 파트너 (파레토 20%) | C44: =ROUND(C43*'② 국가별 파트너 설정'!$C$14,0) -> 1 | D44: =ROUND(D43*'② 국가별 파트너 설정'!$C$14,0) -> 1 | E44: =ROUND(E43*'② 국가별 파트너 설정'!$C$14,0) -> 2 | F44: =ROUND(F43*'② 국가별 파트너 설정'!$C$14,0) -> 2 | G44: =ROUND(G43*'② 국가별 파트너 설정'!$C$14,0) -> 3 | H44: =ROUND(H43*'② 국가별 파트너 설정'!$C$14,0) -> 4 | I44: =ROUND(I43*'② 국가별 파트너 설정'!$C$14,0) -> 4 | J44: =ROUND(J43*'② 국가별 파트너 설정'!$C$14,0) -> 5 | ... N44: =ROUND(N43*'② 국가별 파트너 설정'!$C$14,0) -> 7 | O44: =ROUND(N43*'② 국가별 파트너 설정'!$C$14,0) -> 7
B45: 월 오너 수익 ($) | C45: =(C44*'② 국가별 파트너 설정'!$C$15+(C43-C44)*0.375*'② 국가별 파트너 설정'!$C$16+(C43-C44)*0.625*'② 국가별 파트너 설정'!$C$17)*('② 국가별 파트너 설정'!$E$6+'② 국가별 파트너 설정'!$C$11*'② 국가별 파트너 설정'!$E$7+'② 국가별 파트너 설정'!$C$12*'② 국가별 파트너 설정'!$E$8) -> 586.16677 | D45: =(D44*'② 국가별 파트너 설정'!$C$15+(D43-D44)*0.375*'② 국가별 파트너 설정'!$C$16+(D43-D44)*0.625*'② 국가별 파트너 설정'!$C$17)*('② 국가별 파트너 설정'!$E$6+'② 국가별 파트너 설정'!$C$11*'② 국가별 파트너 설정'!$E$7+'② 국가별 파트너 설정'!$C$12*'② 국가별 파트너 설정'!$E$8) -> 753.113 | E45: =(E44*'② 국가별 파트너 설정'!$C$15+(E43-E44)*0.375*'② 국가별 파트너 설정'!$C$16+(E43-E44)*0.625*'② 국가별 파트너 설정'!$C$17)*('② 국가별 파트너 설정'!$E$6+'② 국가별 파트너 설정'!$C$11*'② 국가별 파트너 설정'!$E$7+'② 국가별 파트너 설정'!$C$12*'② 국가별 파트너 설정'!$E$8) -> 1339.2798 | F45: =(F44*'② 국가별 파트너 설정'!$C$15+(F43-F44)*0.375*'② 국가별 파트너 설정'!$C$16+(F43-F44)*0.625*'② 국가별 파트너 설정'!$C$17)*('② 국가별 파트너 설정'!$E$6+'② 국가별 파트너 설정'!$C$11*'② 국가별 파트너 설정'!$E$7+'② 국가별 파트너 설정'!$C$12*'② 국가별 파트너 설정'!$E$8) -> 1506.226 | G45: =(G44*'② 국가별 파트너 설정'!$C$15+(G43-G44)*0.375*'② 국가별 파트너 설정'!$C$16+(G43-G44)*0.625*'② 국가별 파트너 설정'!$C$17)*('② 국가별 파트너 설정'!$E$6+'② 국가별 파트너 설정'!$C$11*'② 국가별 파트너 설정'!$E$7+'② 국가별 파트너 설정'!$C$12*'② 국가별 파트너 설정'!$E$8) -> 2092.3928 | H45: =(H44*'② 국가별 파트너 설정'!$C$15+(H43-H44)*0.375*'② 국가별 파트너 설정'!$C$16+(H43-H44)*0.625*'② 국가별 파트너 설정'!$C$17)*('② 국가별 파트너 설정'!$E$6+'② 국가별 파트너 설정'!$C$11*'② 국가별 파트너 설정'!$E$7+'② 국가별 파트너 설정'!$C$12*'② 국가별 파트너 설정'!$E$8) -> 2678.5595 | I45: =(I44*'② 국가별 파트너 설정'!$C$15+(I43-I44)*0.375*'② 국가별 파트너 설정'!$C$16+(I43-I44)*0.625*'② 국가별 파트너 설정'!$C$17)*('② 국가별 파트너 설정'!$E$6+'② 국가별 파트너 설정'!$C$11*'② 국가별 파트너 설정'!$E$7+'② 국가별 파트너 설정'!$C$12*'② 국가별 파트너 설정'!$E$8) -> 2845.5058 | J45: =(J44*'② 국가별 파트너 설정'!$C$15+(J43-J44)*0.375*'② 국가별 파트너 설정'!$C$16+(J43-J44)*0.625*'② 국가별 파트너 설정'!$C$17)*('② 국가별 파트너 설정'!$E$6+'② 국가별 파트너 설정'!$C$11*'② 국가별 파트너 설정'!$E$7+'② 국가별 파트너 설정'!$C$12*'② 국가별 파트너 설정'!$E$8) -> 3431.6725 | ... N45: =(N44*'② 국가별 파트너 설정'!$C$15+(N43-N44)*0.375*'② 국가별 파트너 설정'!$C$16+(N43-N44)*0.625*'② 국가별 파트너 설정'!$C$17)*('② 국가별 파트너 설정'!$E$6+'② 국가별 파트너 설정'!$C$11*'② 국가별 파트너 설정'!$E$7+'② 국가별 파트너 설정'!$C$12*'② 국가별 파트너 설정'!$E$8) -> 4937.8985 | O45: =SUM(C45:N45) -> 32725.171
B46: 💰 월 오너 수익 (₩) | C46: =C45*'② 국가별 파트너 설정'!$C$13 -> 820633.47 | D46: =D45*'② 국가별 파트너 설정'!$C$13 -> 1054358.2 | E46: =E45*'② 국가별 파트너 설정'!$C$13 -> 1874991.7 | F46: =F45*'② 국가별 파트너 설정'!$C$13 -> 2108716.4 | G46: =G45*'② 국가별 파트너 설정'!$C$13 -> 2929349.9 | H46: =H45*'② 국가별 파트너 설정'!$C$13 -> 3749983.3 | I46: =I45*'② 국가별 파트너 설정'!$C$13 -> 3983708.1 | J46: =J45*'② 국가별 파트너 설정'!$C$13 -> 4804341.5 | ... N46: =N45*'② 국가별 파트너 설정'!$C$13 -> 6913057.9 | O46: =SUM(C46:N46) -> 45815240
B48: 🏆 전체 국가 합산 월 오너 수익 (₩)
...

Sheet ④ 요약 대시보드
B1: 🏆 최종 요약 — 국가별 12개월 수익 + 전략 포인트
B2: 총 파트너 목표: 660명 | D+1개월 시작 | 파레토 법칙 적용
B4: 📊 국가별 12개월 수익 성과
B5: 국가 | C5: 12개월 파트너수 | D5: 1개월 수익(₩) | E5: 6개월 수익(₩) | F5: 12개월 수익(₩) | G5: 연간누적(₩) | H5: 전체비중(%) | I5: 파트너1인당 연간수익(₩)
B6: 🇧🇷 브라질 | C6: ='③ 12개월 성장 시뮬'!N7 -> 204 | D6: ='③ 12개월 성장 시뮬'!C10 -> 3085166.4 | E6: ='③ 12개월 성장 시뮬'!H10 -> 19684816 | F6: ='③ 12개월 성장 시뮬'!N10 -> 39956540 | G6: =SUM('③ 12개월 성장 시뮬'!C10:N10) -> 2.5883715e+08 | H6: =G6/G$13 -> 0.30873452 | I6: =IF(C6>0,G6/C6,0) -> 1268809.5
B7: 🇲🇽 멕시코 | C7: ='③ 12개월 성장 시뮬'!N13 -> 156 | D7: ='③ 12개월 성장 시뮬'!C16 -> 2773533.4 | E7: ='③ 12개월 성장 시뮬'!H16 -> 15467383 | F7: ='③ 12개월 성장 시뮬'!N16 -> 30347857 | G7: =SUM('③ 12개월 성장 시뮬'!C16:N16) -> 1.9814143e+08 | H7: =G7/G$13 -> 0.23633818 | I7: =IF(C7>0,G7/C7,0) -> 1270137.4
B8: 🇨🇴 콜롬비아 | C8: ='③ 12개월 성장 시뮬'!N19 -> 84 | D8: ='③ 12개월 성장 시뮬'!C22 -> 1132266.4 | E8: ='③ 12개월 성장 시뮬'!H22 -> 7967416.1 | F8: ='③ 12개월 성장 시뮬'!N22 -> 16521741 | G8: =SUM('③ 12개월 성장 시뮬'!C22:N22) -> 1.0651095e+08 | H8: =G8/G$13 -> 0.12704362 | I8: =IF(C8>0,G8/C8,0) -> 1267987.5
B9: 🇺🇸 미국히스패닉 | C9: ='③ 12개월 성장 시뮬'!N25 -> 96 | D9: ='③ 12개월 성장 시뮬'!C28 -> 1797083.4 | E9: ='③ 12개월 성장 시뮬'!H28 -> 9608683.1 | F9: ='③ 12개월 성장 시뮬'!N28 -> 18630457 | G9: =SUM('③ 12개월 성장 시뮬'!C28:N28) -> 1.2197834e+08 | H9: =G9/G$13 -> 0.14549273 | I9: =IF(C9>0,G9/C9,0) -> 1270607.7
B10: 🇦🇷 아르헨티나 | C10: ='③ 12개월 성장 시뮬'!N31 -> 48 | D10: ='③ 12개월 성장 시뮬'!C34 -> 898541.72 | E10: ='③ 12개월 성장 시뮬'!H34 -> 4804341.5 | F10: ='③ 12개월 성장 시뮬'!N34 -> 9608683.1 | G10: =SUM('③ 12개월 성장 시뮬'!C34:N34) -> 61282623 | H10: =G10/G$13 -> 0.07309639 | I10: =IF(C10>0,G10/C10,0) -> 1276721.3
B11: 🇨🇱 칠레 | C11: ='③ 12개월 성장 시뮬'!N37 -> 36 | D11: ='③ 12개월 성장 시뮬'!C40 -> 820633.47 | E11: ='③ 12개월 성장 시뮬'!H40 -> 3749983.3 | F11: ='③ 12개월 성장 시뮬'!N40 -> 6913057.9 | G11: =SUM('③ 12개월 성장 시뮬'!C40:N40) -> 45815240 | H11: =G11/G$13 -> 0.05464728 | I11: =IF(C11>0,G11/C11,0) -> 1272645.5
B12: 🇵🇹 포르투갈 | C12: ='③ 12개월 성장 시뮬'!N43 -> 36 | D12: ='③ 12개월 성장 시뮬'!C46 -> 820633.47 | E12: ='③ 12개월 성장 시뮬'!H46 -> 3749983.3 | F12: ='③ 12개월 성장 시뮬'!N46 -> 6913057.9 | G12: =SUM('③ 12개월 성장 시뮬'!C46:N46) -> 45815240 | H12: =G12/G$13 -> 0.05464728 | I12: =IF(C12>0,G12/C12,0) -> 1272645.5
B13: 📊 전체 합계 | C13: =SUM(C6:C12) -> 660 | D13: =SUM(D6:D12) -> 11327858 | E13: =SUM(E6:E12) -> 65032606 | F13: =SUM(F6:F12) -> 1.2889139e+08 | G13: =SUM(G6:G12) -> 8.3838097e+08 | H13: =SUM(H6:H12) -> 1 | I13: =SUM(I6:I12) -> 8899554.5
B15: 🎯 전략 요약
B16: 🇧🇷 브라질 (200명) + 🇲🇽 멕시코 (156명)만으로 전체 수익의 약 65~70% 창출 — "두 시장 먼저 집중" 전략이 최고 효율. 🇺🇸 미국 히스패닉 (96명): 파트너 수 적어도 소득이 $2,100/월로 T2/T3 전환율이 LATAM보다 높을 가능성 → 파트너 당 수익 1위. 🇦🇷 아르헨티나: 인플레이션으로 달러 수익 선호도 극강 → 커미션(달러) 매력이 가장 큰 시장. 파트너 모집 경쟁력 높음. 총 12개월 목표: 650명+ 파트너 | 브라질+멕시코 Hotmart 오피스 활용 → 현지 파트너 이벤트 참가 추천.
